Workbook

Sheet 6月
A2: 科 目 | B2: 本部 | F2: 本社営業本部 | AD2: 東京支店 | AP2: 全社合計 | AT2: 前期実績 | AX2: 前期比較
F3: 営業本部 | J3: 東大阪 | N3: 南港工場 | R3: 南港事務 | V3: 南港合計 | Z3: 本社営業合計 | AD3: 東京営業 | AH3: 東京工場 | AL3: 東京合計
B4: 45838 | D4: 累計 | F4: 45838 | H4: 累計 | J4: 45838 | L4: 累計 | N4: 45838 | P4: 累計 | R4: 45838 | T4: 累計 | V4: 45838 | X4: 累計 | Z4: 45838 | AB4: 累計 | AD4: 45838 | AF4: 累計 | AH4: 45838 | AJ4: 累計 | AL4: 45838 | AN4: 累計 | AP4: 45838 | AR4: 累計 | AT4: 45473 | AV4: 累計 | AX4: 月中比較 | AZ4: 累計比較
B5: 金 額 | C5: 比率 | D5: 金 額 | E5: 比率 | F5: 金 額 | G5: 比率 | H5: 金 額 | I5: 比率 | J5: 金 額 | K5: 比率 | L5: 金 額 | M5: 比率 | N5: 金 額 | O5: 比率 | P5: 金 額 | Q5: 比率 | R5: 金 額 | S5: 比率 | T5: 金 額 | U5: 比率 | V5: 金 額 | W5: 比率 | X5: 金 額 | Y5: 比率 | Z5: 金 額 | AA5: 比率 | AB5: 金 額 | AC5: 比率 | AD5: 金 額 | AE5: 比率 | AF5: 金 額 | AG5: 比率 | AH5: 金 額 | AI5: 比率 | AJ5: 金 額 | AK5: 比率 | AL5: 金 額 | AM5: 比率 | AN5: 金 額 | AO5: 比率 | AP5: 金 額 | AQ5: 比率 | AR5: 金 額 | AS5: 比率 | AT5: 金 額 | AU5: 比率 | AV5: 金 額 | AW5: 比率 | AX5: 金 額 | AY5: 比率 | AZ5: 金 額 | BA5: 比率
A6: 売上高 | C6: =IF(ISERR(B6/$B$11),"",B6/$B$11) | D6: =B6 -> 0 | E6: =IF(ISERR(D6/$D$11),"",D6/$D$11) | F6: =[1]本社営業!$L$5 -> 433671542 | G6: =IF(ISERR(F6/$F$11),"",F6/$F$11) -> 0.81097613 | H6: =F6 -> 433671542 | I6: =IF(ISERR(H6/$H$11),"",H6/$H$11) -> 0.81097613 | J6: =[1]東大阪!$L$5 -> 512935 | K6: =IF(ISERR(J6/$J$11),"",J6/$J$11) -> 0.057776874 | L6: =J6 -> 512935 | M6: =IF(ISERR(L6/$L$11),"",L6/$L$11) -> 0.057776874 | N6: =[1]南港工場!$L$5 -> 3687510 | O6: =IF(ISERR(N6/$N$11),"",N6/$N$11) -> 0.13065865 | P6: =N6 -> 3687510 | Q6: =IF(ISERR(P6/$P$11),"",P6/$P$11) -> 0.13065865 | S6: =IF(ISERR(R6/$R$11),"",R6/$R$11) | T6: =R6 -> 0 | U6: =IF(ISERR(T6/$T$11),"",T6/$T$11) | V6: =N6+R6 -> 3687510 | W6: =IF(ISERR(V6/$V$11),"",V6/$V$11) -> 0.13065865 | X6: =P6+T6 -> 3687510 | Y6: =IF(ISERR(X6/$X$11),"",X6/$X$11) -> 0.13065865 | Z6: =F6+J6+N6+R6 -> 437871987 | AA6: =IF(ISERR(Z6/$Z$11),"",Z6/$Z$11) -> 0.76570743 | AB6: =H6+L6+P6+T6 -> 437871987 | AC6: =IF(ISERR(AB6/$AB$11),"",AB6/$AB$11) -> 0.76570743 | AD6: =[1]東京事務!$L$5 -> 157743585 | AE6: =IF(ISERR(AD6/$AD$11),"",AD6/$AD$11) -> 0.64044995 | AF6: =AD6 -> 157743585 | AG6: =IF(ISERR(AF6/$AF$11),"",AF6/$AF$11) -> 0.64044995 | AH6: =[1]東京工場!$L$5 -> 0 | AI6: =IF(ISERR(AH6/$AH$11),"",AH6/$AH$11) -> 0 | AJ6: =AH6 -> 0 | AK6: =IF(ISERR(AJ6/$AJ$11),"",AJ6/$AJ$11) -> 0 | AL6: =AD6+AH6 -> 157743585 | AM6: =IF(ISERR(AL6/$AL$11),"",AL6/AL$11) -> 0.61591828 | AN6: =AF6+AJ6 -> 157743585 | AO6: =IF(ISERR(AN6/$AN$11),"",AN6/$AN$11) -> 0.61591828 | AP6: =B6+Z6+AL6 -> 595615572 | AQ6: =IF(ISERR(AP6/$AP$11),"",AP6/$AP$11) -> 0.71937368 | AR6: =D6+AB6+AN6 -> 595615572 | AS6: =IF(ISERR(AR6/$AR$11),"",AR6/$AR$11) -> 0.71937368 | AT6: =[1]全社合計!$N$5 -> 655350010 | AU6: =IF(ISERR(AT6/$AT$11),"",AT6/$AT$11) -> 0.67763905 | AV6: =AT6 -> 655350010 | AW6: =IF(ISERR(AV6/$AV$11),"",AV6/$AV$11) -> 0.67763905 | AX6: =AP6-AT6 -> -59734438 | AY6: =IF(ISERROR(AP6/AT6),"",AP6/AT6) -> 0.90885109 | AZ6: =AR6-AV6 -> -59734438 | BA6: =IF(ISERROR(AR6/AV6),"",AR6/AV6) -> 0.90885109
A7: 輸出売上高 | C7: =IF(ISERR(B7/$B$11),"",B7/$B$11) | D7: =B7 -> 0 | E7: =IF(ISERR(D7/$D$11),"",D7/$D$11) | F7: =[1]本社営業!$L$6 -> 34430373 | G7: =IF(ISERR(F7/$F$11),"",F7/$F$11) -> 0.064385619 | H7: =F7 -> 34430373 | I7: =IF(ISERR(H7/$H$11),"",H7/$H$11) -> 0.064385619 | J7: =[1]東大阪!$L$6 -> 0 | K7: =IF(ISERR(J7/$J$11),"",J7/$J$11) -> 0 | L7: =J7 -> 0 | M7: =IF(ISERR(L7/$L$11),"",L7/$L$11) -> 0 | N7: =[1]南港工場!$L$6 -> 0 | O7: =IF(ISERR(N7/$N$11),"",N7/$N$11) -> 0 | P7: =N7 -> 0 | Q7: =IF(ISERR(P7/$P$11),"",P7/$P$11) -> 0 | S7: =IF(ISERR(R7/$R$11),"",R7/$R$11) | T7: =R7 -> 0 | U7: =IF(ISERR(T7/$T$11),"",T7/$T$11) | V7: =N7+R7 -> 0 | W7: =IF(ISERR(V7/$V$11),"",V7/$V$11) -> 0 | X7: =P7+T7 -> 0 | Y7: =IF(ISERR(X7/$X$11),"",X7/$X$11) -> 0 | Z7: =F7+J7+N7+R7 -> 34430373 | AA7: =IF(ISERR(Z7/$Z$11),"",Z7/$Z$11) -> 0.060208447 | AB7: =H7+L7+P7+T7 -> 34430373 | AC7: =IF(ISERR(AB7/$AB$11),"",AB7/$AB$11) -> 0.060208447 | AD7: =[1]東京事務!$L$6 -> 0 | AE7: =IF(ISERR(AD7/$AD$11),"",AD7/$AD$11) -> 0 | AF7: =AD7 -> 0 | AG7: =IF(ISERR(AF7/$AF$11),"",AF7/$AF$11) -> 0 | AH7: =[1]東京工場!$L$6 -> 0 | AI7: =IF(ISERR(AH7/$AH$11),"",AH7/$AH$11) -> 0 | AJ7: =AH7 -> 0 | AK7: =IF(ISERR(AJ7/$AJ$11),"",AJ7/$AJ$11) -> 0 | AL7: =AD7+AH7 -> 0 | AM7: =IF(ISERR(AL7/$AL$11),"",AL7/AL$11) -> 0 | AN7: =AF7+AJ7 -> 0 | AO7: =IF(ISERR(AN7/$AN$11),"",AN7/$AN$11) -> 0 | AP7: =B7+Z7+AL7 -> 34430373 | AQ7: =IF(ISERR(AP7/$AP$11),"",AP7/$AP$11) -> 0.04158438 | AR7: =D7+AB7+AN7 -> 34430373 | AS7: =IF(ISERR(AR7/$AR$11),"",AR7/$AR$11) -> 0.04158438 | AT7: =[1]全社合計!$N$6 -> 80023208 | AU7: =IF(ISERR(AT7/$AT$11),"",AT7/$AT$11) -> 0.082744869 | AV7: =AT7 -> 80023208 | AW7: =IF(ISERR(AV7/$AV$11),"",AV7/$AV$11) -> 0.082744869 | AX7: =AP7-AT7 -> -45592835 | AY7: =IF(ISERROR(AP7/AT7),"",AP7/AT7) -> 0.43025485 | AZ7: =AR7-AV7 -> -45592835 | BA7: =IF(ISERROR(AR7/AV7),"",AR7/AV7) -> 0.43025485
A8: 加工賃収入 | C8: =IF(ISERR(B8/$B$11),"",B8/$B$11) | D8: =B8 -> 0 | E8: =IF(ISERR(D8/$D$11),"",D8/$D$11) | F8: =[1]本社営業!$L$7 -> 2985710 | G8: =IF(ISERR(F8/$F$11),"",F8/$F$11) -> 0.005583349 | H8: =F8 -> 2985710 | I8: =IF(ISERR(H8/$H$11),"",H8/$H$11) -> 0.005583349 | J8: =[1]東大阪!$L$7 -> 0 | K8: =IF(ISERR(J8/$J$11),"",J8/$J$11) -> 0 | L8: =J8 -> 0 | M8: =IF(ISERR(L8/$L$11),"",L8/$L$11) -> 0 | N8: =[1]南港工場!$L$7 -> 14694120 | O8: =IF(ISERR(N8/$N$11),"",N8/$N$11) -> 0.52065321 | P8: =N8 -> 14694120 | Q8: =IF(ISERR(P8/$P$11),"",P8/$P$11) -> 0.52065321 | S8: =IF(ISERR(R8/$R$11),"",R8/$R$11) | T8: =R8 -> 0 | U8: =IF(ISERR(T8/$T$11),"",T8/$T$11) | V8: =N8+R8 -> 14694120 | W8: =IF(ISERR(V8/$V$11),"",V8/$V$11) -> 0.52065321 | X8: =P8+T8 -> 14694120 | Y8: =IF(ISERR(X8/$X$11),"",X8/$X$11) -> 0.52065321 | Z8: =F8+J8+N8+R8 -> 17679830 | AA8: =IF(ISERR(Z8/$Z$11),"",Z8/$Z$11) -> 0.030916746 | AB8: =H8+L8+P8+T8 -> 17679830 | AC8: =IF(ISERR(AB8/$AB$11),"",AB8/$AB$11) -> 0.030916746 | AD8: =[1]東京事務!$L$7 -> 114496 | AE8: =IF(ISERR(AD8/$AD$11),"",AD8/$AD$11) -> 0.00046486174 | AF8: =AD8 -> 114496 | AG8: =IF(ISERR(AF8/$AF$11),"",AF8/$AF$11) -> 0.00046486174 | AH8: =[1]東京工場!$L$7 -> 0 | AI8: =IF(ISERR(AH8/$AH$11),"",AH8/$AH$11) -> 0 | AJ8: =AH8 -> 0 | AK8: =IF(ISERR(AJ8/$AJ$11),"",AJ8/$AJ$11) -> 0 | AL8: =AD8+AH8 -> 114496 | AM8: =IF(ISERR(AL8/$AL$11),"",AL8/AL$11) -> 0.00044705576 | AN8: =AF8+AJ8 -> 114496 | AO8: =IF(ISERR(AN8/$AN$11),"",AN8/$AN$11) -> 0.00044705576 | AP8: =B8+Z8+AL8 -> 17794326 | AQ8: =IF(ISERR(AP8/$AP$11),"",AP8/$AP$11) -> 0.021491664 | AR8: =D8+AB8+AN8 -> 17794326 | AS8: =IF(ISERR(AR8/$AR$11),"",AR8/$AR$11) -> 0.021491664 | AT8: =[1]全社合計!$N$7 -> 14310081 | AU8: =IF(ISERR(AT8/$AT$11),"",AT8/$AT$11) -> 0.01479678 | AV8: =AT8 -> 14310081 | AW8: =IF(ISERR(AV8/$AV$11),"",AV8/$AV$11) -> 0.01479678 | AX8: =AP8-AT8 -> 3484245 | AY8: =IF(ISERROR(AP8/AT8),"",AP8/AT8) -> 1.2434819 | AZ8: =AR8-AV8 -> 3484245 | BA8: =IF(ISERROR(AR8/AV8),"",AR8/AV8) -> 1.2434819
A9: 役務収入 | C9: =IF(ISERR(B9/$B$11),"",B9/$B$11) | D9: =B9 -> 0 | E9: =IF(ISERR(D9/$D$11),"",D9/$D$11) | F9: =[1]本社営業!$L$8 -> 736070 | G9: =IF(ISERR(F9/$F$11),"",F9/$F$11) -> 0.0013764685 | H9: =F9 -> 736070 | I9: =IF(ISERR(H9/$H$11),"",H9/$H$11) -> 0.0013764685 | J9: =[1]東大阪!$L$8 -> 0 | K9: =IF(ISERR(J9/$J$11),"",J9/$J$11) -> 0 | L9: =J9 -> 0 | M9: =IF(ISERR(L9/$L$11),"",L9/$L$11) -> 0 | N9: =[1]南港工場!$L$8 -> 4480912 | O9: =IF(ISERR(N9/$N$11),"",N9/$N$11) -> 0.15877107 | P9: =N9 -> 4480912 | Q9: =IF(ISERR(P9/$P$11),"",P9/$P$11) -> 0.15877107 | S9: =IF(ISERR(R9/$R$11),"",R9/$R$11) | T9: =R9 -> 0 | U9: =IF(ISERR(T9/$T$11),"",T9/$T$11) | V9: =N9+R9 -> 4480912 | W9: =IF(ISERR(V9/$V$11),"",V9/$V$11) -> 0.15877107 | X9: =P9+T9 -> 4480912 | Y9: =IF(ISERR(X9/$X$11),"",X9/$X$11) -> 0.15877107 | Z9: =F9+J9+N9+R9 -> 5216982 | AA9: =IF(ISERR(Z9/$Z$11),"",Z9/$Z$11) -> 0.0091229446 | AB9: =H9+L9+P9+T9 -> 5216982 | AC9: =IF(ISERR(AB9/$AB$11),"",AB9/$AB$11) -> 0.0091229446 | AD9: =[1]東京事務!$L$8 -> 6000 | AE9: =IF(ISERR(AD9/$AD$11),"",AD9/$AD$11) -> 2.4360418e-05 | AF9: =AD9 -> 6000 | AG9: =IF(ISERR(AF9/$AF$11),"",AF9/$AF$11) -> 2.4360418e-05 | AH9: =[1]東京工場!$L$8 -> 0 | AI9: =IF(ISERR(AH9/$AH$11),"",AH9/$AH$11) -> 0 | AJ9: =AH9 -> 0 | AK9: =IF(ISERR(AJ9/$AJ$11),"",AJ9/$AJ$11) -> 0 | AL9: =AD9+AH9 -> 6000 | AM9: =IF(ISERR(AL9/$AL$11),"",AL9/AL$11) -> 2.3427321e-05 | AN9: =AF9+AJ9 -> 6000 | AO9: =IF(ISERR(AN9/$AN$11),"",AN9/$AN$11) -> 2.3427321e-05 | AP9: =B9+Z9+AL9 -> 5222982 | AQ9: =IF(ISERR(AP9/$AP$11),"",AP9/$AP$11) -> 0.0063082229 | AR9: =D9+AB9+AN9 -> 5222982 | AS9: =IF(ISERR(AR9/$AR$11),"",AR9/$AR$11) -> 0.0063082229 | AT9: =[1]全社合計!$N$8 -> 3799887 | AU9: =IF(ISERR(AT9/$AT$11),"",AT9/$AT$11) -> 0.0039291246 | AV9: =AT9 -> 3799887 | AW9: =IF(ISERR(AV9/$AV$11),"",AV9/$AV$11) -> 0.0039291246 | AX9: =AP9-AT9 -> 1423095 | AY9: =IF(ISERROR(AP9/AT9),"",AP9/AT9) -> 1.3745098 | AZ9: =AR9-AV9 -> 1423095 | BA9: =IF(ISERROR(AR9/AV9),"",AR9/AV9) -> 1.3745098
A10: 本支店売上高 | C10: =IF(ISERR(B10/$B$11),"",B10/$B$11) | D10: =B10 -> 0 | E10: =IF(ISERR(D10/$D$11),"",D10/$D$11) | F10: =[1]本社営業!$L$9 -> 62928838 | G10: =IF(ISERR(F10/$F$11),"",F10/$F$11) -> 0.11767843 | H10: =F10 -> 62928838 | I10: =IF(ISERR(H10/$H$11),"",H10/$H$11) -> 0.11767843 | J10: =[1]東大阪!$L$9 -> 8364925 | K10: =IF(ISERR(J10/$J$11),"",J10/$J$11) -> 0.94222313 | L10: =J10 -> 8364925 | M10: =IF(ISERR(L10/$L$11),"",L10/$L$11) -> 0.94222313 | N10: =[1]南港工場!$L$9 -> 5359929 | O10: =IF(ISERR(N10/$N$11),"",N10/$N$11) -> 0.18991707 | P10: =N10 -> 5359929 | Q10: =IF(ISERR(P10/$P$11),"",P10/$P$11) -> 0.18991707 | S10: =IF(ISERR(R10/$R$11),"",R10/$R$11) | T10: =R10 -> 0 | U10: =IF(ISERR(T10/$T$11),"",T10/$T$11) | V10: =N10+R10 -> 5359929 | W10: =IF(ISERR(V10/$V$11),"",V10/$V$11) -> 0.18991707 | X10: =P10+T10 -> 5359929 | Y10: =IF(ISERR(X10/$X$11),"",X10/$X$11) -> 0.18991707 | Z10: =F10+J10+N10+R10 -> 76653692 | AA10: =IF(ISERR(Z10/$Z$11),"",Z10/$Z$11) -> 0.13404443 | AB10: =H10+L10+P10+T10 -> 76653692 | AC10: =IF(ISERR(AB10/$AB$11),"",AB10/$AB$11) -> 0.13404443 | AD10: =[1]東京事務!$L$9 -> 88437110 | AE10: =IF(ISERR(AD10/$AD$11),"",AD10/$AD$11) -> 0.35906083 | AF10: =AD10 -> 88437110 | AG10: =IF(ISERR(AF10/$AF$11),"",AF10/$AF$11) -> 0.35906083 | AH10: =[1]東京工場!$L$9 -> 9810035 | AI10: =IF(ISERR(AH10/$AH$11),"",AH10/$AH$11) -> 1 | AJ10: =AH10 -> 9810035 | AK10: =IF(ISERR(AJ10/$AJ$11),"",AJ10/$AJ$11) -> 1 | AL10: =AD10+AH10 -> 98247145 | AM10: =IF(ISERR(AL10/$AL$11),"",AL10/AL$11) -> 0.38361124 | AN10: =AF10+AJ10 -> 98247145 | AO10: =IF(ISERR(AN10/$AN$11),"",AN10/$AN$11) -> 0.38361124 | AP10: =B10+Z10+AL10 -> 174900837 | AQ10: =IF(ISERR(AP10/$AP$11),"",AP10/$AP$11) -> 0.21124206 | AR10: =D10+AB10+AN10 -> 174900837 | AS10: =IF(ISERR(AR10/$AR$11),"",AR10/$AR$11) -> 0.21124206 | AT10: =[1]全社合計!$N$9 -> 213624607 | AU10: =IF(ISERR(AT10/$AT$11),"",AT10/$AT$11) -> 0.22089017 | AV10: =AT10 -> 213624607 | AW10: =IF(ISERR(AV10/$AV$11),"",AV10/$AV$11) -> 0.22089017 | AX10: =AP10-AT10 -> -38723770 | AY10: =IF(ISERROR(AP10/AT10),"",AP10/AT10) -> 0.81872982 | AZ10: =AR10-AV10 -> -38723770 | BA10: =IF(ISERROR(AR10/AV10),"",AR10/AV10) -> 0.81872982
A11: 【売上高合計】 | B11: =SUM(B6:B10) -> 0 | C11: =IF(ISERR(B11/$B$11),"",B11/$B$11) | D11: =B11 -> 0 | E11: =IF(ISERR(D11/$D$11),"",D11/$D$11) | F11: =SUM(F6:F10) -> 534752533 | G11: =IF(ISERR(F11/$F$11),"",F11/$F$11) -> 1 | H11: =F11 -> 534752533 | I11: =IF(ISERR(H11/$H$11),"",H11/$H$11) -> 1 | J11: =SUM(J6:J10) -> 8877860 | K11: =IF(ISERR(J11/$J$11),"",J11/$J$11) -> 1 | L11: =J11 -> 8877860 | M11: =IF(ISERR(L11/$L$11),"",L11/$L$11) -> 1 | N11: =SUM(N6:N10) -> 28222471 | O11: =IF(ISERR(N11/$N$11),"",N11/$N$11) -> 1 | P11: =N11 -> 28222471 | Q11: =IF(ISERR(P11/$P$11),"",P11/$P$11) -> 1 | R11: =SUM(R6:R10) -> 0 | S11: =IF(ISERR(R11/$R$11),"",R11/$R$11) | T11: =R11 -> 0 | U11: =IF(ISERR(T11/$T$11),"",T11/$T$11) | V11: =N11+R11 -> 28222471 | W11: =IF(ISERR(V11/$V$11),"",V11/$V$11) -> 1 | X11: =P11+T11 -> 28222471 | Y11: =IF(ISERR(X11/$X$11),"",X11/$X$11) -> 1 | Z11: =F11+J11+N11+R11 -> 571852864 | AA11: =IF(ISERR(Z11/$Z$11),"",Z11/$Z$11) -> 1 | AB11: =H11+L11+P11+T11 -> 571852864 | AC11: =IF(ISERR(AB11/$AB$11),"",AB11/$AB$11) -> 1 | AD11: =SUM(AD6:AD10) -> 246301191 | AE11: =IF(ISERR(AD11/$AD$11),"",AD11/$AD$11) -> 1 | AF11: =AD11 -> 246301191 | AG11: =IF(ISERR(AF11/$AF$11),"",AF11/$AF$11) -> 1 | AH11: =SUM(AH6:AH10) -> 9810035 | AI11: =IF(ISERR(AH11/$AH$11),"",AH11/$AH$11) -> 1 | AJ11: =AH11 -> 9810035 | AK11: =IF(ISERR(AJ11/$AJ$11),"",AJ11/$AJ$11) -> 1 | AL11: =AD11+AH11 -> 256111226 | AM11: =IF(ISERR(AL11/$AL$11),"",AL11/AL$11) -> 1 | AN11: =AF11+AJ11 -> 256111226 | AO11: =IF(ISERR(AN11/$AN$11),"",AN11/$AN$11) -> 1 | AP11: =B11+Z11+AL11 -> 827964090 | AQ11: =IF(ISERR(AP11/$AP$11),"",AP11/$AP$11) -> 1 | AR11: =D11+AB11+AN11 -> 827964090 | AS11: =IF(ISERR(AR11/$AR$11),"",AR11/$AR$11) -> 1 | AT11: =SUM(AT6:AT10) -> 967107793 | AU11: =IF(ISERR(AT11/$AT$11),"",AT11/$AT$11) -> 1 | AV11: =SUM(AV6:AV10) -> 967107793 | AW11: =IF(ISERR(AV11/$AV$11),"",AV11/$AV$11) -> 1 | AX11: =AP11-AT11 -> -139143703 | AY11: =IF(ISERROR(AP11/AT11),"",AP11/AT11) -> 0.85612389 | AZ11: =AR11-AV11 -> -139143703 | BA11: =IF(ISERROR(AR11/AV11),"",AR11/AV11) -> 0.85612389
A12: （売上重量） | F12: =[1]本社営業!$L$11 -> 2471715 | H12: =F12 -> 2471715 | J12: =[1]東大阪!$L$11 -> 17050 | L12: =J12 -> 17050 | N12: =[1]南港工場!$L$11 -> 93030 | P12: =N12 -> 93030 | T12: =R12 -> 0 | V12: =N12+R12 -> 93030 | X12: =P12+T12 -> 93030 | Z12: =F12+J12+N12+R12 -> 2581795 | AB12: =H12+L12+P12+T12 -> 2581795 | AD12: =[1]東京事務!$L$11 -> 1004923 | AF12: =AD12 -> 1004923 | AI12: =IF(ISERR(AH12/$AH$11),"",AH12/$AH$11) -> 0 | AJ12: =AH12 -> 0 | AL12: =AD12+AH12 -> 1004923 | AN12: =AF12+AJ12 -> 1004923 | AP12: =B12+Z12+AL12 -> 3586718 | AR12: =D12+AB12+AN12 -> 3586718 | AT12: =[1]全社合計!$N$11 -> 4336706 | AV12: =AT12 -> 4336706 | AX12: =AP12-AT12 -> -749988 | AY12: =IF(ISERROR(AP12/AT12),"",AP12/AT12) -> 0.82706045 | AZ12: =AR12-AV12 -> -749988 | BA12: =IF(ISERROR(AR12/AV12),"",AR12/AV12) -> 0.82706045
A13: （加工重量） | H13: =F13 -> 0 | L13: =J13 -> 0 | N13: =[1]南港工場!$L$12 -> 3976641 | P13: =N13 -> 3976641 | T13: =R13 -> 0 | V13: =N13+R13 -> 3976641 | X13: =P13+T13 -> 3976641 | Z13: =F13+J13+N13+R13 -> 3976641 | AB13: =H13+L13+P13+T13 -> 3976641 | AF13: =AD13 -> 0 | AI13: =IF(ISERR(AH13/$AH$11),"",AH13/$AH$11) -> 0 | AJ13: =AH13 -> 0 | AL13: =AD13+AH13 -> 0 | AN13: =AF13+AJ13 -> 0 | AP13: =B13+Z13+AL13 -> 3976641 | AR13: =D13+AB13+AN13 -> 3976641 | AT13: =[1]全社合計!$N$12 -> 3535788 | AV13: =AT13 -> 3535788 | AX13: =AP13-AT13 -> 440853 | AY13: =IF(ISERROR(AP13/AT13),"",AP13/AT13) -> 1.1246831 | AZ13: =AR13-AV13 -> 440853 | BA13: =IF(ISERROR(AR13/AV13),"",AR13/AV13) -> 1.1246831
A14: 期首商品棚卸高 | C14: =IF(ISERR(B14/$B$11),"",B14/$B$11) | D14: =B14 -> 0 | E14: =IF(ISERR(D14/$D$11),"",D14/$D$11) | F14: =[1]本社営業!$L$14 -> 1205973702 | G14: =IF(ISERR(F14/$F$11),"",F14/$F$11) -> 2.2551996 | H14: =F14 -> 1205973702 | I14: =IF(ISERR(H14/$H$11),"",H14/$H$11) -> 2.2551996 | K14: =IF(ISERR(J14/$J$11),"",J14/$J$11) -> 0 | L14: =J14 -> 0 | M14: =IF(ISERR(L14/$L$11),"",L14/$L$11) -> 0 | O14: =IF(ISERR(N14/$N$11),"",N14/$N$11) -> 0 | P14: =N14 -> 0 | Q14: =IF(ISERR(P14/$P$11),"",P14/$P$11) -> 0 | S14: =IF(ISERR(R14/$R$11),"",R14/$R$11) | T14: =R14 -> 0 | U14: =IF(ISERR(T14/$T$11),"",T14/$T$11) | V14: =N14+R14 -> 0 | W14: =IF(ISERR(V14/$V$11),"",V14/$V$11) -> 0 | X14: =P14+T14 -> 0 | Y14: =IF(ISERR(X14/$X$11),"",X14/$X$11) -> 0 | Z14: =F14+J14+N14+R14 -> 1205973702 | AA14: =IF(ISERR(Z14/$Z$11),"",Z14/$Z$11) -> 2.1088881 | AB14: =H14+L14+P14+T14 -> 1205973702 | AC14: =IF(ISERR(AB14/$AB$11),"",AB14/$AB$11) -> 2.1088881 | AD14: =[1]東京事務!$L$14 -> 804499700 | AE14: =IF(ISERR(AD14/$AD$11),"",AD14/$AD$11) -> 3.2663248 | AF14: =AD14 -> 804499700 | AG14: =IF(ISERR(AF14/$AF$11),"",AF14/$AF$11) -> 3.2663248 | AI14: =IF(ISERR(AH14/$AH$11),"",AH14/$AH$11) -> 0 | AJ14: =AH14 -> 0 | AK14: =IF(ISERR(AJ14/$AJ$11),"",AJ14/$AJ$11) -> 0 | AL14: =AD14+AH14 -> 804499700 | AM14: =IF(ISERR(AL14/$AL$11),"",AL14/AL$11) -> 3.1412122 | AN14: =AF14+AJ14 -> 804499700 | AO14: =IF(ISERR(AN14/$AN$11),"",AN14/$AN$11) -> 3.1412122 | AP14: =B14+Z14+AL14 -> 2010473402 | AQ14: =IF(ISERR(AP14/$AP$11),"",AP14/$AP$11) -> 2.4282133 | AR14: =D14+AB14+AN14 -> 2010473402 | AS14: =IF(ISERR(AR14/$AR$11),"",AR14/$AR$11) -> 2.4282133 | AT14: =[1]全社合計!$N$14 -> 1816376496 | AU14: =IF(ISERR(AT14/$AT$11),"",AT14/$AT$11) -> 1.8781531 | AV14: =AT14 -> 1816376496 | AW14: =IF(ISERR(AV14/$AV$11),"",AV14/$AV$11) -> 1.8781531 | AX14: =AP14-AT14 -> 194096906 | AY14: =IF(ISERROR(AP14/AT14),"",AP14/AT14) -> 1.1068594 | AZ14: =AR14-AV14 -> 194096906 | BA14: =IF(ISERROR(AR14/AV14),"",AR14/AV14) -> 1.1068594
A15: 当期商品仕入高 | C15: =IF(ISERR(B15/$B$11),"",B15/$B$11) | E15: =IF(ISERR(D15/$D$11),"",D15/$D$11) | F15: =[1]本社営業!$L$15 -> 470134699 | G15: =IF(ISERR(F15/$F$11),"",F15/$F$11) -> 0.87916311 | H15: =F15 -> 470134699 | I15: =IF(ISERR(H15/$H$11),"",H15/$H$11) -> 0.87916311 | J15: =[1]東大阪!$L$15 -> 495885 | K15: =IF(ISERR(J15/$J$11),"",J15/$J$11) -> 0.055856366 | L15: =J15 -> 495885 | M15: =IF(ISERR(L15/$L$11),"",L15/$L$11) -> 0.055856366 | N15: =[1]南港工場!$L$15 -> 2141339 | O15: =IF(ISERR(N15/$N$11),"",N15/$N$11) -> 0.075873548 | P15: =N15 -> 2141339 | Q15: =IF(ISERR(P15/$P$11),"",P15/$P$11) -> 0.075873548 | S15: =IF(ISERR(R15/$R$11),"",R15/$R$11) | T15: =R15 -> 0 | U15: =IF(ISERR(T15/$T$11),"",T15/$T$11) | V15: =N15+R15 -> 2141339 | W15: =IF(ISERR(V15/$V$11),"",V15/$V$11) -> 0.075873548 | X15: =P15+T15 -> 2141339 | Y15: =IF(ISERR(X15/$X$11),"",X15/$X$11) -> 0.075873548 | Z15: =F15+J15+N15+R15 -> 472771923 | AA15: =IF(ISERR(Z15/$Z$11),"",Z15/$Z$11) -> 0.826737 | AB15: =H15+L15+P15+T15 -> 472771923 | AC15: =IF(ISERR(AB15/$AB$11),"",AB15/$AB$11) -> 0.826737 | AD15: =[1]東京事務!$L$15 -> 199249578 | AE15: =IF(ISERR(AD15/$AD$11),"",AD15/$AD$11) -> 0.80896717 | AF15: =AD15 -> 199249578 | AG15: =IF(ISERR(AF15/$AF$11),"",AF15/$AF$11) -> 0.80896717 | AH15: =[1]東京工場!$L$15 -> 0 | AI15: =IF(ISERR(AH15/$AH$11),"",AH15/$AH$11) -> 0 | AJ15: =AH15 -> 0 | AK15: =IF(ISERR(AJ15/$AJ$11),"",AJ15/$AJ$11) -> 0 | AL15: =AD15+AH15 -> 199249578 | AM15: =IF(ISERR(AL15/$AL$11),"",AL15/AL$11) -> 0.77798065 | AN15: =AF15+AJ15 -> 199249578 | AO15: =IF(ISERR(AN15/$AN$11),"",AN15/$AN$11) -> 0.77798065 | AP15: =B15+Z15+AL15 -> 672021501 | AQ15: =IF(ISERR(AP15/$AP$11),"",AP15/$AP$11) -> 0.81165537 | AR15: =D15+AB15+AN15 -> 672021501 | AS15: =IF(ISERR(AR15/$AR$11),"",AR15/$AR$11) -> 0.81165537 | AT15: =[1]全社合計!$N$15 -> 867747663 | AU15: =IF(ISERR(AT15/$AT$11),"",AT15/$AT$11) -> 0.89726054 | AV15: =AT15 -> 867747663 | AW15: =IF(ISERR(AV15/$AV$11),"",AV15/$AV$11) -> 0.89726054 | AX15: =AP15-AT15 -> -195726162 | AY15: =IF(ISERROR(AP15/AT15),"",AP15/AT15) -> 0.77444346 | AZ15: =AR15-AV15 -> -195726162 | BA15: =IF(ISERROR(AR15/AV15),"",AR15/AV15) -> 0.77444346
A16: 期末商品棚卸高 | C16: =IF(ISERR(B16/$B$11),"",B16/$B$11) | D16: =B16 -> 0 | E16: =IF(ISERR(D16/$D$11),"",D16/$D$11) | F16: =[1]本社営業!$L$16 -> 1212643896 | G16: =IF(ISERR(F16/$F$11),"",F16/$F$11) -> 2.267673 | H16: =F16 -> 1212643896 | I16: =IF(ISERR(H16/$H$11),"",H16/$H$11) -> 2.267673 | K16: =IF(ISERR(J16/$J$11),"",J16/$J$11) -> 0 | L16: =J16 -> 0 | M16: =IF(ISERR(L16/$L$11),"",L16/$L$11) -> 0 | O16: =IF(ISERR(N16/$N$11),"",N16/$N$11) -> 0 | P16: =N16 -> 0 | Q16: =IF(ISERR(P16/$P$11),"",P16/$P$11) -> 0 | S16: =IF(ISERR(R16/$R$11),"",R16/$R$11) | T16: =R16 -> 0 | U16: =IF(ISERR(T16/$T$11),"",T16/$T$11) | V16: =N16+R16 -> 0 | W16: =IF(ISERR(V16/$V$11),"",V16/$V$11) -> 0 | X16: =P16+T16 -> 0 | Y16: =IF(ISERR(X16/$X$11),"",X16/$X$11) -> 0 | Z16: =F16+J16+N16+R16 -> 1212643896 | AA16: =IF(ISERR(Z16/$Z$11),"",Z16/$Z$11) -> 2.1205523 | AB16: =H16+L16+P16+T16 -> 1212643896 | AC16: =IF(ISERR(AB16/$AB$11),"",AB16/$AB$11) -> 2.1205523 | AD16: =[1]東京事務!$L$16 -> 778809293 | AE16: =IF(ISERR(AD16/$AD$11),"",AD16/$AD$11) -> 3.16202 | AF16: =AD16 -> 778809293 | AG16: =IF(ISERR(AF16/$AF$11),"",AF16/$AF$11) -> 3.16202 | AI16: =IF(ISERR(AH16/$AH$11),"",AH16/$AH$11) -> 0 | AJ16: =AH16 -> 0 | AK16: =IF(ISERR(AJ16/$AJ$11),"",AJ16/$AJ$11) -> 0 | AL16: =AD16+AH16 -> 778809293 | AM16: =IF(ISERR(AL16/$AL$11),"",AL16/AL$11) -> 3.0409026 | AN16: =AF16+AJ16 -> 778809293 | AO16: =IF(ISERR(AN16/$AN$11),"",AN16/$AN$11) -> 3.0409026 | AP16: =B16+Z16+AL16 -> 1991453189 | AQ16: =IF(ISERR(AP16/$AP$11),"",AP16/$AP$11) -> 2.405241 | AR16: =D16+AB16+AN16 -> 1991453189 | AS16: =IF(ISERR(AR16/$AR$11),"",AR16/$AR$11) -> 2.405241 | AT16: =[1]全社合計!$N$16 -> 1864108715 | AU16: =IF(ISERR(AT16/$AT$11),"",AT16/$AT$11) -> 1.9275087 | AV16: =AT16 -> 1864108715 | AW16: =IF(ISERR(AV16/$AV$11),"",AV16/$AV$11) -> 1.9275087 | AX16: =AP16-AT16 -> 127344474 | AY16: =IF(ISERROR(AP16/AT16),"",AP16/AT16) -> 1.0683139 | AZ16: =AR16-AV16 -> 127344474 | BA16: =IF(ISERROR(AR16/AV16),"",AR16/AV16) -> 1.0683139
A17: 《差引売上原価》 | B17: =+B14+B15-B16 -> 0 | C17: =IF(ISERR(B17/$B$11),"",B17/$B$11) | D17: =B17 -> 0 | E17: =IF(ISERR(D17/$D$11),"",D17/$D$11) | F17: =F14+F15-F16 -> 463464505 | G17: =IF(ISERR(F17/$F$11),"",F17/$F$11) -> 0.86668969 | H17: =F17 -> 463464505 | I17: =IF(ISERR(H17/$H$11),"",H17/$H$11) -> 0.86668969 | J17: =J14+J15-J16 -> 495885 | K17: =IF(ISERR(J17/$J$11),"",J17/$J$11) -> 0.055856366 | L17: =J17 -> 495885 | M17: =IF(ISERR(L17/$L$11),"",L17/$L$11) -> 0.055856366 | N17: =N14+N15-N16 -> 2141339 | O17: =IF(ISERR(N17/$N$11),"",N17/$N$11) -> 0.075873548 | P17: =N17 -> 2141339 | Q17: =IF(ISERR(P17/$P$11),"",P17/$P$11) -> 0.075873548 | R17: =R14+R15-R16 -> 0 | S17: =IF(ISERR(R17/$R$11),"",R17/$R$11) | T17: =R17 -> 0 | U17: =IF(ISERR(T17/$T$11),"",T17/$T$11) | V17: =N17+R17 -> 2141339 | W17: =IF(ISERR(V17/$V$11),"",V17/$V$11) -> 0.075873548 | X17: =P17+T17 -> 2141339 | Y17: =IF(ISERR(X17/$X$11),"",X17/$X$11) -> 0.075873548 | Z17: =F17+J17+N17+R17 -> 466101729 | AA17: =IF(ISERR(Z17/$Z$11),"",Z17/$Z$11) -> 0.81507282 | AB17: =H17+L17+P17+T17 -> 466101729 | AC17: =IF(ISERR(AB17/$AB$11),"",AB17/$AB$11) -> 0.81507282 | AD17: =AD14+AD15-AD16 -> 224939985 | AE17: =IF(ISERR(AD17/$AD$11),"",AD17/$AD$11) -> 0.91327201 | AF17: =AD17 -> 224939985 | AG17: =IF(ISERR(AF17/$AF$11),"",AF17/$AF$11) -> 0.91327201 | AH17: =AH14+AH15-AH16 -> 0 | AI17: =IF(ISERR(AH17/$AH$11),"",AH17/$AH$11) -> 0 | AJ17: =AH17 -> 0 | AK17: =IF(ISERR(AJ17/$AJ$11),"",AJ17/$AJ$11) -> 0 | AL17: =AD17+AH17 -> 224939985 | AM17: =IF(ISERR(AL17/$AL$11),"",AL17/AL$11) -> 0.87829022 | AN17: =AF17+AJ17 -> 224939985 | AO17: =IF(ISERR(AN17/$AN$11),"",AN17/$AN$11) -> 0.87829022 | AP17: =B17+Z17+AL17 -> 691041714 | AQ17: =IF(ISERR(AP17/$AP$11),"",AP17/$AP$11) -> 0.83462764 | AR17: =D17+AB17+AN17 -> 691041714 | AS17: =IF(ISERR(AR17/$AR$11),"",AR17/$AR$11) -> 0.83462764 | AT17: =AT14+AT15-AT16 -> 820015444 | AU17: =IF(ISERR(AT17/$AT$11),"",AT17/$AT$11) -> 0.84790491 | AV17: =AT17 -> 820015444 | AW17: =IF(ISERR(AV17/$AV$11),"",AV17/$AV$11) -> 0.84790491 | AX17: =AP17-AT17 -> -128973730 | AY17: =IF(ISERROR(AP17/AT17),"",AP17/AT17) -> 0.84271793 | AZ17: =AR17-AV17 -> -128973730 | BA17: =IF(ISERROR(AR17/AV17),"",AR17/AV17) -> 0.84271793
A18: 【売上総利益】 | B18: =+B11-B17 -> 0 | C18: =IF(ISERR(B18/$B$11),"",B18/$B$11) | D18: =B18 -> 0 | E18: =IF(ISERR(D18/$D$11),"",D18/$D$11) | F18: =F11-F17 -> 71288028 | G18: =IF(ISERR(F18/$F$11),"",F18/$F$11) -> 0.13331031 | H18: =F18 -> 71288028 | I18: =IF(ISERR(H18/$H$11),"",H18/$H$11) -> 0.13331031 | J18: =J11-J17 -> 8381975 | K18: =IF(ISERR(J18/$J$11),"",J18/$J$11) -> 0.94414363 | L18: =J18 -> 8381975 | M18: =IF(ISERR(L18/$L$11),"",L18/$L$11) -> 0.94414363 | N18: =N11-N17 -> 26081132 | O18: =IF(ISERR(N18/$N$11),"",N18/$N$11) -> 0.92412645 | P18: =N18 -> 26081132 | Q18: =IF(ISERR(P18/$P$11),"",P18/$P$11) -> 0.92412645 | R18: =R11-R17 -> 0 | S18: =IF(ISERR(R18/$R$11),"",R18/$R$11) | T18: =R18 -> 0 | U18: =IF(ISERR(T18/$T$11),"",T18/$T$11) | V18: =N18+R18 -> 26081132 | W18: =IF(ISERR(V18/$V$11),"",V18/$V$11) -> 0.92412645 | X18: =P18+T18 -> 26081132 | Y18: =IF(ISERR(X18/$X$11),"",X18/$X$11) -> 0.92412645 | Z18: =F18+J18+N18+R18 -> 105751135 | AA18: =IF(ISERR(Z18/$Z$11),"",Z18/$Z$11) -> 0.18492718 | AB18: =H18+L18+P18+T18 -> 105751135 | AC18: =IF(ISERR(AB18/$AB$11),"",AB18/$AB$11) -> 0.18492718 | AD18: =AD11-AD17 -> 21361206 | AE18: =IF(ISERR(AD18/$AD$11),"",AD18/$AD$11) -> 0.086727985 | AF18: =AD18 -> 21361206 | AG18: =IF(ISERR(AF18/$AF$11),"",AF18/$AF$11) -> 0.086727985 | AH18: =AH11-AH17 -> 9810035 | AI18: =IF(ISERR(AH18/$AH$11),"",AH18/$AH$11) -> 1 | AJ18: =AH18 -> 9810035 | AK18: =IF(ISERR(AJ18/$AJ$11),"",AJ18/$AJ$11) -> 1 | AL18: =AD18+AH18 -> 31171241 | AM18: =IF(ISERR(AL18/$AL$11),"",AL18/AL$11) -> 0.12170978 | AN18: =AF18+AJ18 -> 31171241 | AO18: =IF(ISERR(AN18/$AN$11),"",AN18/$AN$11) -> 0.12170978 | AP18: =B18+Z18+AL18 -> 136922376 | AQ18: =IF(ISERR(AP18/$AP$11),"",AP18/$AP$11) -> 0.16537236 | AR18: =D18+AB18+AN18 -> 136922376 | AS18: =IF(ISERR(AR18/$AR$11),"",AR18/$AR$11) -> 0.16537236 | AT18: =AT11-AT17 -> 147092349 | AU18: =IF(ISERR(AT18/$AT$11),"",AT18/$AT$11) -> 0.15209509 | AV18: =AT18 -> 147092349 | AW18: =IF(ISERR(AV18/$AV$11),"",AV18/$AV$11) -> 0.15209509 | AX18: =AP18-AT18 -> -10169973 | AY18: =IF(ISERROR(AP18/AT18),"",AP18/AT18) -> 0.93085995 | AZ18: =AR18-AV18 -> -10169973 | BA18: =IF(ISERROR(AR18/AV18),"",AR18/AV18) -> 0.93085995
A19: 給料 | B19: =[1]本部!$L$19 -> 5756800 | C19: =IF(ISERR(B19/$B$11),"",B19/$B$11) | D19: =B19 -> 5756800 | E19: =IF(ISERR(D19/$D$11),"",D19/$D$11) | F19: =[1]本社営業!$L$19 -> 10130507 | G19: =IF(ISERR(F19/$F$11),"",F19/$F$11) -> 0.01894429 | H19: =F19 -> 10130507 | I19: =IF(ISERR(H19/$H$11),"",H19/$H$11) -> 0.01894429 | J19: =[1]東大阪!$L$19 -> 3780080 | K19: =IF(ISERR(J19/$J$11),"",J19/$J$11) -> 0.4257873 | L19: =J19 -> 3780080 | M19: =IF(ISERR(L19/$L$11),"",L19/$L$11) -> 0.4257873 | N19: =[1]南港工場!$L$19 -> 6988011 | O19: =IF(ISERR(N19/$N$11),"",N19/$N$11) -> 0.24760451 | P19: =N19 -> 6988011 | Q19: =IF(ISERR(P19/$P$11),"",P19/$P$11) -> 0.24760451 | R19: =[1]南港事務!$L$19 -> 2788493 | S19: =IF(ISERR(R19/$R$11),"",R19/$R$11) | T19: =R19 -> 2788493 | U19: =IF(ISERR(T19/$T$11),"",T19/$T$11) | V19: =N19+R19 -> 9776504 | W19: =IF(ISERR(V19/$V$11),"",V19/$V$11) -> 0.34640851 | X19: =P19+T19 -> 9776504 | Y19: =IF(ISERR(X19/$X$11),"",X19/$X$11) -> 0.34640851 | Z19: =F19+J19+N19+R19 -> 23687091 | AA19: =IF(ISERR(Z19/$Z$11),"",Z19/$Z$11) -> 0.041421653 | AB19: =H19+L19+P19+T19 -> 23687091 | AC19: =IF(ISERR(AB19/$AB$11),"",AB19/$AB$11) -> 0.041421653 | AD19: =[1]東京事務!$L$19 -> 4513900 | AE19: =IF(ISERR(AD19/$AD$11),"",AD19/$AD$11) -> 0.018326749 | AF19: =AD19 -> 4513900 | AG19: =IF(ISERR(AF19/$AF$11),"",AF19/$AF$11) -> 0.018326749 | AH19: =[1]東京工場!$L$19 -> 4592338 | AI19: =IF(ISERR(AH19/$AH$11),"",AH19/$AH$11) -> 0.46812657 | AJ19: =AH19 -> 4592338 | AK19: =IF(ISERR(AJ19/$AJ$11),"",AJ19/$AJ$11) -> 0.46812657 | AL19: =AD19+AH19 -> 9106238 | AM19: =IF(ISERR(AL19/$AL$11),"",AL19/AL$11) -> 0.035555794 | AN19: =AF19+AJ19 -> 9106238 | AO19: =IF(ISERR(AN19/$AN$11),"",AN19/$AN$11) -> 0.035555794 | AP19: =B19+Z19+AL19 -> 38550129 | AQ19: =IF(ISERR(AP19/$AP$11),"",AP19/$AP$11) -> 0.046560146 | AR19: =D19+AB19+AN19 -> 38550129 | AS19: =IF(ISERR(AR19/$AR$11),"",AR19/$AR$11) -> 0.046560146 | AT19: =[1]全社合計!$N$19 -> 36878679 | AU19: =IF(ISERR(AT19/$AT$11),"",AT19/$AT$11) -> 0.038132956 | AV19: =AT19 -> 36878679 | AW19: =IF(ISERR(AV19/$AV$11),"",AV19/$AV$11) -> 0.038132956 | AX19: =AP19-AT19 -> 1671450 | AY19: =IF(ISERROR(AP19/AT19),"",AP19/AT19) -> 1.0453229 | AZ19: =AR19-AV19 -> 1671450 | BA19: =IF(ISERROR(AR19/AV19),"",AR19/AV19) -> 1.0453229
A20: 退職年金保険 | B20: =[1]本部!$L$20 -> 56110 | C20: =IF(ISERR(B20/$B$11),"",B20/$B$11) | D20: =B20 -> 56110 | E20: =IF(ISERR(D20/$D$11),"",D20/$D$11) | F20: =[1]本社営業!$L$20 -> 264862 | G20: =IF(ISERR(F20/$F$11),"",F20/$F$11) -> 0.00049529826 | H20: =F20 -> 264862 | I20: =IF(ISERR(H20/$H$11),"",H20/$H$11) -> 0.00049529826 | J20: =[1]東大阪!$L$20 -> 163642 | K20: =IF(ISERR(J20/$J$11),"",J20/$J$11) -> 0.018432595 | L20: =J20 -> 163642 | M20: =IF(ISERR(L20/$L$11),"",L20/$L$11) -> 0.018432595 | N20: =[1]南港工場!$L$20 -> 241330 | O20: =IF(ISERR(N20/$N$11),"",N20/$N$11) -> 0.0085509876 | P20: =N20 -> 241330 | Q20: =IF(ISERR(P20/$P$11),"",P20/$P$11) -> 0.0085509876 | R20: =[1]南港事務!$L$20 -> 88532 | S20: =IF(ISERR(R20/$R$11),"",R20/$R$11) | T20: =R20 -> 88532 | U20: =IF(ISERR(T20/$T$11),"",T20/$T$11) | V20: =N20+R20 -> 329862 | W20: =IF(ISERR(V20/$V$11),"",V20/$V$11) -> 0.011687921 | X20: =P20+T20 -> 329862 | Y20: =IF(ISERR(X20/$X$11),"",X20/$X$11) -> 0.011687921 | Z20: =F20+J20+N20+R20 -> 758366 | AA20: =IF(ISERR(Z20/$Z$11),"",Z20/$Z$11) -> 0.0013261558 | AB20: =H20+L20+P20+T20 -> 758366 | AC20: =IF(ISERR(AB20/$AB$11),"",AB20/$AB$11) -> 0.0013261558 | AD20: =[1]東京事務!$L$20 -> 124954 | AE20: =IF(ISERR(AD20/$AD$11),"",AD20/$AD$11) -> 0.00050732195 | AF20: =AD20 -> 124954 | AG20: =IF(ISERR(AF20/$AF$11),"",AF20/$AF$11) -> 0.00050732195 | AH20: =[1]東京工場!$L$20 -> 111642 | AI20: =IF(ISERR(AH20/$AH$11),"",AH20/$AH$11) -> 0.011380388 | AJ20: =AH20 -> 111642 | AK20: =IF(ISERR(AJ20/$AJ$11),"",AJ20/$AJ$11) -> 0.011380388 | AL20: =AD20+AH20 -> 236596 | AM20: =IF(ISERR(AL20/$AL$11),"",AL20/AL$11) -> 0.00092380175 | AN20: =AF20+AJ20 -> 236596 | AO20: =IF(ISERR(AN20/$AN$11),"",AN20/$AN$11) -> 0.00092380175 | AP20: =B20+Z20+AL20 -> 1051072 | AQ20: =IF(ISERR(AP20/$AP$11),"",AP20/$AP$11) -> 0.0012694657 | AR20: =D20+AB20+AN20 -> 1051072 | AS20: =IF(ISERR(AR20/$AR$11),"",AR20/$AR$11) -> 0.0012694657 | AT20: =[1]全社合計!$N$20 -> 1081228 | AU20: =IF(ISERR(AT20/$AT$11),"",AT20/$AT$11) -> 0.0011180015 | AV20: =AT20 -> 1081228 | AW20: =IF(ISERR(AV20/$AV$11),"",AV20/$AV$11) -> 0.0011180015 | AX20: =AP20-AT20 -> -30156 | AY20: =IF(ISERROR(AP20/AT20),"",AP20/AT20) -> 0.97210949 | AZ20: =AR20-AV20 -> -30156 | BA20: =IF(ISERROR(AR20/AV20),"",AR20/AV20) -> 0.97210949
A21: 退職金 | B21: =[1]本部!$L$21 -> 0 | C21: =IF(ISERR(B21/$B$11),"",B21/$B$11) | D21: =B21 -> 0 | E21: =IF(ISERR(D21/$D$11),"",D21/$D$11) | F21: =[1]本社営業!$L$21 -> 0 | G21: =IF(ISERR(F21/$F$11),"",F21/$F$11) -> 0 | H21: =F21 -> 0 | I21: =IF(ISERR(H21/$H$11),"",H21/$H$11) -> 0 | J21: =[1]東大阪!$L$21 -> 0 | K21: =IF(ISERR(J21/$J$11),"",J21/$J$11) -> 0 | L21: =J21 -> 0 | M21: =IF(ISERR(L21/$L$11),"",L21/$L$11) -> 0 | N21: =[1]南港工場!$L$21 -> 0 | O21: =IF(ISERR(N21/$N$11),"",N21/$N$11) -> 0 | P21: =N21 -> 0 | Q21: =IF(ISERR(P21/$P$11),"",P21/$P$11) -> 0 | R21: =[1]南港事務!$L$21 -> 0 | S21: =IF(ISERR(R21/$R$11),"",R21/$R$11) | T21: =R21 -> 0 | U21: =IF(ISERR(T21/$T$11),"",T21/$T$11) | V21: =N21+R21 -> 0 | W21: =IF(ISERR(V21/$V$11),"",V21/$V$11) -> 0 | X21: =P21+T21 -> 0 | Y21: =IF(ISERR(X21/$X$11),"",X21/$X$11) -> 0 | Z21: =F21+J21+N21+R21 -> 0 | AA21: =IF(ISERR(Z21/$Z$11),"",Z21/$Z$11) -> 0 | AB21: =H21+L21+P21+T21 -> 0 | AC21: =IF(ISERR(AB21/$AB$11),"",AB21/$AB$11) -> 0 | AD21: =[1]東京事務!$L$21 -> 0 | AE21: =IF(ISERR(AD21/$AD$11),"",AD21/$AD$11) -> 0 | AF21: =AD21 -> 0 | AG21: =IF(ISERR(AF21/$AF$11),"",AF21/$AF$11) -> 0 | AH21: =[1]東京工場!$L$21 -> 0 | AI21: =IF(ISERR(AH21/$AH$11),"",AH21/$AH$11) -> 0 | AJ21: =AH21 -> 0 | AK21: =IF(ISERR(AJ21/$AJ$11),"",AJ21/$AJ$11) -> 0 | AL21: =AD21+AH21 -> 0 | AM21: =IF(ISERR(AL21/$AL$11),"",AL21/AL$11) -> 0 | AN21: =AF21+AJ21 -> 0 | AO21: =IF(ISERR(AN21/$AN$11),"",AN21/$AN$11) -> 0 | AP21: =B21+Z21+AL21 -> 0 | AQ21: =IF(ISERR(AP21/$AP$11),"",AP21/$AP$11) -> 0 | AR21: =D21+AB21+AN21 -> 0 | AS21: =IF(ISERR(AR21/$AR$11),"",AR21/$AR$11) -> 0 | AT21: =[1]全社合計!$N$21 -> 0 | AU21: =IF(ISERR(AT21/$AT$11),"",AT21/$AT$11) -> 0 | AV21: =AT21 -> 0 | AW21: =IF(ISERR(AV21/$AV$11),"",AV21/$AV$11) -> 0 | AX21: =AP21-AT21 -> 0 | AY21: =IF(ISERROR(AP21/AT21),"",AP21/AT21) | AZ21: =AR21-AV21 -> 0 | BA21: =IF(ISERROR(AR21/AV21),"",AR21/AV21)
A22: 法定福利費 | B22: =[1]本部!$L$22 -> 0 | C22: =IF(ISERR(B22/$B$11),"",B22/$B$11) | D22: =B22 -> 0 | E22: =IF(ISERR(D22/$D$11),"",D22/$D$11) | F22: =[1]本社営業!$L$22 -> 0 | G22: =IF(ISERR(F22/$F$11),"",F22/$F$11) -> 0 | H22: =F22 -> 0 | I22: =IF(ISERR(H22/$H$11),"",H22/$H$11) -> 0 | J22: =[1]東大阪!$L$22 -> 0 | K22: =IF(ISERR(J22/$J$11),"",J22/$J$11) -> 0 | L22: =J22 -> 0 | M22: =IF(ISERR(L22/$L$11),"",L22/$L$11) -> 0 | N22: =[1]南港工場!$L$22 -> 0 | O22: =IF(ISERR(N22/$N$11),"",N22/$N$11) -> 0 | P22: =N22 -> 0 | Q22: =IF(ISERR(P22/$P$11),"",P22/$P$11) -> 0 | R22: =[1]南港事務!$L$22 -> 0 | S22: =IF(ISERR(R22/$R$11),"",R22/$R$11) | T22: =R22 -> 0 | U22: =IF(ISERR(T22/$T$11),"",T22/$T$11) | V22: =N22+R22 -> 0 | W22: =IF(ISERR(V22/$V$11),"",V22/$V$11) -> 0 | X22: =P22+T22 -> 0 | Y22: =IF(ISERR(X22/$X$11),"",X22/$X$11) -> 0 | Z22: =F22+J22+N22+R22 -> 0 | AA22: =IF(ISERR(Z22/$Z$11),"",Z22/$Z$11) -> 0 | AB22: =H22+L22+P22+T22 -> 0 | AC22: =IF(ISERR(AB22/$AB$11),"",AB22/$AB$11) -> 0 | AD22: =[1]東京事務!$L$22 -> 0 | AE22: =IF(ISERR(AD22/$AD$11),"",AD22/$AD$11) -> 0 | AF22: =AD22 -> 0 | AG22: =IF(ISERR(AF22/$AF$11),"",AF22/$AF$11) -> 0 | AH22: =[1]東京工場!$L$22 -> 0 | AI22: =IF(ISERR(AH22/$AH$11),"",AH22/$AH$11) -> 0 | AJ22: =AH22 -> 0 | AK22: =IF(ISERR(AJ22/$AJ$11),"",AJ22/$AJ$11) -> 0 | AL22: =AD22+AH22 -> 0 | AM22: =IF(ISERR(AL22/$AL$11),"",AL22/AL$11) -> 0 | AN22: =AF22+AJ22 -> 0 | AO22: =IF(ISERR(AN22/$AN$11),"",AN22/$AN$11) -> 0 | AP22: =B22+Z22+AL22 -> 0 | AQ22: =IF(ISERR(AP22/$AP$11),"",AP22/$AP$11) -> 0 | AR22: =D22+AB22+AN22 -> 0 | AS22: =IF(ISERR(AR22/$AR$11),"",AR22/$AR$11) -> 0 | AT22: =[1]全社合計!$N$22 -> 0 | AU22: =IF(ISERR(AT22/$AT$11),"",AT22/$AT$11) -> 0 | AV22: =AT22 -> 0 | AW22: =IF(ISERR(AV22/$AV$11),"",AV22/$AV$11) -> 0 | AX22: =AP22-AT22 -> 0 | AY22: =IF(ISERROR(AP22/AT22),"",AP22/AT22) | AZ22: =AR22-AV22 -> 0 | BA22: =IF(ISERROR(AR22/AV22),"",AR22/AV22)
A23: 厚生費 | B23: =[1]本部!$L$23 -> 535788 | C23: =IF(ISERR(B23/$B$11),"",B23/$B$11) | D23: =B23 -> 535788 | E23: =IF(ISERR(D23/$D$11),"",D23/$D$11) | F23: =[1]本社営業!$L$23 -> 101166 | G23: =IF(ISERR(F23/$F$11),"",F23/$F$11) -> 0.00018918283 | H23: =F23 -> 101166 | I23: =IF(ISERR(H23/$H$11),"",H23/$H$11) -> 0.00018918283 | J23: =[1]東大阪!$L$23 -> 63391 | K23: =IF(ISERR(J23/$J$11),"",J23/$J$11) -> 0.0071403469 | L23: =J23 -> 63391 | M23: =IF(ISERR(L23/$L$11),"",L23/$L$11) -> 0.0071403469 | N23: =[1]南港工場!$L$23 -> 73890 | O23: =IF(ISERR(N23/$N$11),"",N23/$N$11) -> 0.0026181265 | P23: =N23 -> 73890 | Q23: =IF(ISERR(P23/$P$11),"",P23/$P$11) -> 0.0026181265 | R23: =[1]南港事務!$L$23 -> 52641 | S23: =IF(ISERR(R23/$R$11),"",R23/$R$11) | T23: =R23 -> 52641 | U23: =IF(ISERR(T23/$T$11),"",T23/$T$11) | V23: =N23+R23 -> 126531 | W23: =IF(ISERR(V23/$V$11),"",V23/$V$11) -> 0.0044833424 | X23: =P23+T23 -> 126531 | Y23: =IF(ISERR(X23/$X$11),"",X23/$X$11) -> 0.0044833424 | Z23: =F23+J23+N23+R23 -> 291088 | AA23: =IF(ISERR(Z23/$Z$11),"",Z23/$Z$11) -> 0.00050902604 | AB23: =H23+L23+P23+T23 -> 291088 | AC23: =IF(ISERR(AB23/$AB$11),"",AB23/$AB$11) -> 0.00050902604 | AD23: =[1]東京事務!$L$23 -> 54263 | AE23: =IF(ISERR(AD23/$AD$11),"",AD23/$AD$11) -> 0.00022031156 | AF23: =AD23 -> 54263 | AG23: =IF(ISERR(AF23/$AF$11),"",AF23/$AF$11) -> 0.00022031156 | AH23: =[1]東京工場!$L$23 -> 53739 | AI23: =IF(ISERR(AH23/$AH$11),"",AH23/$AH$11) -> 0.0054779621 | AJ23: =AH23 -> 53739 | AK23: =IF(ISERR(AJ23/$AJ$11),"",AJ23/$AJ$11) -> 0.0054779621 | AL23: =AD23+AH23 -> 108002 | AM23: =IF(ISERR(AL23/$AL$11),"",AL23/AL$11) -> 0.00042169959 | AN23: =AF23+AJ23 -> 108002 | AO23: =IF(ISERR(AN23/$AN$11),"",AN23/$AN$11) -> 0.00042169959 | AP23: =B23+Z23+AL23 -> 934878 | AQ23: =IF(ISERR(AP23/$AP$11),"",AP23/$AP$11) -> 0.0011291287 | AR23: =D23+AB23+AN23 -> 934878 | AS23: =IF(ISERR(AR23/$AR$11),"",AR23/$AR$11) -> 0.0011291287 | AT23: =[1]全社合計!$N$23 -> 899087 | AU23: =IF(ISERR(AT23/$AT$11),"",AT23/$AT$11) -> 0.00092966576 | AV23: =AT23 -> 899087 | AW23: =IF(ISERR(AV23/$AV$11),"",AV23/$AV$11) -> 0.00092966576 | AX23: =AP23-AT23 -> 35791 | AY23: =IF(ISERROR(AP23/AT23),"",AP23/AT23) -> 1.0398082 | AZ23: =AR23-AV23 -> 35791 | BA23: =IF(ISERROR(AR23/AV23),"",AR23/AV23) -> 1.0398082
A24: 賃借料 | B24: =[1]本部!$L$24 -> 45000 | C24: =IF(ISERR(B24/$B$11),"",B24/$B$11) | D24: =B24 -> 45000 | E24: =IF(ISERR(D24/$D$11),"",D24/$D$11) | F24: =[1]本社営業!$L$24 -> 853650 | G24: =IF(ISERR(F24/$F$11),"",F24/$F$11) -> 0.0015963459 | H24: =F24 -> 853650 | I24: =IF(ISERR(H24/$H$11),"",H24/$H$11) -> 0.0015963459 | J24: =[1]東大阪!$L$24 -> 96410 | K24: =IF(ISERR(J24/$J$11),"",J24/$J$11) -> 0.010859599 | L24: =J24 -> 96410 | M24: =IF(ISERR(L24/$L$11),"",L24/$L$11) -> 0.010859599 | N24: =[1]南港工場!$L$24 -> 28600 | O24: =IF(ISERR(N24/$N$11),"",N24/$N$11) -> 0.0010133769 | P24: =N24 -> 28600 | Q24: =IF(ISERR(P24/$P$11),"",P24/$P$11) -> 0.0010133769 | R24: =[1]南港事務!$L$24 -> 0 | S24: =IF(ISERR(R24/$R$11),"",R24/$R$11) | T24: =R24 -> 0 | U24: =IF(ISERR(T24/$T$11),"",T24/$T$11) | V24: =N24+R24 -> 28600 | W24: =IF(ISERR(V24/$V$11),"",V24/$V$11) -> 0.0010133769 | X24: =P24+T24 -> 28600 | Y24: =IF(ISERR(X24/$X$11),"",X24/$X$11) -> 0.0010133769 | Z24: =F24+J24+N24+R24 -> 978660 | AA24: =IF(ISERR(Z24/$Z$11),"",Z24/$Z$11) -> 0.0017113843 | AB24: =H24+L24+P24+T24 -> 978660 | AC24: =IF(ISERR(AB24/$AB$11),"",AB24/$AB$11) -> 0.0017113843 | AD24: =[1]東京事務!$L$24 -> 143500 | AE24: =IF(ISERR(AD24/$AD$11),"",AD24/$AD$11) -> 0.00058262 | AF24: =AD24 -> 143500 | AG24: =IF(ISERR(AF24/$AF$11),"",AF24/$AF$11) -> 0.00058262 | AH24: =[1]東京工場!$L$24 -> 0 | AI24: =IF(ISERR(AH24/$AH$11),"",AH24/$AH$11) -> 0 | AJ24: =AH24 -> 0 | AK24: =IF(ISERR(AJ24/$AJ$11),"",AJ24/$AJ$11) -> 0 | AL24: =AD24+AH24 -> 143500 | AM24: =IF(ISERR(AL24/$AL$11),"",AL24/AL$11) -> 0.00056030344 | AN24: =AF24+AJ24 -> 143500 | AO24: =IF(ISERR(AN24/$AN$11),"",AN24/$AN$11) -> 0.00056030344 | AP24: =B24+Z24+AL24 -> 1167160 | AQ24: =IF(ISERR(AP24/$AP$11),"",AP24/$AP$11) -> 0.0014096747 | AR24: =D24+AB24+AN24 -> 1167160 | AS24: =IF(ISERR(AR24/$AR$11),"",AR24/$AR$11) -> 0.0014096747 | AT24: =[1]全社合計!$N$24 -> 1127978 | AU24: =IF(ISERR(AT24/$AT$11),"",AT24/$AT$11) -> 0.0011663415 | AV24: =AT24 -> 1127978 | AW24: =IF(ISERR(AV24/$AV$11),"",AV24/$AV$11) -> 0.0011663415 | AX24: =AP24-AT24 -> 39182 | AY24: =IF(ISERROR(AP24/AT24),"",AP24/AT24) -> 1.0347365 | AZ24: =AR24-AV24 -> 39182 | BA24: =IF(ISERROR(AR24/AV24),"",AR24/AV24) -> 1.0347365
A25: リース料 | B25: =[1]本部!$L$25 -> 129379 | C25: =IF(ISERR(B25/$B$11),"",B25/$B$11) | D25: =B25 -> 129379 | E25: =IF(ISERR(D25/$D$11),"",D25/$D$11) | F25: =[1]本社営業!$L$25 -> 86370 | G25: =IF(ISERR(F25/$F$11),"",F25/$F$11) -> 0.00016151396 | H25: =F25 -> 86370 | I25: =IF(ISERR(H25/$H$11),"",H25/$H$11) -> 0.00016151396 | J25: =[1]東大阪!$L$25 -> 10180 | K25: =IF(ISERR(J25/$J$11),"",J25/$J$11) -> 0.0011466727 | L25: =J25 -> 10180 | M25: =IF(ISERR(L25/$L$11),"",L25/$L$11) -> 0.0011466727 | N25: =[1]南港工場!$L$25 -> 0 | O25: =IF(ISERR(N25/$N$11),"",N25/$N$11) -> 0 | P25: =N25 -> 0 | Q25: =IF(ISERR(P25/$P$11),"",P25/$P$11) -> 0 | R25: =[1]南港事務!$L$25 -> 10180 | S25: =IF(ISERR(R25/$R$11),"",R25/$R$11) | T25: =R25 -> 10180 | U25: =IF(ISERR(T25/$T$11),"",T25/$T$11) | V25: =N25+R25 -> 10180 | W25: =IF(ISERR(V25/$V$11),"",V25/$V$11) -> 0.00036070548 | X25: =P25+T25 -> 10180 | Y25: =IF(ISERR(X25/$X$11),"",X25/$X$11) -> 0.00036070548 | Z25: =F25+J25+N25+R25 -> 106730 | AA25: =IF(ISERR(Z25/$Z$11),"",Z25/$Z$11) -> 0.00018663892 | AB25: =H25+L25+P25+T25 -> 106730 | AC25: =IF(ISERR(AB25/$AB$11),"",AB25/$AB$11) -> 0.00018663892 | AD25: =[1]東京事務!$L$25 -> 18542 | AE25: =IF(ISERR(AD25/$AD$11),"",AD25/$AD$11) -> 7.5281812e-05 | AF25: =AD25 -> 18542 | AG25: =IF(ISERR(AF25/$AF$11),"",AF25/$AF$11) -> 7.5281812e-05 | AH25: =[1]東京工場!$L$25 -> 8300 | AI25: =IF(ISERR(AH25/$AH$11),"",AH25/$AH$11) -> 0.00084607241 | AJ25: =AH25 -> 8300 | AK25: =IF(ISERR(AJ25/$AJ$11),"",AJ25/$AJ$11) -> 0.00084607241 | AL25: =AD25+AH25 -> 26842 | AM25: =IF(ISERR(AL25/$AL$11),"",AL25/AL$11) -> 0.00010480603 | AN25: =AF25+AJ25 -> 26842 | AO25: =IF(ISERR(AN25/$AN$11),"",AN25/$AN$11) -> 0.00010480603 | AP25: =B25+Z25+AL25 -> 262951 | AQ25: =IF(ISERR(AP25/$AP$11),"",AP25/$AP$11) -> 0.00031758745 | AR25: =D25+AB25+AN25 -> 262951 | AS25: =IF(ISERR(AR25/$AR$11),"",AR25/$AR$11) -> 0.00031758745 | AT25: =[1]全社合計!$N$25 -> 240981 | AU25: =IF(ISERR(AT25/$AT$11),"",AT25/$AT$11) -> 0.00024917698 | AV25: =AT25 -> 240981 | AW25: =IF(ISERR(AV25/$AV$11),"",AV25/$AV$11) -> 0.00024917698 | AX25: =AP25-AT25 -> 21970 | AY25: =IF(ISERROR(AP25/AT25),"",AP25/AT25) -> 1.091169 | AZ25: =AR25-AV25 -> 21970 | BA25: =IF(ISERROR(AR25/AV25),"",AR25/AV25) -> 1.091169
A26: 保守料 | B26: =[1]本部!$L$26 -> 328701 | C26: =IF(ISERR(B26/$B$11),"",B26/$B$11) | D26: =B26 -> 328701 | E26: =IF(ISERR(D26/$D$11),"",D26/$D$11) | F26: =[1]本社営業!$L$26 -> 680 | G26: =IF(ISERR(F26/$F$11),"",F26/$F$11) -> 1.2716162e-06 | H26: =F26 -> 680 | I26: =IF(ISERR(H26/$H$11),"",H26/$H$11) -> 1.2716162e-06 | J26: =[1]東大阪!$L$26 -> 7170 | K26: =IF(ISERR(J26/$J$11),"",J26/$J$11) -> 0.00080762706 | L26: =J26 -> 7170 | M26: =IF(ISERR(L26/$L$11),"",L26/$L$11) -> 0.00080762706 | N26: =[1]南港工場!$L$26 -> 0 | O26: =IF(ISERR(N26/$N$11),"",N26/$N$11) -> 0 | P26: =N26 -> 0 | Q26: =IF(ISERR(P26/$P$11),"",P26/$P$11) -> 0 | R26: =[1]南港事務!$L$26 -> 5520 | S26: =IF(ISERR(R26/$R$11),"",R26/$R$11) | T26: =R26 -> 5520 | U26: =IF(ISERR(T26/$T$11),"",T26/$T$11) | V26: =N26+R26 -> 5520 | W26: =IF(ISERR(V26/$V$11),"",V26/$V$11) -> 0.00019558883 | X26: =P26+T26 -> 5520 | Y26: =IF(ISERR(X26/$X$11),"",X26/$X$11) -> 0.00019558883 | Z26: =F26+J26+N26+R26 -> 13370 | AA26: =IF(ISERR(Z26/$Z$11),"",Z26/$Z$11) -> 2.338014e-05 | AB26: =H26+L26+P26+T26 -> 13370 | AC26: =IF(ISERR(AB26/$AB$11),"",AB26/$AB$11) -> 2.338014e-05 | AD26: =[1]東京事務!$L$26 -> 7170 | AE26: =IF(ISERR(AD26/$AD$11),"",AD26/$AD$11) -> 2.91107e-05 | AF26: =AD26 -> 7170 | AG26: =IF(ISERR(AF26/$AF$11),"",AF26/$AF$11) -> 2.91107e-05 | AH26: =[1]東京工場!$L$26 -> 13000 | AI26: =IF(ISERR(AH26/$AH$11),"",AH26/$AH$11) -> 0.0013251737 | AJ26: =AH26 -> 13000 | AK26: =IF(ISERR(AJ26/$AJ$11),"",AJ26/$AJ$11) -> 0.0013251737 | AL26: =AD26+AH26 -> 20170 | AM26: =IF(ISERR(AL26/$AL$11),"",AL26/AL$11) -> 7.8754845e-05 | AN26: =AF26+AJ26 -> 20170 | AO26: =IF(ISERR(AN26/$AN$11),"",AN26/$AN$11) -> 7.8754845e-05 | AP26: =B26+Z26+AL26 -> 362241 | AQ26: =IF(ISERR(AP26/$AP$11),"",AP26/$AP$11) -> 0.0004375081 | AR26: =D26+AB26+AN26 -> 362241 | AS26: =IF(ISERR(AR26/$AR$11),"",AR26/$AR$11) -> 0.0004375081 | AT26: =[1]全社合計!$N$26 -> 377291 | AU26: =IF(ISERR(AT26/$AT$11),"",AT26/$AT$11) -> 0.00039012301 | AV26: =AT26 -> 377291 | AW26: =IF(ISERR(AV26/$AV$11),"",AV26/$AV$11) -> 0.00039012301 | AX26: =AP26-AT26 -> -15050 | AY26: =IF(ISERROR(AP26/AT26),"",AP26/AT26) -> 0.96011037 | AZ26: =AR26-AV26 -> -15050 | BA26: =IF(ISERROR(AR26/AV26),"",AR26/AV26) -> 0.96011037
A27: 修繕費 | B27: =[1]本部!$L$27 -> 0 | C27: =IF(ISERR(B27/$B$11),"",B27/$B$11) | D27: =B27 -> 0 | E27: =IF(ISERR(D27/$D$11),"",D27/$D$11) | F27: =[1]本社営業!$L$27 -> 0 | G27: =IF(ISERR(F27/$F$11),"",F27/$F$11) -> 0 | H27: =F27 -> 0 | I27: =IF(ISERR(H27/$H$11),"",H27/$H$11) -> 0 | J27: =[1]東大阪!$L$27 -> 14400 | K27: =IF(ISERR(J27/$J$11),"",J27/$J$11) -> 0.0016220125 | L27: =J27 -> 14400 | M27: =IF(ISERR(L27/$L$11),"",L27/$L$11) -> 0.0016220125 | N27: =[1]南港工場!$L$27 -> 55610 | O27: =IF(ISERR(N27/$N$11),"",N27/$N$11) -> 0.0019704157 | P27: =N27 -> 55610 | Q27: =IF(ISERR(P27/$P$11),"",P27/$P$11) -> 0.0019704157 | R27: =[1]南港事務!$L$27 -> 0 | S27: =IF(ISERR(R27/$R$11),"",R27/$R$11) | T27: =R27 -> 0 | U27: =IF(ISERR(T27/$T$11),"",T27/$T$11) | V27: =N27+R27 -> 55610 | W27: =IF(ISERR(V27/$V$11),"",V27/$V$11) -> 0.0019704157 | X27: =P27+T27 -> 55610 | Y27: =IF(ISERR(X27/$X$11),"",X27/$X$11) -> 0.0019704157 | Z27: =F27+J27+N27+R27 -> 70010 | AA27: =IF(ISERR(Z27/$Z$11),"",Z27/$Z$11) -> 0.0001224266 | AB27: =H27+L27+P27+T27 -> 70010 | AC27: =IF(ISERR(AB27/$AB$11),"",AB27/$AB$11) -> 0.0001224266 | AD27: =[1]東京事務!$L$27 -> 0 | AE27: =IF(ISERR(AD27/$AD$11),"",AD27/$AD$11) -> 0 | AF27: =AD27 -> 0 | AG27: =IF(ISERR(AF27/$AF$11),"",AF27/$AF$11) -> 0 | AH27: =[1]東京工場!$L$27 -> 45900 | AI27: =IF(ISERR(AH27/$AH$11),"",AH27/$AH$11) -> 0.0046788824 | AJ27: =AH27 -> 45900 | AK27: =IF(ISERR(AJ27/$AJ$11),"",AJ27/$AJ$11) -> 0.0046788824 | AL27: =AD27+AH27 -> 45900 | AM27: =IF(ISERR(AL27/$AL$11),"",AL27/AL$11) -> 0.00017921901 | AN27: =AF27+AJ27 -> 45900 | AO27: =IF(ISERR(AN27/$AN$11),"",AN27/$AN$11) -> 0.00017921901 | AP27: =B27+Z27+AL27 -> 115910 | AQ27: =IF(ISERR(AP27/$AP$11),"",AP27/$AP$11) -> 0.00013999399 | AR27: =D27+AB27+AN27 -> 115910 | AS27: =IF(ISERR(AR27/$AR$11),"",AR27/$AR$11) -> 0.00013999399 | AT27: =[1]全社合計!$N$27 -> 600000 | AU27: =IF(ISERR(AT27/$AT$11),"",AT27/$AT$11) -> 0.00062040654 | AV27: =AT27 -> 600000 | AW27: =IF(ISERR(AV27/$AV$11),"",AV27/$AV$11) -> 0.00062040654 | AX27: =AP27-AT27 -> -484090 | AY27: =IF(ISERROR(AP27/AT27),"",AP27/AT27) -> 0.19318333 | AZ27: =AR27-AV27 -> -484090 | BA27: =IF(ISERROR(AR27/AV27),"",AR27/AV27) -> 0.19318333
A28: 事務用消耗品費 | B28: =[1]本部!$L$28 -> 377326 | C28: =IF(ISERR(B28/$B$11),"",B28/$B$11) | D28: =B28 -> 377326 | E28: =IF(ISERR(D28/$D$11),"",D28/$D$11) | F28: =[1]本社営業!$L$28 -> 104894 | G28: =IF(ISERR(F28/$F$11),"",F28/$F$11) -> 0.00019615428 | H28: =F28 -> 104894 | I28: =IF(ISERR(H28/$H$11),"",H28/$H$11) -> 0.00019615428 | J28: =[1]東大阪!$L$28 -> 4120 | K28: =IF(ISERR(J28/$J$11),"",J28/$J$11) -> 0.0004640758 | L28: =J28 -> 4120 | M28: =IF(ISERR(L28/$L$11),"",L28/$L$11) -> 0.0004640758 | N28: =[1]南港工場!$L$28 -> 0 | O28: =IF(ISERR(N28/$N$11),"",N28/$N$11) -> 0 | P28: =N28 -> 0 | Q28: =IF(ISERR(P28/$P$11),"",P28/$P$11) -> 0 | R28: =[1]南港事務!$L$28 -> 4108 | S28: =IF(ISERR(R28/$R$11),"",R28/$R$11) | T28: =R28 -> 4108 | U28: =IF(ISERR(T28/$T$11),"",T28/$T$11) | V28: =N28+R28 -> 4108 | W28: =IF(ISERR(V28/$V$11),"",V28/$V$11) -> 0.00014555777 | X28: =P28+T28 -> 4108 | Y28: =IF(ISERR(X28/$X$11),"",X28/$X$11) -> 0.00014555777 | Z28: =F28+J28+N28+R28 -> 113122 | AA28: =IF(ISERR(Z28/$Z$11),"",Z28/$Z$11) -> 0.00019781662 | AB28: =H28+L28+P28+T28 -> 113122 | AC28: =IF(ISERR(AB28/$AB$11),"",AB28/$AB$11) -> 0.00019781662 | AD28: =[1]東京事務!$L$28 -> 0 | AE28: =IF(ISERR(AD28/$AD$11),"",AD28/$AD$11) -> 0 | AF28: =AD28 -> 0 | AG28: =IF(ISERR(AF28/$AF$11),"",AF28/$AF$11) -> 0 | AH28: =[1]東京工場!$L$28 -> 0 | AI28: =IF(ISERR(AH28/$AH$11),"",AH28/$AH$11) -> 0 | AJ28: =AH28 -> 0 | AK28: =IF(ISERR(AJ28/$AJ$11),"",AJ28/$AJ$11) -> 0 | AL28: =AD28+AH28 -> 0 | AM28: =IF(ISERR(AL28/$AL$11),"",AL28/AL$11) -> 0 | AN28: =AF28+AJ28 -> 0 | AO28: =IF(ISERR(AN28/$AN$11),"",AN28/$AN$11) -> 0 | AP28: =B28+Z28+AL28 -> 490448 | AQ28: =IF(ISERR(AP28/$AP$11),"",AP28/$AP$11) -> 0.00059235419 | AR28: =D28+AB28+AN28 -> 490448 | AS28: =IF(ISERR(AR28/$AR$11),"",AR28/$AR$11) -> 0.00059235419 | AT28: =[1]全社合計!$N$28 -> 367814 | AU28: =IF(ISERR(AT28/$AT$11),"",AT28/$AT$11) -> 0.00038032369 | AV28: =AT28 -> 367814 | AW28: =IF(ISERR(AV28/$AV$11),"",AV28/$AV$11) -> 0.00038032369 | AX28: =AP28-AT28 -> 122634 | AY28: =IF(ISERROR(AP28/AT28),"",AP28/AT28) -> 1.3334131 | AZ28: =AR28-AV28 -> 122634 | BA28: =IF(ISERROR(AR28/AV28),"",AR28/AV28) -> 1.3334131
A29: 消耗品費 | B29: =[1]本部!$L$29 -> 0 | C29: =IF(ISERR(B29/$B$11),"",B29/$B$11) | D29: =B29 -> 0 | E29: =IF(ISERR(D29/$D$11),"",D29/$D$11) | F29: =[1]本社営業!$L$29 -> 22000 | G29: =IF(ISERR(F29/$F$11),"",F29/$F$11) -> 4.1140525e-05 | H29: =F29 -> 22000 | I29: =IF(ISERR(H29/$H$11),"",H29/$H$11) -> 4.1140525e-05 | J29: =[1]東大阪!$L$29 -> 268490 | K29: =IF(ISERR(J29/$J$11),"",J29/$J$11) -> 0.030242649 | L29: =J29 -> 268490 | M29: =IF(ISERR(L29/$L$11),"",L29/$L$11) -> 0.030242649 | N29: =[1]南港工場!$L$29 -> 809706 | O29: =IF(ISERR(N29/$N$11),"",N29/$N$11) -> 0.028690117 | P29: =N29 -> 809706 | Q29: =IF(ISERR(P29/$P$11),"",P29/$P$11) -> 0.028690117 | R29: =[1]南港事務!$L$29 -> 0 | S29: =IF(ISERR(R29/$R$11),"",R29/$R$11) | T29: =R29 -> 0 | U29: =IF(ISERR(T29/$T$11),"",T29/$T$11) | V29: =N29+R29 -> 809706 | W29: =IF(ISERR(V29/$V$11),"",V29/$V$11) -> 0.028690117 | X29: =P29+T29 -> 809706 | Y29: =IF(ISERR(X29/$X$11),"",X29/$X$11) -> 0.028690117 | Z29: =F29+J29+N29+R29 -> 1100196 | AA29: =IF(ISERR(Z29/$Z$11),"",Z29/$Z$11) -> 0.0019239145 | AB29: =H29+L29+P29+T29 -> 1100196 | AC29: =IF(ISERR(AB29/$AB$11),"",AB29/$AB$11) -> 0.0019239145 | AD29: =[1]東京事務!$L$29 -> 0 | AE29: =IF(ISERR(AD29/$AD$11),"",AD29/$AD$11) -> 0 | AF29: =AD29 -> 0 | AG29: =IF(ISERR(AF29/$AF$11),"",AF29/$AF$11) -> 0 | AH29: =[1]東京工場!$L$29 -> 228538 | AI29: =IF(ISERR(AH29/$AH$11),"",AH29/$AH$11) -> 0.023296349 | AJ29: =AH29 -> 228538 | AK29: =IF(ISERR(AJ29/$AJ$11),"",AJ29/$AJ$11) -> 0.023296349 | AL29: =AD29+AH29 -> 228538 | AM29: =IF(ISERR(AL29/$AL$11),"",AL29/AL$11) -> 0.00089233886 | AN29: =AF29+AJ29 -> 228538 | AO29: =IF(ISERR(AN29/$AN$11),"",AN29/$AN$11) -> 0.00089233886 | AP29: =B29+Z29+AL29 -> 1328734 | AQ29: =IF(ISERR(AP29/$AP$11),"",AP29/$AP$11) -> 0.0016048208 | AR29: =D29+AB29+AN29 -> 1328734 | AS29: =IF(ISERR(AR29/$AR$11),"",AR29/$AR$11) -> 0.0016048208 | AT29: =[1]全社合計!$N$29 -> 896717 | AU29: =IF(ISERR(AT29/$AT$11),"",AT29/$AT$11) -> 0.00092721515 | AV29: =AT29 -> 896717 | AW29: =IF(ISERR(AV29/$AV$11),"",AV29/$AV$11) -> 0.00092721515 | AX29: =AP29-AT29 -> 432017 | AY29: =IF(ISERROR(AP29/AT29),"",AP29/AT29) -> 1.4817763 | AZ29: =AR29-AV29 -> 432017 | BA29: =IF(ISERROR(AR29/AV29),"",AR29/AV29) -> 1.4817763
A30: 水道光熱費 | B30: =[1]本部!$L$30 -> 12910 | C30: =IF(ISERR(B30/$B$11),"",B30/$B$11) | D30: =B30 -> 12910 | E30: =IF(ISERR(D30/$D$11),"",D30/$D$11) | F30: =[1]本社営業!$L$30 -> 25821 | G30: =IF(ISERR(F30/$F$11),"",F30/$F$11) -> 4.8285886e-05 | H30: =F30 -> 25821 | I30: =IF(ISERR(H30/$H$11),"",H30/$H$11) -> 4.8285886e-05 | J30: =[1]東大阪!$L$30 -> 433946 | K30: =IF(ISERR(J30/$J$11),"",J30/$J$11) -> 0.048879572 | L30: =J30 -> 433946 | M30: =IF(ISERR(L30/$L$11),"",L30/$L$11) -> 0.048879572 | N30: =[1]南港工場!$L$30 -> 586335 | O30: =IF(ISERR(N30/$N$11),"",N30/$N$11) -> 0.020775466 | P30: =N30 -> 586335 | Q30: =IF(ISERR(P30/$P$11),"",P30/$P$11) -> 0.020775466 | R30: =[1]南港事務!$L$30 -> 21731 | S30: =IF(ISERR(R30/$R$11),"",R30/$R$11) | T30: =R30 -> 21731 | U30: =IF(ISERR(T30/$T$11),"",T30/$T$11) | V30: =N30+R30 -> 608066 | W30: =IF(ISERR(V30/$V$11),"",V30/$V$11) -> 0.021545456 | X30: =P30+T30 -> 608066 | Y30: =IF(ISERR(X30/$X$11),"",X30/$X$11) -> 0.021545456 | Z30: =F30+J30+N30+R30 -> 1067833 | AA30: =IF(ISERR(Z30/$Z$11),"",Z30/$Z$11) -> 0.0018673212 | AB30: =H30+L30+P30+T30 -> 1067833 | AC30: =IF(ISERR(AB30/$AB$11),"",AB30/$AB$11) -> 0.0018673212 | AD30: =[1]東京事務!$L$30 -> 45961 | AE30: =IF(ISERR(AD30/$AD$11),"",AD30/$AD$11) -> 0.00018660486 | AF30: =AD30 -> 45961 | AG30: =IF(ISERR(AF30/$AF$11),"",AF30/$AF$11) -> 0.00018660486 | AH30: =[1]東京工場!$L$30 -> 199518 | AI30: =IF(ISERR(AH30/$AH$11),"",AH30/$AH$11) -> 0.020338154 | AJ30: =AH30 -> 199518 | AK30: =IF(ISERR(AJ30/$AJ$11),"",AJ30/$AJ$11) -> 0.020338154 | AL30: =AD30+AH30 -> 245479 | AM30: =IF(ISERR(AL30/$AL$11),"",AL30/AL$11) -> 0.0009584859 | AN30: =AF30+AJ30 -> 245479 | AO30: =IF(ISERR(AN30/$AN$11),"",AN30/$AN$11) -> 0.0009584859 | AP30: =B30+Z30+AL30 -> 1326222 | AQ30: =IF(ISERR(AP30/$AP$11),"",AP30/$AP$11) -> 0.0016017869 | AR30: =D30+AB30+AN30 -> 1326222 | AS30: =IF(ISERR(AR30/$AR$11),"",AR30/$AR$11) -> 0.0016017869 | AT30: =[1]全社合計!$N$30 -> 1323813 | AU30: =IF(ISERR(AT30/$AT$11),"",AT30/$AT$11) -> 0.0013688371 | AV30: =AT30 -> 1323813 | AW30: =IF(ISERR(AV30/$AV$11),"",AV30/$AV$11) -> 0.0013688371 | AX30: =AP30-AT30 -> 2409 | AY30: =IF(ISERROR(AP30/AT30),"",AP30/AT30) -> 1.0018197 | AZ30: =AR30-AV30 -> 2409 | BA30: =IF(ISERROR(AR30/AV30),"",AR30/AV30) -> 1.0018197
A31: 旅費交通費 | B31: =[1]本部!$L$31 -> 189304 | C31: =IF(ISERR(B31/$B$11),"",B31/$B$11) | D31: =B31 -> 189304 | E31: =IF(ISERR(D31/$D$11),"",D31/$D$11) | F31: =[1]本社営業!$L$31 -> 715946 | G31: =IF(ISERR(F31/$F$11),"",F31/$F$11) -> 0.0013388361 | H31: =F31 -> 715946 | I31: =IF(ISERR(H31/$H$11),"",H31/$H$11) -> 0.0013388361 | J31: =[1]東大阪!$L$31 -> 112818 | K31: =IF(ISERR(J31/$J$11),"",J31/$J$11) -> 0.012707792 | L31: =J31 -> 112818 | M31: =IF(ISERR(L31/$L$11),"",L31/$L$11) -> 0.012707792 | N31: =[1]南港工場!$L$31 -> 265719 | O31: =IF(ISERR(N31/$N$11),"",N31/$N$11) -> 0.0094151572 | P31: =N31 -> 265719 | Q31: =IF(ISERR(P31/$P$11),"",P31/$P$11) -> 0.0094151572 | R31: =[1]南港事務!$L$31 -> 130777 | S31: =IF(ISERR(R31/$R$11),"",R31/$R$11) | T31: =R31 -> 130777 | U31: =IF(ISERR(T31/$T$11),"",T31/$T$11) | V31: =N31+R31 -> 396496 | W31: =IF(ISERR(V31/$V$11),"",V31/$V$11) -> 0.014048947 | X31: =P31+T31 -> 396496 | Y31: =IF(ISERR(X31/$X$11),"",X31/$X$11) -> 0.014048947 | Z31: =F31+J31+N31+R31 -> 1225260 | AA31: =IF(ISERR(Z31/$Z$11),"",Z31/$Z$11) -> 0.0021426141 | AB31: =H31+L31+P31+T31 -> 1225260 | AC31: =IF(ISERR(AB31/$AB$11),"",AB31/$AB$11) -> 0.0021426141 | AD31: =[1]東京事務!$L$31 -> 336941 | AE31: =IF(ISERR(AD31/$AD$11),"",AD31/$AD$11) -> 0.0013680039 | AF31: =AD31 -> 336941 | AG31: =IF(ISERR(AF31/$AF$11),"",AF31/$AF$11) -> 0.0013680039 | AH31: =[1]東京工場!$L$31 -> 174855 | AI31: =IF(ISERR(AH31/$AH$11),"",AH31/$AH$11) -> 0.017824095 | AJ31: =AH31 -> 174855 | AK31: =IF(ISERR(AJ31/$AJ$11),"",AJ31/$AJ$11) -> 0.017824095 | AL31: =AD31+AH31 -> 511796 | AM31: =IF(ISERR(AL31/$AL$11),"",AL31/AL$11) -> 0.0019983349 | AN31: =AF31+AJ31 -> 511796 | AO31: =IF(ISERR(AN31/$AN$11),"",AN31/$AN$11) -> 0.0019983349 | AP31: =B31+Z31+AL31 -> 1926360 | AQ31: =IF(ISERR(AP31/$AP$11),"",AP31/$AP$11) -> 0.0023266226 | AR31: =D31+AB31+AN31 -> 1926360 | AS31: =IF(ISERR(AR31/$AR$11),"",AR31/$AR$11) -> 0.0023266226 | AT31: =[1]全社合計!$N$31 -> 1486264 | AU31: =IF(ISERR(AT31/$AT$11),"",AT31/$AT$11) -> 0.0015368132 | AV31: =AT31 -> 1486264 | AW31: =IF(ISERR(AV31/$AV$11),"",AV31/$AV$11) -> 0.0015368132 | AX31: =AP31-AT31 -> 440096 | AY31: =IF(ISERROR(AP31/AT31),"",AP31/AT31) -> 1.2961089 | AZ31: =AR31-AV31 -> 440096 | BA31: =IF(ISERROR(AR31/AV31),"",AR31/AV31) -> 1.2961089
A32: 支払手数料 | B32: =[1]本部!$L$32 -> 453880 | C32: =IF(ISERR(B32/$B$11),"",B32/$B$11) | D32: =B32 -> 453880 | E32: =IF(ISERR(D32/$D$11),"",D32/$D$11) | F32: =[1]本社営業!$L$32 -> 903148 | G32: =IF(ISERR(F32/$F$11),"",F32/$F$11) -> 0.0016889083 | H32: =F32 -> 903148 | I32: =IF(ISERR(H32/$H$11),"",H32/$H$11) -> 0.0016889083 | J32: =[1]東大阪!$L$32 -> 159200 | K32: =IF(ISERR(J32/$J$11),"",J32/$J$11) -> 0.017932249 | L32: =J32 -> 159200 | M32: =IF(ISERR(L32/$L$11),"",L32/$L$11) -> 0.017932249 | N32: =[1]南港工場!$L$32 -> 133550 | O32: =IF(ISERR(N32/$N$11),"",N32/$N$11) -> 0.0047320449 | P32: =N32 -> 133550 | Q32: =IF(ISERR(P32/$P$11),"",P32/$P$11) -> 0.0047320449 | R32: =[1]南港事務!$L$32 -> 150707 | S32: =IF(ISERR(R32/$R$11),"",R32/$R$11) | T32: =R32 -> 150707 | U32: =IF(ISERR(T32/$T$11),"",T32/$T$11) | V32: =N32+R32 -> 284257 | W32: =IF(ISERR(V32/$V$11),"",V32/$V$11) -> 0.01007201 | X32: =P32+T32 -> 284257 | Y32: =IF(ISERR(X32/$X$11),"",X32/$X$11) -> 0.01007201 | Z32: =F32+J32+N32+R32 -> 1346605 | AA32: =IF(ISERR(Z32/$Z$11),"",Z32/$Z$11) -> 0.0023548103 | AB32: =H32+L32+P32+T32 -> 1346605 | AC32: =IF(ISERR(AB32/$AB$11),"",AB32/$AB$11) -> 0.0023548103 | AD32: =[1]東京事務!$L$32 -> 70000 | AE32: =IF(ISERR(AD32/$AD$11),"",AD32/$AD$11) -> 0.00028420488 | AF32: =AD32 -> 70000 | AG32: =IF(ISERR(AF32/$AF$11),"",AF32/$AF$11) -> 0.00028420488 | AH32: =[1]東京工場!$L$32 -> 37150 | AI32: =IF(ISERR(AH32/$AH$11),"",AH32/$AH$11) -> 0.0037869386 | AJ32: =AH32 -> 37150 | AK32: =IF(ISERR(AJ32/$AJ$11),"",AJ32/$AJ$11) -> 0.0037869386 | AL32: =AD32+AH32 -> 107150 | AM32: =IF(ISERR(AL32/$AL$11),"",AL32/AL$11) -> 0.00041837291 | AN32: =AF32+AJ32 -> 107150 | AO32: =IF(ISERR(AN32/$AN$11),"",AN32/$AN$11) -> 0.00041837291 | AP32: =B32+Z32+AL32 -> 1907635 | AQ32: =IF(ISERR(AP32/$AP$11),"",AP32/$AP$11) -> 0.0023040069 | AR32: =D32+AB32+AN32 -> 1907635 | AS32: =IF(ISERR(AR32/$AR$11),"",AR32/$AR$11) -> 0.0023040069 | AT32: =[1]全社合計!$N$32 -> 2887731 | AU32: =IF(ISERR(AT32/$AT$11),"",AT32/$AT$11) -> 0.0029859453 | AV32: =AT32 -> 2887731 | AW32: =IF(ISERR(AV32/$AV$11),"",AV32/$AV$11) -> 0.0029859453 | AX32: =AP32-AT32 -> -980096 | AY32: =IF(ISERROR(AP32/AT32),"",AP32/AT32) -> 0.66059997 | AZ32: =AR32-AV32 -> -980096 | BA32: =IF(ISERROR(AR32/AV32),"",AR32/AV32) -> 0.66059997
A33: 租税公課 | B33: =[1]本部!$L$33 -> 197626 | C33: =IF(ISERR(B33/$B$11),"",B33/$B$11) | D33: =B33 -> 197626 | E33: =IF(ISERR(D33/$D$11),"",D33/$D$11) | F33: =[1]本社営業!$L$33 -> 55000 | G33: =IF(ISERR(F33/$F$11),"",F33/$F$11) -> 0.00010285131 | H33: =F33 -> 55000 | I33: =IF(ISERR(H33/$H$11),"",H33/$H$11) -> 0.00010285131 | J33: =[1]東大阪!$L$33 -> 440000 | K33: =IF(ISERR(J33/$J$11),"",J33/$J$11) -> 0.049561493 | L33: =J33 -> 440000 | M33: =IF(ISERR(L33/$L$11),"",L33/$L$11) -> 0.049561493 | N33: =[1]南港工場!$L$33 -> 525000 | O33: =IF(ISERR(N33/$N$11),"",N33/$N$11) -> 0.018602198 | P33: =N33 -> 525000 | Q33: =IF(ISERR(P33/$P$11),"",P33/$P$11) -> 0.018602198 | R33: =[1]南港事務!$L$33 -> 20000 | S33: =IF(ISERR(R33/$R$11),"",R33/$R$11) | T33: =R33 -> 20000 | U33: =IF(ISERR(T33/$T$11),"",T33/$T$11) | V33: =N33+R33 -> 545000 | W33: =IF(ISERR(V33/$V$11),"",V33/$V$11) -> 0.019310853 | X33: =P33+T33 -> 545000 | Y33: =IF(ISERR(X33/$X$11),"",X33/$X$11) -> 0.019310853 | Z33: =F33+J33+N33+R33 -> 1040000 | AA33: =IF(ISERR(Z33/$Z$11),"",Z33/$Z$11) -> 0.0018186496 | AB33: =H33+L33+P33+T33 -> 1040000 | AC33: =IF(ISERR(AB33/$AB$11),"",AB33/$AB$11) -> 0.0018186496 | AD33: =[1]東京事務!$L$33 -> 55000 | AE33: =IF(ISERR(AD33/$AD$11),"",AD33/$AD$11) -> 0.00022330383 | AF33: =AD33 -> 55000 | AG33: =IF(ISERR(AF33/$AF$11),"",AF33/$AF$11) -> 0.00022330383 | AH33: =[1]東京工場!$L$33 -> 325000 | AI33: =IF(ISERR(AH33/$AH$11),"",AH33/$AH$11) -> 0.033129342 | AJ33: =AH33 -> 325000 | AK33: =IF(ISERR(AJ33/$AJ$11),"",AJ33/$AJ$11) -> 0.033129342 | AL33: =AD33+AH33 -> 380000 | AM33: =IF(ISERR(AL33/$AL$11),"",AL33/AL$11) -> 0.0014837304 | AN33: =AF33+AJ33 -> 380000 | AO33: =IF(ISERR(AN33/$AN$11),"",AN33/$AN$11) -> 0.0014837304 | AP33: =B33+Z33+AL33 -> 1617626 | AQ33: =IF(ISERR(AP33/$AP$11),"",AP33/$AP$11) -> 0.0019537393 | AR33: =D33+AB33+AN33 -> 1617626 | AS33: =IF(ISERR(AR33/$AR$11),"",AR33/$AR$11) -> 0.0019537393 | AT33: =[1]全社合計!$N$33 -> 1613174 | AU33: =IF(ISERR(AT33/$AT$11),"",AT33/$AT$11) -> 0.0016680395 | AV33: =AT33 -> 1613174 | AW33: =IF(ISERR(AV33/$AV$11),"",AV33/$AV$11) -> 0.0016680395 | AX33: =AP33-AT33 -> 4452 | AY33: =IF(ISERROR(AP33/AT33),"",AP33/AT33) -> 1.0027598 | AZ33: =AR33-AV33 -> 4452 | BA33: =IF(ISERROR(AR33/AV33),"",AR33/AV33) -> 1.0027598
A34: 交際費 | B34: =[1]本部!$L$34 -> 0 | C34: =IF(ISERR(B34/$B$11),"",B34/$B$11) | D34: =B34 -> 0 | E34: =IF(ISERR(D34/$D$11),"",D34/$D$11) | F34: =[1]本社営業!$L$34 -> 277676 | G34: =IF(ISERR(F34/$F$11),"",F34/$F$11) -> 0.00051926075 | H34: =F34 -> 277676 | I34: =IF(ISERR(H34/$H$11),"",H34/$H$11) -> 0.00051926075 | J34: =[1]東大阪!$L$34 -> 0 | K34: =IF(ISERR(J34/$J$11),"",J34/$J$11) -> 0 | L34: =J34 -> 0 | M34: =IF(ISERR(L34/$L$11),"",L34/$L$11) -> 0 | N34: =[1]南港工場!$L$34 -> 0 | O34: =IF(ISERR(N34/$N$11),"",N34/$N$11) -> 0 | P34: =N34 -> 0 | Q34: =IF(ISERR(P34/$P$11),"",P34/$P$11) -> 0 | R34: =[1]南港事務!$L$34 -> 0 | S34: =IF(ISERR(R34/$R$11),"",R34/$R$11) | T34: =R34 -> 0 | U34: =IF(ISERR(T34/$T$11),"",T34/$T$11) | V34: =N34+R34 -> 0 | W34: =IF(ISERR(V34/$V$11),"",V34/$V$11) -> 0 | X34: =P34+T34 -> 0 | Y34: =IF(ISERR(X34/$X$11),"",X34/$X$11) -> 0 | Z34: =F34+J34+N34+R34 -> 277676 | AA34: =IF(ISERR(Z34/$Z$11),"",Z34/$Z$11) -> 0.00048557246 | AB34: =H34+L34+P34+T34 -> 277676 | AC34: =IF(ISERR(AB34/$AB$11),"",AB34/$AB$11) -> 0.00048557246 | AD34: =[1]東京事務!$L$34 -> 460664 | AE34: =IF(ISERR(AD34/$AD$11),"",AD34/$AD$11) -> 0.0018703279 | AF34: =AD34 -> 460664 | AG34: =IF(ISERR(AF34/$AF$11),"",AF34/$AF$11) -> 0.0018703279 | AH34: =[1]東京工場!$L$34 -> 0 | AI34: =IF(ISERR(AH34/$AH$11),"",AH34/$AH$11) -> 0 | AJ34: =AH34 -> 0 | AK34: =IF(ISERR(AJ34/$AJ$11),"",AJ34/$AJ$11) -> 0 | AL34: =AD34+AH34 -> 460664 | AM34: =IF(ISERR(AL34/$AL$11),"",AL34/AL$11) -> 0.0017986873 | AN34: =AF34+AJ34 -> 460664 | AO34: =IF(ISERR(AN34/$AN$11),"",AN34/$AN$11) -> 0.0017986873 | AP34: =B34+Z34+AL34 -> 738340 | AQ34: =IF(ISERR(AP34/$AP$11),"",AP34/$AP$11) -> 0.00089175365 | AR34: =D34+AB34+AN34 -> 738340 | AS34: =IF(ISERR(AR34/$AR$11),"",AR34/$AR$11) -> 0.00089175365 | AT34: =[1]全社合計!$N$34 -> 496966 | AU34: =IF(ISERR(AT34/$AT$11),"",AT34/$AT$11) -> 0.00051386826 | AV34: =AT34 -> 496966 | AW34: =IF(ISERR(AV34/$AV$11),"",AV34/$AV$11) -> 0.00051386826 | AX34: =AP34-AT34 -> 241374 | AY34: =IF(ISERROR(AP34/AT34),"",AP34/AT34) -> 1.4856952 | AZ34: =AR34-AV34 -> 241374 | BA34: =IF(ISERROR(AR34/AV34),"",AR34/AV34) -> 1.4856952
