Workbook

Sheet 商品マスタ
A1: 商品マスタ
A2: ※材料費(円/kg)と単重(kg/個)を入力すると材料原価・粗利が自動計算されます。グループを設定すると月別計画実績のグループが自動入力されます。商品名は変更・削除禁止（廃番の場合はJ列に「廃番」と記入）。
A3: 商品名 | B3: グループ | C3: 単位 | D3: 売値 (円) | E3: 材料費 (円/kg) | F3: 単重 (kg/個) | G3: 材料原価 (円) 自動 | H3: 粗利/枚 (円) 自動 | I3: 粗利率 (%) 自動 | J3: 廃番 フラグ | K3: 備考
A4: 57mm上 | B4: 缶バッジ | C4: 個 | D4: 4.8 | G4: =IF(AND(E4<>"",F4<>""),E4*F4,4.36) -> 4.36 | H4: =D4-G4 -> 0.44 | I4: =IFERROR(H4/D4,0) -> 0.091666667 | J4: 有効
A5: 56Φ上蓋 | B5: 缶バッジ | C5: 個 | D5: 3.72 | G5: =IF(AND(E5<>"",F5<>""),E5*F5,3.38) -> 3.38 | H5: =D5-G5 -> 0.34 | I5: =IFERROR(H5/D5,0) -> 0.091397849 | J5: 有効
A6: 38mm上 | B6: 缶バッジ | C6: 個 | D6: 4.77 | G6: =IF(AND(E6<>"",F6<>""),E6*F6,4.34) -> 4.34 | H6: =D6-G6 -> 0.43 | I6: =IFERROR(H6/D6,0) -> 0.090146751 | J6: 有効
A7: 32mm上 | B7: 缶バッジ | C7: 個 | D7: 3.34 | G7: =IF(AND(E7<>"",F7<>""),E7*F7,3.04) -> 3.04 | H7: =D7-G7 -> 0.3 | I7: =IFERROR(H7/D7,0) -> 0.089820359 | J7: 有効
A8: 44mm上 | B8: 缶バッジ | C8: 個 | D8: 3.11 | G8: =IF(AND(E8<>"",F8<>""),E8*F8,2.83) -> 2.83 | H8: =D8-G8 -> 0.28 | I8: =IFERROR(H8/D8,0) -> 0.090032154 | J8: 有効
A9: 長方形ﾊﾞｯｼﾞ上蓋 | B9: 缶バッジ | C9: 個 | D9: 5.51 | G9: =IF(AND(E9<>"",F9<>""),E9*F9,5.01) -> 5.01 | H9: =D9-G9 -> 0.5 | I9: =IFERROR(H9/D9,0) -> 0.090744102 | J9: 有効
A10: 76mm上 | B10: 缶バッジ | C10: 個 | D10: 6.8 | G10: =IF(AND(E10<>"",F10<>""),E10*F10,6.18) -> 6.18 | H10: =D10-G10 -> 0.62 | I10: =IFERROR(H10/D10,0) -> 0.091176471 | J10: 有効
A11: 44x70丸角長方形上 | B11: 缶バッジ | C11: 個 | D11: 5.69 | G11: =IF(AND(E11<>"",F11<>""),E11*F11,5.17) -> 5.17 | H11: =D11-G11 -> 0.52 | I11: =IFERROR(H11/D11,0) -> 0.091388401 | J11: 有効
A12: 長方形53ｘ78mm用 | B12: 缶バッジ | C12: 個 | D12: 7.84 | G12: =IF(AND(E12<>"",F12<>""),E12*F12,7.13) -> 7.13 | H12: =D12-G12 -> 0.71 | I12: =IFERROR(H12/D12,0) -> 0.090561224 | J12: 有効
A13: 57mmﾂﾒ下ﾋﾟﾝ付き | B13: 缶バッジ | C13: 個 | D13: 12.55 | G13: =IF(AND(E13<>"",F13<>""),E13*F13,11.41) -> 11.41 | H13: =D13-G13 -> 1.14 | I13: =IFERROR(H13/D13,0) -> 0.090836653 | J13: 有効
A14: 54Φ下蓋 | B14: 缶バッジ | C14: 個 | D14: 3.72 | G14: =IF(AND(E14<>"",F14<>""),E14*F14,3.38) -> 3.38 | H14: =D14-G14 -> 0.34 | I14: =IFERROR(H14/D14,0) -> 0.091397849 | J14: 有効
A15: 56Φ下蓋 | B15: 缶バッジ | C15: 個 | D15: 3.72 | G15: =IF(AND(E15<>"",F15<>""),E15*F15,3.38) -> 3.38 | H15: =D15-G15 -> 0.34 | I15: =IFERROR(H15/D15,0) -> 0.091397849 | J15: 有効
A16: 32mm穴下 | B16: 缶バッジ | C16: 個 | D16: 3.83 | G16: =IF(AND(E16<>"",F16<>""),E16*F16,3.48) -> 3.48 | H16: =D16-G16 -> 0.35 | I16: =IFERROR(H16/D16,0) -> 0.091383812 | J16: 有効
A17: 75Φ下蓋 | B17: 缶バッジ | C17: 個 | D17: 5.28 | G17: =IF(AND(E17<>"",F17<>""),E17*F17,4.8) -> 4.8 | H17: =D17-G17 -> 0.48 | I17: =IFERROR(H17/D17,0) -> 0.090909091 | J17: 有効
A18: 57mm穴下 | B18: 缶バッジ | C18: 個 | D18: 6.02 | G18: =IF(AND(E18<>"",F18<>""),E18*F18,5.47) -> 5.47 | H18: =D18-G18 -> 0.55 | I18: =IFERROR(H18/D18,0) -> 0.091362126 | J18: 有効
A19: 57mmﾂﾒ下 | B19: 缶バッジ | C19: 個 | D19: 6.02 | G19: =IF(AND(E19<>"",F19<>""),E19*F19,5.47) -> 5.47 | H19: =D19-G19 -> 0.55 | I19: =IFERROR(H19/D19,0) -> 0.091362126 | J19: 有効
A20: 32mmﾂﾒ下ﾋﾟﾝ付き | B20: 缶バッジ | C20: 個 | D20: 14.87 | G20: =IF(AND(E20<>"",F20<>""),E20*F20,13.52) -> 13.52 | H20: =D20-G20 -> 1.35 | I20: =IFERROR(H20/D20,0) -> 0.090786819 | J20: 有効
A21: 32mm穴下ﾋﾟﾝ付き | B21: 缶バッジ | C21: 個 | D21: 14.87 | G21: =IF(AND(E21<>"",F21<>""),E21*F21,13.52) -> 13.52 | H21: =D21-G21 -> 1.35 | I21: =IFERROR(H21/D21,0) -> 0.090786819 | J21: 有効
A22: 44mm穴下ﾋﾟﾝ付き | B22: 缶バッジ | C22: 個 | D22: 18.42 | G22: =IF(AND(E22<>"",F22<>""),E22*F22,16.75) -> 16.75 | H22: =D22-G22 -> 1.67 | I22: =IFERROR(H22/D22,0) -> 0.090662324 | J22: 有効
A23: 44mmﾂﾒ下ﾋﾟﾝ付き | B23: 缶バッジ | C23: 個 | D23: 18.42 | G23: =IF(AND(E23<>"",F23<>""),E23*F23,16.75) -> 16.75 | H23: =D23-G23 -> 1.67 | I23: =IFERROR(H23/D23,0) -> 0.090662324 | J23: 有効
A24: 38mmﾂﾒ下ﾋﾟﾝ付き | B24: 缶バッジ | C24: 個 | D24: 10.56 | G24: =IF(AND(E24<>"",F24<>""),E24*F24,9.6) -> 9.6 | H24: =D24-G24 -> 0.96 | I24: =IFERROR(H24/D24,0) -> 0.090909091 | J24: 有効
A25: 76mmﾂﾒ下 | B25: 缶バッジ | C25: 個 | D25: 9.6 | G25: =IF(AND(E25<>"",F25<>""),E25*F25,8.73) -> 8.73 | H25: =D25-G25 -> 0.87 | I25: =IFERROR(H25/D25,0) -> 0.090625 | J25: 有効
A26: 44mmﾂﾒ下 | B26: 缶バッジ | C26: 個 | D26: 5.24 | G26: =IF(AND(E26<>"",F26<>""),E26*F26,4.76) -> 4.76 | H26: =D26-G26 -> 0.48 | I26: =IFERROR(H26/D26,0) -> 0.091603053 | J26: 有効
A27: 44x70丸角長方形下 | B27: 缶バッジ | C27: 個 | D27: 6.92 | G27: =IF(AND(E27<>"",F27<>""),E27*F27,6.29) -> 6.29 | H27: =D27-G27 -> 0.63 | I27: =IFERROR(H27/D27,0) -> 0.091040462 | J27: 有効
A28: 38mm穴下 | B28: 缶バッジ | C28: 個 | D28: 7.44 | G28: =IF(AND(E28<>"",F28<>""),E28*F28,6.76) -> 6.76 | H28: =D28-G28 -> 0.68 | I28: =IFERROR(H28/D28,0) -> 0.091397849 | J28: 有効
A29: 32mmﾂﾒ下 | B29: 缶バッジ | C29: 個 | D29: 4.58 | G29: =IF(AND(E29<>"",F29<>""),E29*F29,4.16) -> 4.16 | H29: =D29-G29 -> 0.42 | I29: =IFERROR(H29/D29,0) -> 0.091703057 | J29: 有効
A30: 57mm穴下ﾋﾟﾝ付き | B30: 缶バッジ | C30: 個 | D30: 20.68 | G30: =IF(AND(E30<>"",F30<>""),E30*F30,18.8) -> 18.8 | H30: =D30-G30 -> 1.88 | I30: =IFERROR(H30/D30,0) -> 0.090909091 | J30: 有効
A31: 76mmﾂﾒ下ﾋﾟﾝ付き | B31: 缶バッジ | C31: 個 | D31: 28.75 | G31: =IF(AND(E31<>"",F31<>""),E31*F31,26.14) -> 26.14 | H31: =D31-G31 -> 2.61 | I31: =IFERROR(H31/D31,0) -> 0.090782609 | J31: 有効
A32: ハート穴下 | B32: 缶バッジ | C32: 個 | D32: 12.77 | G32: =IF(AND(E32<>"",F32<>""),E32*F32,11.61) -> 11.61 | H32: =D32-G32 -> 1.16 | I32: =IFERROR(H32/D32,0) -> 0.090837901 | J32: 有効
A33: 57㎜ﾂﾒ下ﾋﾟﾝ付き(ｸﾘｱ) | B33: 缶バッジ | C33: 個 | D33: 22.44 | G33: =IF(AND(E33<>"",F33<>""),E33*F33,20.4) -> 20.4 | H33: =D33-G33 -> 2.04 | I33: =IFERROR(H33/D33,0) -> 0.090909091 | J33: 有効
A34: 57mm バックパーツ | B34: 缶バッジ | C34: 個 | D34: 3.72 | G34: =IF(AND(E34<>"",F34<>""),E34*F34,3.38) -> 3.38 | H34: =D34-G34 -> 0.34 | I34: =IFERROR(H34/D34,0) -> 0.091397849 | J34: 有効
A35: 76mm バックパーツ | B35: 缶バッジ | C35: 個 | D35: 5.28 | G35: =IF(AND(E35<>"",F35<>""),E35*F35,4.8) -> 4.8 | H35: =D35-G35 -> 0.48 | I35: =IFERROR(H35/D35,0) -> 0.090909091 | J35: 有効
A36: 44mm バックパーツ | B36: 缶バッジ | C36: 個 | D36: 3.11 | G36: =IF(AND(E36<>"",F36<>""),E36*F36,2.83) -> 2.83 | H36: =D36-G36 -> 0.28 | I36: =IFERROR(H36/D36,0) -> 0.090032154 | J36: 有効
A37: 38㎜ バックパーツ | B37: 缶バッジ | C37: 個 | D37: 2.85 | G37: =IF(AND(E37<>"",F37<>""),E37*F37,2.59) -> 2.59 | H37: =D37-G37 -> 0.26 | I37: =IFERROR(H37/D37,0) -> 0.09122807 | J37: 有効
A38: 57mm シェル | B38: 缶バッジ | C38: 個 | D38: 3.72 | G38: =IF(AND(E38<>"",F38<>""),E38*F38,3.38) -> 3.38 | H38: =D38-G38 -> 0.34 | I38: =IFERROR(H38/D38,0) -> 0.091397849 | J38: 有効
A39: 57mm バックパーツ | B39: 缶バッジ | C39: 個 | D39: 3.72 | G39: =IF(AND(E39<>"",F39<>""),E39*F39,3.38) -> 3.38 | H39: =D39-G39 -> 0.34 | I39: =IFERROR(H39/D39,0) -> 0.091397849 | J39: 有効
A40: 76㎜ シェルパーツ | B40: 缶バッジ | C40: 個 | D40: 5.28 | G40: =IF(AND(E40<>"",F40<>""),E40*F40,4.8) -> 4.8 | H40: =D40-G40 -> 0.48 | I40: =IFERROR(H40/D40,0) -> 0.090909091 | J40: 有効
...

Sheet 月別計画実績
A1: 三幸プロダクツ株式会社 42期 月別計画実績（2026年6月〜2027年5月）
A2: 【入力方法】D列=商品名をドロップダウンから選択 → B列グループ・E/F列単価が自動入力 → 各月の計画数量・実績数量を入力 → 売上・粗利が自動計算されます。 実績は「-」入力で0円取引、空白は未入力扱い。
A3: 工場 | B3: グループ | C3: 取引先 | D3: 商品名 | E3: 売値 (円) | F3: 粗利/枚 (円) | G3: 年間計画 | J3: 年間実績 | M3: 達成率 売上 | N3: 達成率 粗利 | O3: 6月 | R3: 6月 | U3: 7月 | X3: 7月 | AA3: 8月 | AD3: 8月 | AG3: 9月 | AJ3: 9月 | AM3: 10月 | AP3: 10月 | AS3: 11月 | AV3: 11月 | AY3: 12月 | BB3: 12月 | BE3: 1月 | BH3: 1月 | BK3: 2月 | BN3: 2月 | BQ3: 3月 | BT3: 3月 | BW3: 4月 | BZ3: 4月 | CC3: 5月 | CF3: 5月
G4: 計画 数量 | H4: 計画 売上 | I4: 計画 粗利 | J4: 実績 数量 | K4: 実績 売上 | L4: 実績 粗利 | O4: 計画 数量 | P4: 計画 売上 | Q4: 計画 粗利 | R4: 実績 数量 | S4: 実績 売上 | T4: 実績 粗利 | U4: 計画 数量 | V4: 計画 売上 | W4: 計画 粗利 | X4: 実績 数量 | Y4: 実績 売上 | Z4: 実績 粗利 | AA4: 計画 数量 | AB4: 計画 売上 | AC4: 計画 粗利 | AD4: 実績 数量 | AE4: 実績 売上 | AF4: 実績 粗利 | AG4: 計画 数量 | AH4: 計画 売上 | AI4: 計画 粗利 | AJ4: 実績 数量 | AK4: 実績 売上 | AL4: 実績 粗利 | AM4: 計画 数量 | AN4: 計画 売上 | AO4: 計画 粗利 | AP4: 実績 数量 | AQ4: 実績 売上 | AR4: 実績 粗利 | AS4: 計画 数量 | AT4: 計画 売上 | AU4: 計画 粗利 | AV4: 実績 数量 | AW4: 実績 売上 | AX4: 実績 粗利 | AY4: 計画 数量 | AZ4: 計画 売上 | BA4: 計画 粗利 | BB4: 実績 数量 | BC4: 実績 売上 | BD4: 実績 粗利 | BE4: 計画 数量 | BF4: 計画 売上 | BG4: 計画 粗利 | BH4: 実績 数量 | BI4: 実績 売上 | BJ4: 実績 粗利 | BK4: 計画 数量 | BL4: 計画 売上 | BM4: 計画 粗利 | BN4: 実績 数量 | BO4: 実績 売上 | BP4: 実績 粗利 | BQ4: 計画 数量 | BR4: 計画 売上 | BS4: 計画 粗利 | BT4: 実績 数量 | BU4: 実績 売上 | BV4: 実績 粗利 | BW4: 計画 数量 | BX4: 計画 売上 | BY4: 計画 粗利 | BZ4: 実績 数量 | CA4: 実績 売上 | CB4: 実績 粗利 | CC4: 計画 数量 | CD4: 計画 売上 | CE4: 計画 粗利 | CF4: 実績 数量 | CG4: 実績 売上 | CH4: 実績 粗利
A5: 東大阪 | B5: =IF(D5="","",IFERROR(VLOOKUP(D5,商品マスタ!$A:$K,2,FALSE),"昭和")) -> 昭和 | C5: 昭和プロダクツ | D5: 金具・ネジ類 | E5: =IF(D5="","",IFERROR(VLOOKUP(D5,商品マスタ!$A:$K,4,FALSE),8.14)) -> 8.14 | F5: =IF(D5="","",IFERROR(VLOOKUP(D5,商品マスタ!$A:$K,8,FALSE),0)) -> 0 | G5: =SUM(O5,U5,AA5,AG5,AM5,AS5,AY5,BE5,BK5,BQ5,BW5,CC5) -> 10 | H5: =SUM(P5,V5,AB5,AH5,AN5,AT5,AZ5,BF5,BL5,BR5,BX5,CD5) -> 81.4 | I5: =SUM(Q5,W5,AC5,AI5,AO5,AU5,BA5,BG5,BM5,BS5,BY5,CE5) -> 0 | J5: =SUM(R5,X5,AD5,AJ5,AP5,AV5,BB5,BH5,BN5,BT5,BZ5,CF5) -> 0 | K5: =SUM(S5,Y5,AE5,AK5,AQ5,AW5,BC5,BI5,BO5,BU5,CA5,CG5) -> 0 | L5: =SUM(T5,Z5,AF5,AL5,AR5,AX5,BD5,BJ5,BP5,BV5,CB5,CH5) -> 0 | M5: =IFERROR(K5/CI5,"") | N5: =IFERROR(L5/CJ5,"") | O5: 10 | P5: =IF(O5="","",O5*$E5) -> 81.4 | Q5: =IF(O5="","",O5*$F5) -> 0 | S5: =IF(R5="","",R5*$E5) | T5: =IF(R5="","",R5*$F5) | V5: =IF(U5="","",U5*$E5) | W5: =IF(U5="","",U5*$F5) | Y5: =IF(X5="","",X5*$E5) | Z5: =IF(X5="","",X5*$F5) | AB5: =IF(AA5="","",AA5*$E5) | AC5: =IF(AA5="","",AA5*$F5) | AE5: =IF(AD5="","",AD5*$E5) | AF5: =IF(AD5="","",AD5*$F5) | AH5: =IF(AG5="","",AG5*$E5) | AI5: =IF(AG5="","",AG5*$F5) | AK5: =IF(AJ5="","",AJ5*$E5) | AL5: =IF(AJ5="","",AJ5*$F5) | AN5: =IF(AM5="","",AM5*$E5) | AO5: =IF(AM5="","",AM5*$F5) | AQ5: =IF(AP5="","",AP5*$E5) | AR5: =IF(AP5="","",AP5*$F5) | AT5: =IF(AS5="","",AS5*$E5) | AU5: =IF(AS5="","",AS5*$F5) | AW5: =IF(AV5="","",AV5*$E5) | AX5: =IF(AV5="","",AV5*$F5) | AZ5: =IF(AY5="","",AY5*$E5) | BA5: =IF(AY5="","",AY5*$F5) | BC5: =IF(BB5="","",BB5*$E5) | BD5: =IF(BB5="","",BB5*$F5) | BF5: =IF(BE5="","",BE5*$E5) | BG5: =IF(BE5="","",BE5*$F5) | BI5: =IF(BH5="","",BH5*$E5) | BJ5: =IF(BH5="","",BH5*$F5) | BL5: =IF(BK5="","",BK5*$E5) | BM5: =IF(BK5="","",BK5*$F5) | BO5: =IF(BN5="","",BN5*$E5) | BP5: =IF(BN5="","",BN5*$F5) | BR5: =IF(BQ5="","",BQ5*$E5) | BS5: =IF(BQ5="","",BQ5*$F5) | BU5: =IF(BT5="","",BT5*$E5) | BV5: =IF(BT5="","",BT5*$F5) | BX5: =IF(BW5="","",BW5*$E5) | BY5: =IF(BW5="","",BW5*$F5) | CA5: =IF(BZ5="","",BZ5*$E5) | CB5: =IF(BZ5="","",BZ5*$F5) | CD5: =IF(CC5="","",CC5*$E5) | CE5: =IF(CC5="","",CC5*$F5) | CG5: =IF(CF5="","",CF5*$E5) | CH5: =IF(CF5="","",CF5*$F5) | CI5: =IF(R5>0,P5,0) + IF(X5>0,V5,0) + IF(AD5>0,AB5,0) + IF(AJ5>0,AH5,0) + IF(AP5>0,AN5,0) + IF(AV5>0,AT5,0) + IF(BB5>0,AZ5,0) + IF(BH5>0,BF5,0) + IF(BN5>0,BL5,0) + IF(BT5>0,BR5,0) + IF(BZ5>0,BX5,0) + IF(CF5>0,CD5,0) -> 0 | CJ5: =IF(R5>0,Q5,0) + IF(X5>0,W5,0) + IF(AD5>0,AC5,0) + IF(AJ5>0,AI5,0) + IF(AP5>0,AO5,0) + IF(AV5>0,AU5,0) + IF(BB5>0,BA5,0) + IF(BH5>0,BG5,0) + IF(BN5>0,BM5,0) + IF(BT5>0,BS5,0) + IF(BZ5>0,BY5,0) + IF(CF5>0,CE5,0) -> 0
A6: 東大阪 | B6: =IF(D6="","",IFERROR(VLOOKUP(D6,商品マスタ!$A:$K,2,FALSE),"昭和")) -> 昭和 | C6: 昭和丸筒 | D6: 金具・ネジ類 | E6: =IF(D6="","",IFERROR(VLOOKUP(D6,商品マスタ!$A:$K,4,FALSE),8.14)) -> 8.14 | F6: =IF(D6="","",IFERROR(VLOOKUP(D6,商品マスタ!$A:$K,8,FALSE),0)) -> 0 | G6: =SUM(O6,U6,AA6,AG6,AM6,AS6,AY6,BE6,BK6,BQ6,BW6,CC6) -> 0 | H6: =SUM(P6,V6,AB6,AH6,AN6,AT6,AZ6,BF6,BL6,BR6,BX6,CD6) -> 0 | I6: =SUM(Q6,W6,AC6,AI6,AO6,AU6,BA6,BG6,BM6,BS6,BY6,CE6) -> 0 | J6: =SUM(R6,X6,AD6,AJ6,AP6,AV6,BB6,BH6,BN6,BT6,BZ6,CF6) -> 0 | K6: =SUM(S6,Y6,AE6,AK6,AQ6,AW6,BC6,BI6,BO6,BU6,CA6,CG6) -> 0 | L6: =SUM(T6,Z6,AF6,AL6,AR6,AX6,BD6,BJ6,BP6,BV6,CB6,CH6) -> 0 | M6: =IFERROR(K6/CI6,"") | N6: =IFERROR(L6/CJ6,"") | P6: =IF(O6="","",O6*$E6) | Q6: =IF(O6="","",O6*$F6) | S6: =IF(R6="","",R6*$E6) | T6: =IF(R6="","",R6*$F6) | V6: =IF(U6="","",U6*$E6) | W6: =IF(U6="","",U6*$F6) | Y6: =IF(X6="","",X6*$E6) | Z6: =IF(X6="","",X6*$F6) | AB6: =IF(AA6="","",AA6*$E6) | AC6: =IF(AA6="","",AA6*$F6) | AE6: =IF(AD6="","",AD6*$E6) | AF6: =IF(AD6="","",AD6*$F6) | AH6: =IF(AG6="","",AG6*$E6) | AI6: =IF(AG6="","",AG6*$F6) | AK6: =IF(AJ6="","",AJ6*$E6) | AL6: =IF(AJ6="","",AJ6*$F6) | AN6: =IF(AM6="","",AM6*$E6) | AO6: =IF(AM6="","",AM6*$F6) | AQ6: =IF(AP6="","",AP6*$E6) | AR6: =IF(AP6="","",AP6*$F6) | AT6: =IF(AS6="","",AS6*$E6) | AU6: =IF(AS6="","",AS6*$F6) | AW6: =IF(AV6="","",AV6*$E6) | AX6: =IF(AV6="","",AV6*$F6) | AZ6: =IF(AY6="","",AY6*$E6) | BA6: =IF(AY6="","",AY6*$F6) | BC6: =IF(BB6="","",BB6*$E6) | BD6: =IF(BB6="","",BB6*$F6) | BF6: =IF(BE6="","",BE6*$E6) | BG6: =IF(BE6="","",BE6*$F6) | BI6: =IF(BH6="","",BH6*$E6) | BJ6: =IF(BH6="","",BH6*$F6) | BL6: =IF(BK6="","",BK6*$E6) | BM6: =IF(BK6="","",BK6*$F6) | BO6: =IF(BN6="","",BN6*$E6) | BP6: =IF(BN6="","",BN6*$F6) | BR6: =IF(BQ6="","",BQ6*$E6) | BS6: =IF(BQ6="","",BQ6*$F6) | BU6: =IF(BT6="","",BT6*$E6) | BV6: =IF(BT6="","",BT6*$F6) | BX6: =IF(BW6="","",BW6*$E6) | BY6: =IF(BW6="","",BW6*$F6) | CA6: =IF(BZ6="","",BZ6*$E6) | CB6: =IF(BZ6="","",BZ6*$F6) | CD6: =IF(CC6="","",CC6*$E6) | CE6: =IF(CC6="","",CC6*$F6) | CG6: =IF(CF6="","",CF6*$E6) | CH6: =IF(CF6="","",CF6*$F6) | CI6: =IF(R6>0,P6,0) + IF(X6>0,V6,0) + IF(AD6>0,AB6,0) + IF(AJ6>0,AH6,0) + IF(AP6>0,AN6,0) + IF(AV6>0,AT6,0) + IF(BB6>0,AZ6,0) + IF(BH6>0,BF6,0) + IF(BN6>0,BL6,0) + IF(BT6>0,BR6,0) + IF(BZ6>0,BX6,0) + IF(CF6>0,CD6,0) -> 0 | CJ6: =IF(R6>0,Q6,0) + IF(X6>0,W6,0) + IF(AD6>0,AC6,0) + IF(AJ6>0,AI6,0) + IF(AP6>0,AO6,0) + IF(AV6>0,AU6,0) + IF(BB6>0,BA6,0) + IF(BH6>0,BG6,0) + IF(BN6>0,BM6,0) + IF(BT6>0,BS6,0) + IF(BZ6>0,BY6,0) + IF(CF6>0,CE6,0) -> 0
A7: 東大阪 | B7: =IF(D7="","",IFERROR(VLOOKUP(D7,商品マスタ!$A:$K,2,FALSE),"昭和")) -> 昭和 | C7: 昭和化成工業 | D7: その他 | E7: =IF(D7="","",IFERROR(VLOOKUP(D7,商品マスタ!$A:$K,4,FALSE),0)) -> 0 | F7: =IF(D7="","",IFERROR(VLOOKUP(D7,商品マスタ!$A:$K,8,FALSE),0)) -> 0 | G7: =SUM(O7,U7,AA7,AG7,AM7,AS7,AY7,BE7,BK7,BQ7,BW7,CC7) -> 0 | H7: =SUM(P7,V7,AB7,AH7,AN7,AT7,AZ7,BF7,BL7,BR7,BX7,CD7) -> 0 | I7: =SUM(Q7,W7,AC7,AI7,AO7,AU7,BA7,BG7,BM7,BS7,BY7,CE7) -> 0 | J7: =SUM(R7,X7,AD7,AJ7,AP7,AV7,BB7,BH7,BN7,BT7,BZ7,CF7) -> 0 | K7: =SUM(S7,Y7,AE7,AK7,AQ7,AW7,BC7,BI7,BO7,BU7,CA7,CG7) -> 0 | L7: =SUM(T7,Z7,AF7,AL7,AR7,AX7,BD7,BJ7,BP7,BV7,CB7,CH7) -> 0 | M7: =IFERROR(K7/CI7,"") | N7: =IFERROR(L7/CJ7,"") | P7: =IF(O7="","",O7*$E7) | Q7: =IF(O7="","",O7*$F7) | S7: =IF(R7="","",R7*$E7) | T7: =IF(R7="","",R7*$F7) | V7: =IF(U7="","",U7*$E7) | W7: =IF(U7="","",U7*$F7) | Y7: =IF(X7="","",X7*$E7) | Z7: =IF(X7="","",X7*$F7) | AB7: =IF(AA7="","",AA7*$E7) | AC7: =IF(AA7="","",AA7*$F7) | AE7: =IF(AD7="","",AD7*$E7) | AF7: =IF(AD7="","",AD7*$F7) | AH7: =IF(AG7="","",AG7*$E7) | AI7: =IF(AG7="","",AG7*$F7) | AK7: =IF(AJ7="","",AJ7*$E7) | AL7: =IF(AJ7="","",AJ7*$F7) | AN7: =IF(AM7="","",AM7*$E7) | AO7: =IF(AM7="","",AM7*$F7) | AQ7: =IF(AP7="","",AP7*$E7) | AR7: =IF(AP7="","",AP7*$F7) | AT7: =IF(AS7="","",AS7*$E7) | AU7: =IF(AS7="","",AS7*$F7) | AW7: =IF(AV7="","",AV7*$E7) | AX7: =IF(AV7="","",AV7*$F7) | AZ7: =IF(AY7="","",AY7*$E7) | BA7: =IF(AY7="","",AY7*$F7) | BC7: =IF(BB7="","",BB7*$E7) | BD7: =IF(BB7="","",BB7*$F7) | BF7: =IF(BE7="","",BE7*$E7) | BG7: =IF(BE7="","",BE7*$F7) | BI7: =IF(BH7="","",BH7*$E7) | BJ7: =IF(BH7="","",BH7*$F7) | BL7: =IF(BK7="","",BK7*$E7) | BM7: =IF(BK7="","",BK7*$F7) | BO7: =IF(BN7="","",BN7*$E7) | BP7: =IF(BN7="","",BN7*$F7) | BR7: =IF(BQ7="","",BQ7*$E7) | BS7: =IF(BQ7="","",BQ7*$F7) | BU7: =IF(BT7="","",BT7*$E7) | BV7: =IF(BT7="","",BT7*$F7) | BX7: =IF(BW7="","",BW7*$E7) | BY7: =IF(BW7="","",BW7*$F7) | CA7: =IF(BZ7="","",BZ7*$E7) | CB7: =IF(BZ7="","",BZ7*$F7) | CD7: =IF(CC7="","",CC7*$E7) | CE7: =IF(CC7="","",CC7*$F7) | CG7: =IF(CF7="","",CF7*$E7) | CH7: =IF(CF7="","",CF7*$F7) | CI7: =IF(R7>0,P7,0) + IF(X7>0,V7,0) + IF(AD7>0,AB7,0) + IF(AJ7>0,AH7,0) + IF(AP7>0,AN7,0) + IF(AV7>0,AT7,0) + IF(BB7>0,AZ7,0) + IF(BH7>0,BF7,0) + IF(BN7>0,BL7,0) + IF(BT7>0,BR7,0) + IF(BZ7>0,BX7,0) + IF(CF7>0,CD7,0) -> 0 | CJ7: =IF(R7>0,Q7,0) + IF(X7>0,W7,0) + IF(AD7>0,AC7,0) + IF(AJ7>0,AI7,0) + IF(AP7>0,AO7,0) + IF(AV7>0,AU7,0) + IF(BB7>0,BA7,0) + IF(BH7>0,BG7,0) + IF(BN7>0,BM7,0) + IF(BT7>0,BS7,0) + IF(BZ7>0,BY7,0) + IF(CF7>0,CE7,0) -> 0
A8: 東大阪 | B8: =IF(D8="","",IFERROR(VLOOKUP(D8,商品マスタ!$A:$K,2,FALSE),"昭和以外")) -> 昭和以外 | C8: イワサキ | D8: その他 | E8: =IF(D8="","",IFERROR(VLOOKUP(D8,商品マスタ!$A:$K,4,FALSE),0)) -> 0 | F8: =IF(D8="","",IFERROR(VLOOKUP(D8,商品マスタ!$A:$K,8,FALSE),0)) -> 0 | G8: =SUM(O8,U8,AA8,AG8,AM8,AS8,AY8,BE8,BK8,BQ8,BW8,CC8) -> 0 | H8: =SUM(P8,V8,AB8,AH8,AN8,AT8,AZ8,BF8,BL8,BR8,BX8,CD8) -> 0 | I8: =SUM(Q8,W8,AC8,AI8,AO8,AU8,BA8,BG8,BM8,BS8,BY8,CE8) -> 0 | J8: =SUM(R8,X8,AD8,AJ8,AP8,AV8,BB8,BH8,BN8,BT8,BZ8,CF8) -> 0 | K8: =SUM(S8,Y8,AE8,AK8,AQ8,AW8,BC8,BI8,BO8,BU8,CA8,CG8) -> 0 | L8: =SUM(T8,Z8,AF8,AL8,AR8,AX8,BD8,BJ8,BP8,BV8,CB8,CH8) -> 0 | M8: =IFERROR(K8/CI8,"") | N8: =IFERROR(L8/CJ8,"") | P8: =IF(O8="","",O8*$E8) | Q8: =IF(O8="","",O8*$F8) | S8: =IF(R8="","",R8*$E8) | T8: =IF(R8="","",R8*$F8) | V8: =IF(U8="","",U8*$E8) | W8: =IF(U8="","",U8*$F8) | Y8: =IF(X8="","",X8*$E8) | Z8: =IF(X8="","",X8*$F8) | AB8: =IF(AA8="","",AA8*$E8) | AC8: =IF(AA8="","",AA8*$F8) | AE8: =IF(AD8="","",AD8*$E8) | AF8: =IF(AD8="","",AD8*$F8) | AH8: =IF(AG8="","",AG8*$E8) | AI8: =IF(AG8="","",AG8*$F8) | AK8: =IF(AJ8="","",AJ8*$E8) | AL8: =IF(AJ8="","",AJ8*$F8) | AN8: =IF(AM8="","",AM8*$E8) | AO8: =IF(AM8="","",AM8*$F8) | AQ8: =IF(AP8="","",AP8*$E8) | AR8: =IF(AP8="","",AP8*$F8) | AT8: =IF(AS8="","",AS8*$E8) | AU8: =IF(AS8="","",AS8*$F8) | AW8: =IF(AV8="","",AV8*$E8) | AX8: =IF(AV8="","",AV8*$F8) | AZ8: =IF(AY8="","",AY8*$E8) | BA8: =IF(AY8="","",AY8*$F8) | BC8: =IF(BB8="","",BB8*$E8) | BD8: =IF(BB8="","",BB8*$F8) | BF8: =IF(BE8="","",BE8*$E8) | BG8: =IF(BE8="","",BE8*$F8) | BI8: =IF(BH8="","",BH8*$E8) | BJ8: =IF(BH8="","",BH8*$F8) | BL8: =IF(BK8="","",BK8*$E8) | BM8: =IF(BK8="","",BK8*$F8) | BO8: =IF(BN8="","",BN8*$E8) | BP8: =IF(BN8="","",BN8*$F8) | BR8: =IF(BQ8="","",BQ8*$E8) | BS8: =IF(BQ8="","",BQ8*$F8) | BU8: =IF(BT8="","",BT8*$E8) | BV8: =IF(BT8="","",BT8*$F8) | BX8: =IF(BW8="","",BW8*$E8) | BY8: =IF(BW8="","",BW8*$F8) | CA8: =IF(BZ8="","",BZ8*$E8) | CB8: =IF(BZ8="","",BZ8*$F8) | CD8: =IF(CC8="","",CC8*$E8) | CE8: =IF(CC8="","",CC8*$F8) | CG8: =IF(CF8="","",CF8*$E8) | CH8: =IF(CF8="","",CF8*$F8) | CI8: =IF(R8>0,P8,0) + IF(X8>0,V8,0) + IF(AD8>0,AB8,0) + IF(AJ8>0,AH8,0) + IF(AP8>0,AN8,0) + IF(AV8>0,AT8,0) + IF(BB8>0,AZ8,0) + IF(BH8>0,BF8,0) + IF(BN8>0,BL8,0) + IF(BT8>0,BR8,0) + IF(BZ8>0,BX8,0) + IF(CF8>0,CD8,0) -> 0 | CJ8: =IF(R8>0,Q8,0) + IF(X8>0,W8,0) + IF(AD8>0,AC8,0) + IF(AJ8>0,AI8,0) + IF(AP8>0,AO8,0) + IF(AV8>0,AU8,0) + IF(BB8>0,BA8,0) + IF(BH8>0,BG8,0) + IF(BN8>0,BM8,0) + IF(BT8>0,BS8,0) + IF(BZ8>0,BY8,0) + IF(CF8>0,CE8,0) -> 0
A9: 東大阪 | B9: =IF(D9="","",IFERROR(VLOOKUP(D9,商品マスタ!$A:$K,2,FALSE),"昭和以外")) -> 昭和以外 | C9: 三協丸筒 | D9: 金具・ネジ類 | E9: =IF(D9="","",IFERROR(VLOOKUP(D9,商品マスタ!$A:$K,4,FALSE),8.14)) -> 8.14 | F9: =IF(D9="","",IFERROR(VLOOKUP(D9,商品マスタ!$A:$K,8,FALSE),0)) -> 0 | G9: =SUM(O9,U9,AA9,AG9,AM9,AS9,AY9,BE9,BK9,BQ9,BW9,CC9) -> 0 | H9: =SUM(P9,V9,AB9,AH9,AN9,AT9,AZ9,BF9,BL9,BR9,BX9,CD9) -> 0 | I9: =SUM(Q9,W9,AC9,AI9,AO9,AU9,BA9,BG9,BM9,BS9,BY9,CE9) -> 0 | J9: =SUM(R9,X9,AD9,AJ9,AP9,AV9,BB9,BH9,BN9,BT9,BZ9,CF9) -> 0 | K9: =SUM(S9,Y9,AE9,AK9,AQ9,AW9,BC9,BI9,BO9,BU9,CA9,CG9) -> 0 | L9: =SUM(T9,Z9,AF9,AL9,AR9,AX9,BD9,BJ9,BP9,BV9,CB9,CH9) -> 0 | M9: =IFERROR(K9/CI9,"") | N9: =IFERROR(L9/CJ9,"") | P9: =IF(O9="","",O9*$E9) | Q9: =IF(O9="","",O9*$F9) | S9: =IF(R9="","",R9*$E9) | T9: =IF(R9="","",R9*$F9) | V9: =IF(U9="","",U9*$E9) | W9: =IF(U9="","",U9*$F9) | Y9: =IF(X9="","",X9*$E9) | Z9: =IF(X9="","",X9*$F9) | AB9: =IF(AA9="","",AA9*$E9) | AC9: =IF(AA9="","",AA9*$F9) | AE9: =IF(AD9="","",AD9*$E9) | AF9: =IF(AD9="","",AD9*$F9) | AH9: =IF(AG9="","",AG9*$E9) | AI9: =IF(AG9="","",AG9*$F9) | AK9: =IF(AJ9="","",AJ9*$E9) | AL9: =IF(AJ9="","",AJ9*$F9) | AN9: =IF(AM9="","",AM9*$E9) | AO9: =IF(AM9="","",AM9*$F9) | AQ9: =IF(AP9="","",AP9*$E9) | AR9: =IF(AP9="","",AP9*$F9) | AT9: =IF(AS9="","",AS9*$E9) | AU9: =IF(AS9="","",AS9*$F9) | AW9: =IF(AV9="","",AV9*$E9) | AX9: =IF(AV9="","",AV9*$F9) | AZ9: =IF(AY9="","",AY9*$E9) | BA9: =IF(AY9="","",AY9*$F9) | BC9: =IF(BB9="","",BB9*$E9) | BD9: =IF(BB9="","",BB9*$F9) | BF9: =IF(BE9="","",BE9*$E9) | BG9: =IF(BE9="","",BE9*$F9) | BI9: =IF(BH9="","",BH9*$E9) | BJ9: =IF(BH9="","",BH9*$F9) | BL9: =IF(BK9="","",BK9*$E9) | BM9: =IF(BK9="","",BK9*$F9) | BO9: =IF(BN9="","",BN9*$E9) | BP9: =IF(BN9="","",BN9*$F9) | BR9: =IF(BQ9="","",BQ9*$E9) | BS9: =IF(BQ9="","",BQ9*$F9) | BU9: =IF(BT9="","",BT9*$E9) | BV9: =IF(BT9="","",BT9*$F9) | BX9: =IF(BW9="","",BW9*$E9) | BY9: =IF(BW9="","",BW9*$F9) | CA9: =IF(BZ9="","",BZ9*$E9) | CB9: =IF(BZ9="","",BZ9*$F9) | CD9: =IF(CC9="","",CC9*$E9) | CE9: =IF(CC9="","",CC9*$F9) | CG9: =IF(CF9="","",CF9*$E9) | CH9: =IF(CF9="","",CF9*$F9) | CI9: =IF(R9>0,P9,0) + IF(X9>0,V9,0) + IF(AD9>0,AB9,0) + IF(AJ9>0,AH9,0) + IF(AP9>0,AN9,0) + IF(AV9>0,AT9,0) + IF(BB9>0,AZ9,0) + IF(BH9>0,BF9,0) + IF(BN9>0,BL9,0) + IF(BT9>0,BR9,0) + IF(BZ9>0,BX9,0) + IF(CF9>0,CD9,0) -> 0 | CJ9: =IF(R9>0,Q9,0) + IF(X9>0,W9,0) + IF(AD9>0,AC9,0) + IF(AJ9>0,AI9,0) + IF(AP9>0,AO9,0) + IF(AV9>0,AU9,0) + IF(BB9>0,BA9,0) + IF(BH9>0,BG9,0) + IF(BN9>0,BM9,0) + IF(BT9>0,BS9,0) + IF(BZ9>0,BY9,0) + IF(CF9>0,CE9,0) -> 0
A10: 東大阪 | B10: =IF(D10="","",IFERROR(VLOOKUP(D10,商品マスタ!$A:$K,2,FALSE),"昭和以外")) -> 昭和以外 | C10: 向陽エンジニアリング | D10: その他 | E10: =IF(D10="","",IFERROR(VLOOKUP(D10,商品マスタ!$A:$K,4,FALSE),0)) -> 0 | F10: =IF(D10="","",IFERROR(VLOOKUP(D10,商品マスタ!$A:$K,8,FALSE),0)) -> 0 | G10: =SUM(O10,U10,AA10,AG10,AM10,AS10,AY10,BE10,BK10,BQ10,BW10,CC10) -> 0 | H10: =SUM(P10,V10,AB10,AH10,AN10,AT10,AZ10,BF10,BL10,BR10,BX10,CD10) -> 0 | I10: =SUM(Q10,W10,AC10,AI10,AO10,AU10,BA10,BG10,BM10,BS10,BY10,CE10) -> 0 | J10: =SUM(R10,X10,AD10,AJ10,AP10,AV10,BB10,BH10,BN10,BT10,BZ10,CF10) -> 0 | K10: =SUM(S10,Y10,AE10,AK10,AQ10,AW10,BC10,BI10,BO10,BU10,CA10,CG10) -> 0 | L10: =SUM(T10,Z10,AF10,AL10,AR10,AX10,BD10,BJ10,BP10,BV10,CB10,CH10) -> 0 | M10: =IFERROR(K10/CI10,"") | N10: =IFERROR(L10/CJ10,"") | P10: =IF(O10="","",O10*$E10) | Q10: =IF(O10="","",O10*$F10) | S10: =IF(R10="","",R10*$E10) | T10: =IF(R10="","",R10*$F10) | V10: =IF(U10="","",U10*$E10) | W10: =IF(U10="","",U10*$F10) | Y10: =IF(X10="","",X10*$E10) | Z10: =IF(X10="","",X10*$F10) | AB10: =IF(AA10="","",AA10*$E10) | AC10: =IF(AA10="","",AA10*$F10) | AE10: =IF(AD10="","",AD10*$E10) | AF10: =IF(AD10="","",AD10*$F10) | AH10: =IF(AG10="","",AG10*$E10) | AI10: =IF(AG10="","",AG10*$F10) | AK10: =IF(AJ10="","",AJ10*$E10) | AL10: =IF(AJ10="","",AJ10*$F10) | AN10: =IF(AM10="","",AM10*$E10) | AO10: =IF(AM10="","",AM10*$F10) | AQ10: =IF(AP10="","",AP10*$E10) | AR10: =IF(AP10="","",AP10*$F10) | AT10: =IF(AS10="","",AS10*$E10) | AU10: =IF(AS10="","",AS10*$F10) | AW10: =IF(AV10="","",AV10*$E10) | AX10: =IF(AV10="","",AV10*$F10) | AZ10: =IF(AY10="","",AY10*$E10) | BA10: =IF(AY10="","",AY10*$F10) | BC10: =IF(BB10="","",BB10*$E10) | BD10: =IF(BB10="","",BB10*$F10) | BF10: =IF(BE10="","",BE10*$E10) | BG10: =IF(BE10="","",BE10*$F10) | BI10: =IF(BH10="","",BH10*$E10) | BJ10: =IF(BH10="","",BH10*$F10) | BL10: =IF(BK10="","",BK10*$E10) | BM10: =IF(BK10="","",BK10*$F10) | BO10: =IF(BN10="","",BN10*$E10) | BP10: =IF(BN10="","",BN10*$F10) | BR10: =IF(BQ10="","",BQ10*$E10) | BS10: =IF(BQ10="","",BQ10*$F10) | BU10: =IF(BT10="","",BT10*$E10) | BV10: =IF(BT10="","",BT10*$F10) | BX10: =IF(BW10="","",BW10*$E10) | BY10: =IF(BW10="","",BW10*$F10) | CA10: =IF(BZ10="","",BZ10*$E10) | CB10: =IF(BZ10="","",BZ10*$F10) | CD10: =IF(CC10="","",CC10*$E10) | CE10: =IF(CC10="","",CC10*$F10) | CG10: =IF(CF10="","",CF10*$E10) | CH10: =IF(CF10="","",CF10*$F10) | CI10: =IF(R10>0,P10,0) + IF(X10>0,V10,0) + IF(AD10>0,AB10,0) + IF(AJ10>0,AH10,0) + IF(AP10>0,AN10,0) + IF(AV10>0,AT10,0) + IF(BB10>0,AZ10,0) + IF(BH10>0,BF10,0) + IF(BN10>0,BL10,0) + IF(BT10>0,BR10,0) + IF(BZ10>0,BX10,0) + IF(CF10>0,CD10,0) -> 0 | CJ10: =IF(R10>0,Q10,0) + IF(X10>0,W10,0) + IF(AD10>0,AC10,0) + IF(AJ10>0,AI10,0) + IF(AP10>0,AO10,0) + IF(AV10>0,AU10,0) + IF(BB10>0,BA10,0) + IF(BH10>0,BG10,0) + IF(BN10>0,BM10,0) + IF(BT10>0,BS10,0) + IF(BZ10>0,BY10,0) + IF(CF10>0,CE10,0) -> 0
A11: 東大阪 | B11: =IF(D11="","",IFERROR(VLOOKUP(D11,商品マスタ!$A:$K,2,FALSE),"昭和以外")) -> 昭和以外 | C11: 晶立工作所 | D11: プランジャー・スプリング | E11: =IF(D11="","",IFERROR(VLOOKUP(D11,商品マスタ!$A:$K,4,FALSE),6.55)) -> 6.55 | F11: =IF(D11="","",IFERROR(VLOOKUP(D11,商品マスタ!$A:$K,8,FALSE),0.599999999999999)) -> 0.6 | G11: =SUM(O11,U11,AA11,AG11,AM11,AS11,AY11,BE11,BK11,BQ11,BW11,CC11) -> 0 | H11: =SUM(P11,V11,AB11,AH11,AN11,AT11,AZ11,BF11,BL11,BR11,BX11,CD11) -> 0 | I11: =SUM(Q11,W11,AC11,AI11,AO11,AU11,BA11,BG11,BM11,BS11,BY11,CE11) -> 0 | J11: =SUM(R11,X11,AD11,AJ11,AP11,AV11,BB11,BH11,BN11,BT11,BZ11,CF11) -> 0 | K11: =SUM(S11,Y11,AE11,AK11,AQ11,AW11,BC11,BI11,BO11,BU11,CA11,CG11) -> 0 | L11: =SUM(T11,Z11,AF11,AL11,AR11,AX11,BD11,BJ11,BP11,BV11,CB11,CH11) -> 0 | M11: =IFERROR(K11/CI11,"") | N11: =IFERROR(L11/CJ11,"") | P11: =IF(O11="","",O11*$E11) | Q11: =IF(O11="","",O11*$F11) | S11: =IF(R11="","",R11*$E11) | T11: =IF(R11="","",R11*$F11) | V11: =IF(U11="","",U11*$E11) | W11: =IF(U11="","",U11*$F11) | Y11: =IF(X11="","",X11*$E11) | Z11: =IF(X11="","",X11*$F11) | AB11: =IF(AA11="","",AA11*$E11) | AC11: =IF(AA11="","",AA11*$F11) | AE11: =IF(AD11="","",AD11*$E11) | AF11: =IF(AD11="","",AD11*$F11) | AH11: =IF(AG11="","",AG11*$E11) | AI11: =IF(AG11="","",AG11*$F11) | AK11: =IF(AJ11="","",AJ11*$E11) | AL11: =IF(AJ11="","",AJ11*$F11) | AN11: =IF(AM11="","",AM11*$E11) | AO11: =IF(AM11="","",AM11*$F11) | AQ11: =IF(AP11="","",AP11*$E11) | AR11: =IF(AP11="","",AP11*$F11) | AT11: =IF(AS11="","",AS11*$E11) | AU11: =IF(AS11="","",AS11*$F11) | AW11: =IF(AV11="","",AV11*$E11) | AX11: =IF(AV11="","",AV11*$F11) | AZ11: =IF(AY11="","",AY11*$E11) | BA11: =IF(AY11="","",AY11*$F11) | BC11: =IF(BB11="","",BB11*$E11) | BD11: =IF(BB11="","",BB11*$F11) | BF11: =IF(BE11="","",BE11*$E11) | BG11: =IF(BE11="","",BE11*$F11) | BI11: =IF(BH11="","",BH11*$E11) | BJ11: =IF(BH11="","",BH11*$F11) | BL11: =IF(BK11="","",BK11*$E11) | BM11: =IF(BK11="","",BK11*$F11) | BO11: =IF(BN11="","",BN11*$E11) | BP11: =IF(BN11="","",BN11*$F11) | BR11: =IF(BQ11="","",BQ11*$E11) | BS11: =IF(BQ11="","",BQ11*$F11) | BU11: =IF(BT11="","",BT11*$E11) | BV11: =IF(BT11="","",BT11*$F11) | BX11: =IF(BW11="","",BW11*$E11) | BY11: =IF(BW11="","",BW11*$F11) | CA11: =IF(BZ11="","",BZ11*$E11) | CB11: =IF(BZ11="","",BZ11*$F11) | CD11: =IF(CC11="","",CC11*$E11) | CE11: =IF(CC11="","",CC11*$F11) | CG11: =IF(CF11="","",CF11*$E11) | CH11: =IF(CF11="","",CF11*$F11) | CI11: =IF(R11>0,P11,0) + IF(X11>0,V11,0) + IF(AD11>0,AB11,0) + IF(AJ11>0,AH11,0) + IF(AP11>0,AN11,0) + IF(AV11>0,AT11,0) + IF(BB11>0,AZ11,0) + IF(BH11>0,BF11,0) + IF(BN11>0,BL11,0) + IF(BT11>0,BR11,0) + IF(BZ11>0,BX11,0) + IF(CF11>0,CD11,0) -> 0 | CJ11: =IF(R11>0,Q11,0) + IF(X11>0,W11,0) + IF(AD11>0,AC11,0) + IF(AJ11>0,AI11,0) + IF(AP11>0,AO11,0) + IF(AV11>0,AU11,0) + IF(BB11>0,BA11,0) + IF(BH11>0,BG11,0) + IF(BN11>0,BM11,0) + IF(BT11>0,BS11,0) + IF(BZ11>0,BY11,0) + IF(CF11>0,CE11,0) -> 0
A12: 東大阪 | B12: =IF(D12="","",IFERROR(VLOOKUP(D12,商品マスタ!$A:$K,2,FALSE),"昭和以外")) -> 昭和以外 | C12: 製作工房タケダ | D12: その他 | E12: =IF(D12="","",IFERROR(VLOOKUP(D12,商品マスタ!$A:$K,4,FALSE),0)) -> 0 | F12: =IF(D12="","",IFERROR(VLOOKUP(D12,商品マスタ!$A:$K,8,FALSE),0)) -> 0 | G12: =SUM(O12,U12,AA12,AG12,AM12,AS12,AY12,BE12,BK12,BQ12,BW12,CC12) -> 0 | H12: =SUM(P12,V12,AB12,AH12,AN12,AT12,AZ12,BF12,BL12,BR12,BX12,CD12) -> 0 | I12: =SUM(Q12,W12,AC12,AI12,AO12,AU12,BA12,BG12,BM12,BS12,BY12,CE12) -> 0 | J12: =SUM(R12,X12,AD12,AJ12,AP12,AV12,BB12,BH12,BN12,BT12,BZ12,CF12) -> 0 | K12: =SUM(S12,Y12,AE12,AK12,AQ12,AW12,BC12,BI12,BO12,BU12,CA12,CG12) -> 0 | L12: =SUM(T12,Z12,AF12,AL12,AR12,AX12,BD12,BJ12,BP12,BV12,CB12,CH12) -> 0 | M12: =IFERROR(K12/CI12,"") | N12: =IFERROR(L12/CJ12,"") | P12: =IF(O12="","",O12*$E12) | Q12: =IF(O12="","",O12*$F12) | S12: =IF(R12="","",R12*$E12) | T12: =IF(R12="","",R12*$F12) | V12: =IF(U12="","",U12*$E12) | W12: =IF(U12="","",U12*$F12) | Y12: =IF(X12="","",X12*$E12) | Z12: =IF(X12="","",X12*$F12) | AB12: =IF(AA12="","",AA12*$E12) | AC12: =IF(AA12="","",AA12*$F12) | AE12: =IF(AD12="","",AD12*$E12) | AF12: =IF(AD12="","",AD12*$F12) | AH12: =IF(AG12="","",AG12*$E12) | AI12: =IF(AG12="","",AG12*$F12) | AK12: =IF(AJ12="","",AJ12*$E12) | AL12: =IF(AJ12="","",AJ12*$F12) | AN12: =IF(AM12="","",AM12*$E12) | AO12: =IF(AM12="","",AM12*$F12) | AQ12: =IF(AP12="","",AP12*$E12) | AR12: =IF(AP12="","",AP12*$F12) | AT12: =IF(AS12="","",AS12*$E12) | AU12: =IF(AS12="","",AS12*$F12) | AW12: =IF(AV12="","",AV12*$E12) | AX12: =IF(AV12="","",AV12*$F12) | AZ12: =IF(AY12="","",AY12*$E12) | BA12: =IF(AY12="","",AY12*$F12) | BC12: =IF(BB12="","",BB12*$E12) | BD12: =IF(BB12="","",BB12*$F12) | BF12: =IF(BE12="","",BE12*$E12) | BG12: =IF(BE12="","",BE12*$F12) | BI12: =IF(BH12="","",BH12*$E12) | BJ12: =IF(BH12="","",BH12*$F12) | BL12: =IF(BK12="","",BK12*$E12) | BM12: =IF(BK12="","",BK12*$F12) | BO12: =IF(BN12="","",BN12*$E12) | BP12: =IF(BN12="","",BN12*$F12) | BR12: =IF(BQ12="","",BQ12*$E12) | BS12: =IF(BQ12="","",BQ12*$F12) | BU12: =IF(BT12="","",BT12*$E12) | BV12: =IF(BT12="","",BT12*$F12) | BX12: =IF(BW12="","",BW12*$E12) | BY12: =IF(BW12="","",BW12*$F12) | CA12: =IF(BZ12="","",BZ12*$E12) | CB12: =IF(BZ12="","",BZ12*$F12) | CD12: =IF(CC12="","",CC12*$E12) | CE12: =IF(CC12="","",CC12*$F12) | CG12: =IF(CF12="","",CF12*$E12) | CH12: =IF(CF12="","",CF12*$F12) | CI12: =IF(R12>0,P12,0) + IF(X12>0,V12,0) + IF(AD12>0,AB12,0) + IF(AJ12>0,AH12,0) + IF(AP12>0,AN12,0) + IF(AV12>0,AT12,0) + IF(BB12>0,AZ12,0) + IF(BH12>0,BF12,0) + IF(BN12>0,BL12,0) + IF(BT12>0,BR12,0) + IF(BZ12>0,BX12,0) + IF(CF12>0,CD12,0) -> 0 | CJ12: =IF(R12>0,Q12,0) + IF(X12>0,W12,0) + IF(AD12>0,AC12,0) + IF(AJ12>0,AI12,0) + IF(AP12>0,AO12,0) + IF(AV12>0,AU12,0) + IF(BB12>0,BA12,0) + IF(BH12>0,BG12,0) + IF(BN12>0,BM12,0) + IF(BT12>0,BS12,0) + IF(BZ12>0,BY12,0) + IF(CF12>0,CE12,0) -> 0
A13: 東大阪 | B13: =IF(D13="","",IFERROR(VLOOKUP(D13,商品マスタ!$A:$K,2,FALSE),"缶バッジ")) -> 缶バッジ | C13: ダイキ | D13: 下蓋・穴下・ツメ下 | E13: =IF(D13="","",IFERROR(VLOOKUP(D13,商品マスタ!$A:$K,4,FALSE),12.55)) -> 12.55 | F13: =IF(D13="","",IFERROR(VLOOKUP(D13,商品マスタ!$A:$K,8,FALSE),1.14)) -> 1.14 | G13: =SUM(O13,U13,AA13,AG13,AM13,AS13,AY13,BE13,BK13,BQ13,BW13,CC13) -> 0 | H13: =SUM(P13,V13,AB13,AH13,AN13,AT13,AZ13,BF13,BL13,BR13,BX13,CD13) -> 0 | I13: =SUM(Q13,W13,AC13,AI13,AO13,AU13,BA13,BG13,BM13,BS13,BY13,CE13) -> 0 | J13: =SUM(R13,X13,AD13,AJ13,AP13,AV13,BB13,BH13,BN13,BT13,BZ13,CF13) -> 0 | K13: =SUM(S13,Y13,AE13,AK13,AQ13,AW13,BC13,BI13,BO13,BU13,CA13,CG13) -> 0 | L13: =SUM(T13,Z13,AF13,AL13,AR13,AX13,BD13,BJ13,BP13,BV13,CB13,CH13) -> 0 | M13: =IFERROR(K13/CI13,"") | N13: =IFERROR(L13/CJ13,"") | P13: =IF(O13="","",O13*$E13) | Q13: =IF(O13="","",O13*$F13) | S13: =IF(R13="","",R13*$E13) | T13: =IF(R13="","",R13*$F13) | V13: =IF(U13="","",U13*$E13) | W13: =IF(U13="","",U13*$F13) | Y13: =IF(X13="","",X13*$E13) | Z13: =IF(X13="","",X13*$F13) | AB13: =IF(AA13="","",AA13*$E13) | AC13: =IF(AA13="","",AA13*$F13) | AE13: =IF(AD13="","",AD13*$E13) | AF13: =IF(AD13="","",AD13*$F13) | AH13: =IF(AG13="","",AG13*$E13) | AI13: =IF(AG13="","",AG13*$F13) | AK13: =IF(AJ13="","",AJ13*$E13) | AL13: =IF(AJ13="","",AJ13*$F13) | AN13: =IF(AM13="","",AM13*$E13) | AO13: =IF(AM13="","",AM13*$F13) | AQ13: =IF(AP13="","",AP13*$E13) | AR13: =IF(AP13="","",AP13*$F13) | AT13: =IF(AS13="","",AS13*$E13) | AU13: =IF(AS13="","",AS13*$F13) | AW13: =IF(AV13="","",AV13*$E13) | AX13: =IF(AV13="","",AV13*$F13) | AZ13: =IF(AY13="","",AY13*$E13) | BA13: =IF(AY13="","",AY13*$F13) | BC13: =IF(BB13="","",BB13*$E13) | BD13: =IF(BB13="","",BB13*$F13) | BF13: =IF(BE13="","",BE13*$E13) | BG13: =IF(BE13="","",BE13*$F13) | BI13: =IF(BH13="","",BH13*$E13) | BJ13: =IF(BH13="","",BH13*$F13) | BL13: =IF(BK13="","",BK13*$E13) | BM13: =IF(BK13="","",BK13*$F13) | BO13: =IF(BN13="","",BN13*$E13) | BP13: =IF(BN13="","",BN13*$F13) | BR13: =IF(BQ13="","",BQ13*$E13) | BS13: =IF(BQ13="","",BQ13*$F13) | BU13: =IF(BT13="","",BT13*$E13) | BV13: =IF(BT13="","",BT13*$F13) | BX13: =IF(BW13="","",BW13*$E13) | BY13: =IF(BW13="","",BW13*$F13) | CA13: =IF(BZ13="","",BZ13*$E13) | CB13: =IF(BZ13="","",BZ13*$F13) | CD13: =IF(CC13="","",CC13*$E13) | CE13: =IF(CC13="","",CC13*$F13) | CG13: =IF(CF13="","",CF13*$E13) | CH13: =IF(CF13="","",CF13*$F13) | CI13: =IF(R13>0,P13,0) + IF(X13>0,V13,0) + IF(AD13>0,AB13,0) + IF(AJ13>0,AH13,0) + IF(AP13>0,AN13,0) + IF(AV13>0,AT13,0) + IF(BB13>0,AZ13,0) + IF(BH13>0,BF13,0) + IF(BN13>0,BL13,0) + IF(BT13>0,BR13,0) + IF(BZ13>0,BX13,0) + IF(CF13>0,CD13,0) -> 0 | CJ13: =IF(R13>0,Q13,0) + IF(X13>0,W13,0) + IF(AD13>0,AC13,0) + IF(AJ13>0,AI13,0) + IF(AP13>0,AO13,0) + IF(AV13>0,AU13,0) + IF(BB13>0,BA13,0) + IF(BH13>0,BG13,0) + IF(BN13>0,BM13,0) + IF(BT13>0,BS13,0) + IF(BZ13>0,BY13,0) + IF(CF13>0,CE13,0) -> 0
A14: 東大阪 | B14: =IF(D14="","",IFERROR(VLOOKUP(D14,商品マスタ!$A:$K,2,FALSE),"缶バッジ")) -> 缶バッジ | C14: ノート | D14: 下蓋・穴下・ツメ下 | E14: =IF(D14="","",IFERROR(VLOOKUP(D14,商品マスタ!$A:$K,4,FALSE),12.55)) -> 12.55 | F14: =IF(D14="","",IFERROR(VLOOKUP(D14,商品マスタ!$A:$K,8,FALSE),1.14)) -> 1.14 | G14: =SUM(O14,U14,AA14,AG14,AM14,AS14,AY14,BE14,BK14,BQ14,BW14,CC14) -> 0 | H14: =SUM(P14,V14,AB14,AH14,AN14,AT14,AZ14,BF14,BL14,BR14,BX14,CD14) -> 0 | I14: =SUM(Q14,W14,AC14,AI14,AO14,AU14,BA14,BG14,BM14,BS14,BY14,CE14) -> 0 | J14: =SUM(R14,X14,AD14,AJ14,AP14,AV14,BB14,BH14,BN14,BT14,BZ14,CF14) -> 0 | K14: =SUM(S14,Y14,AE14,AK14,AQ14,AW14,BC14,BI14,BO14,BU14,CA14,CG14) -> 0 | L14: =SUM(T14,Z14,AF14,AL14,AR14,AX14,BD14,BJ14,BP14,BV14,CB14,CH14) -> 0 | M14: =IFERROR(K14/CI14,"") | N14: =IFERROR(L14/CJ14,"") | P14: =IF(O14="","",O14*$E14) | Q14: =IF(O14="","",O14*$F14) | S14: =IF(R14="","",R14*$E14) | T14: =IF(R14="","",R14*$F14) | V14: =IF(U14="","",U14*$E14) | W14: =IF(U14="","",U14*$F14) | Y14: =IF(X14="","",X14*$E14) | Z14: =IF(X14="","",X14*$F14) | AB14: =IF(AA14="","",AA14*$E14) | AC14: =IF(AA14="","",AA14*$F14) | AE14: =IF(AD14="","",AD14*$E14) | AF14: =IF(AD14="","",AD14*$F14) | AH14: =IF(AG14="","",AG14*$E14) | AI14: =IF(AG14="","",AG14*$F14) | AK14: =IF(AJ14="","",AJ14*$E14) | AL14: =IF(AJ14="","",AJ14*$F14) | AN14: =IF(AM14="","",AM14*$E14) | AO14: =IF(AM14="","",AM14*$F14) | AQ14: =IF(AP14="","",AP14*$E14) | AR14: =IF(AP14="","",AP14*$F14) | AT14: =IF(AS14="","",AS14*$E14) | AU14: =IF(AS14="","",AS14*$F14) | AW14: =IF(AV14="","",AV14*$E14) | AX14: =IF(AV14="","",AV14*$F14) | AZ14: =IF(AY14="","",AY14*$E14) | BA14: =IF(AY14="","",AY14*$F14) | BC14: =IF(BB14="","",BB14*$E14) | BD14: =IF(BB14="","",BB14*$F14) | BF14: =IF(BE14="","",BE14*$E14) | BG14: =IF(BE14="","",BE14*$F14) | BI14: =IF(BH14="","",BH14*$E14) | BJ14: =IF(BH14="","",BH14*$F14) | BL14: =IF(BK14="","",BK14*$E14) | BM14: =IF(BK14="","",BK14*$F14) | BO14: =IF(BN14="","",BN14*$E14) | BP14: =IF(BN14="","",BN14*$F14) | BR14: =IF(BQ14="","",BQ14*$E14) | BS14: =IF(BQ14="","",BQ14*$F14) | BU14: =IF(BT14="","",BT14*$E14) | BV14: =IF(BT14="","",BT14*$F14) | BX14: =IF(BW14="","",BW14*$E14) | BY14: =IF(BW14="","",BW14*$F14) | CA14: =IF(BZ14="","",BZ14*$E14) | CB14: =IF(BZ14="","",BZ14*$F14) | CD14: =IF(CC14="","",CC14*$E14) | CE14: =IF(CC14="","",CC14*$F14) | CG14: =IF(CF14="","",CF14*$E14) | CH14: =IF(CF14="","",CF14*$F14) | CI14: =IF(R14>0,P14,0) + IF(X14>0,V14,0) + IF(AD14>0,AB14,0) + IF(AJ14>0,AH14,0) + IF(AP14>0,AN14,0) + IF(AV14>0,AT14,0) + IF(BB14>0,AZ14,0) + IF(BH14>0,BF14,0) + IF(BN14>0,BL14,0) + IF(BT14>0,BR14,0) + IF(BZ14>0,BX14,0) + IF(CF14>0,CD14,0) -> 0 | CJ14: =IF(R14>0,Q14,0) + IF(X14>0,W14,0) + IF(AD14>0,AC14,0) + IF(AJ14>0,AI14,0) + IF(AP14>0,AO14,0) + IF(AV14>0,AU14,0) + IF(BB14>0,BA14,0) + IF(BH14>0,BG14,0) + IF(BN14>0,BM14,0) + IF(BT14>0,BS14,0) + IF(BZ14>0,BY14,0) + IF(CF14>0,CE14,0) -> 0
A15: 東大阪 | B15: =IF(D15="","",IFERROR(VLOOKUP(D15,商品マスタ!$A:$K,2,FALSE),"缶バッジ")) -> 缶バッジ | C15: ベック | D15: バックパーツ・シェル | E15: =IF(D15="","",IFERROR(VLOOKUP(D15,商品マスタ!$A:$K,4,FALSE),3.72)) -> 3.72 | F15: =IF(D15="","",IFERROR(VLOOKUP(D15,商品マスタ!$A:$K,8,FALSE),0.34)) -> 0.34 | G15: =SUM(O15,U15,AA15,AG15,AM15,AS15,AY15,BE15,BK15,BQ15,BW15,CC15) -> 0 | H15: =SUM(P15,V15,AB15,AH15,AN15,AT15,AZ15,BF15,BL15,BR15,BX15,CD15) -> 0 | I15: =SUM(Q15,W15,AC15,AI15,AO15,AU15,BA15,BG15,BM15,BS15,BY15,CE15) -> 0 | J15: =SUM(R15,X15,AD15,AJ15,AP15,AV15,BB15,BH15,BN15,BT15,BZ15,CF15) -> 0 | K15: =SUM(S15,Y15,AE15,AK15,AQ15,AW15,BC15,BI15,BO15,BU15,CA15,CG15) -> 0 | L15: =SUM(T15,Z15,AF15,AL15,AR15,AX15,BD15,BJ15,BP15,BV15,CB15,CH15) -> 0 | M15: =IFERROR(K15/CI15,"") | N15: =IFERROR(L15/CJ15,"") | P15: =IF(O15="","",O15*$E15) | Q15: =IF(O15="","",O15*$F15) | S15: =IF(R15="","",R15*$E15) | T15: =IF(R15="","",R15*$F15) | V15: =IF(U15="","",U15*$E15) | W15: =IF(U15="","",U15*$F15) | Y15: =IF(X15="","",X15*$E15) | Z15: =IF(X15="","",X15*$F15) | AB15: =IF(AA15="","",AA15*$E15) | AC15: =IF(AA15="","",AA15*$F15) | AE15: =IF(AD15="","",AD15*$E15) | AF15: =IF(AD15="","",AD15*$F15) | AH15: =IF(AG15="","",AG15*$E15) | AI15: =IF(AG15="","",AG15*$F15) | AK15: =IF(AJ15="","",AJ15*$E15) | AL15: =IF(AJ15="","",AJ15*$F15) | AN15: =IF(AM15="","",AM15*$E15) | AO15: =IF(AM15="","",AM15*$F15) | AQ15: =IF(AP15="","",AP15*$E15) | AR15: =IF(AP15="","",AP15*$F15) | AT15: =IF(AS15="","",AS15*$E15) | AU15: =IF(AS15="","",AS15*$F15) | AW15: =IF(AV15="","",AV15*$E15) | AX15: =IF(AV15="","",AV15*$F15) | AZ15: =IF(AY15="","",AY15*$E15) | BA15: =IF(AY15="","",AY15*$F15) | BC15: =IF(BB15="","",BB15*$E15) | BD15: =IF(BB15="","",BB15*$F15) | BF15: =IF(BE15="","",BE15*$E15) | BG15: =IF(BE15="","",BE15*$F15) | BI15: =IF(BH15="","",BH15*$E15) | BJ15: =IF(BH15="","",BH15*$F15) | BL15: =IF(BK15="","",BK15*$E15) | BM15: =IF(BK15="","",BK15*$F15) | BO15: =IF(BN15="","",BN15*$E15) | BP15: =IF(BN15="","",BN15*$F15) | BR15: =IF(BQ15="","",BQ15*$E15) | BS15: =IF(BQ15="","",BQ15*$F15) | BU15: =IF(BT15="","",BT15*$E15) | BV15: =IF(BT15="","",BT15*$F15) | BX15: =IF(BW15="","",BW15*$E15) | BY15: =IF(BW15="","",BW15*$F15) | CA15: =IF(BZ15="","",BZ15*$E15) | CB15: =IF(BZ15="","",BZ15*$F15) | CD15: =IF(CC15="","",CC15*$E15) | CE15: =IF(CC15="","",CC15*$F15) | CG15: =IF(CF15="","",CF15*$E15) | CH15: =IF(CF15="","",CF15*$F15) | CI15: =IF(R15>0,P15,0) + IF(X15>0,V15,0) + IF(AD15>0,AB15,0) + IF(AJ15>0,AH15,0) + IF(AP15>0,AN15,0) + IF(AV15>0,AT15,0) + IF(BB15>0,AZ15,0) + IF(BH15>0,BF15,0) + IF(BN15>0,BL15,0) + IF(BT15>0,BR15,0) + IF(BZ15>0,BX15,0) + IF(CF15>0,CD15,0) -> 0 | CJ15: =IF(R15>0,Q15,0) + IF(X15>0,W15,0) + IF(AD15>0,AC15,0) + IF(AJ15>0,AI15,0) + IF(AP15>0,AO15,0) + IF(AV15>0,AU15,0) + IF(BB15>0,BA15,0) + IF(BH15>0,BG15,0) + IF(BN15>0,BM15,0) + IF(BT15>0,BS15,0) + IF(BZ15>0,BY15,0) + IF(CF15>0,CE15,0) -> 0
A16: 松原 | B16: =IF(D16="","",IFERROR(VLOOKUP(D16,商品マスタ!$A:$K,2,FALSE),"缶バッジ")) -> 缶バッジ | C16: よつば | D16: 下蓋・穴下・ツメ下 | E16: =IF(D16="","",IFERROR(VLOOKUP(D16,商品マスタ!$A:$K,4,FALSE),12.55)) -> 12.55 | F16: =IF(D16="","",IFERROR(VLOOKUP(D16,商品マスタ!$A:$K,8,FALSE),1.14)) -> 1.14 | G16: =SUM(O16,U16,AA16,AG16,AM16,AS16,AY16,BE16,BK16,BQ16,BW16,CC16) -> 0 | H16: =SUM(P16,V16,AB16,AH16,AN16,AT16,AZ16,BF16,BL16,BR16,BX16,CD16) -> 0 | I16: =SUM(Q16,W16,AC16,AI16,AO16,AU16,BA16,BG16,BM16,BS16,BY16,CE16) -> 0 | J16: =SUM(R16,X16,AD16,AJ16,AP16,AV16,BB16,BH16,BN16,BT16,BZ16,CF16) -> 0 | K16: =SUM(S16,Y16,AE16,AK16,AQ16,AW16,BC16,BI16,BO16,BU16,CA16,CG16) -> 0 | L16: =SUM(T16,Z16,AF16,AL16,AR16,AX16,BD16,BJ16,BP16,BV16,CB16,CH16) -> 0 | M16: =IFERROR(K16/CI16,"") | N16: =IFERROR(L16/CJ16,"") | P16: =IF(O16="","",O16*$E16) | Q16: =IF(O16="","",O16*$F16) | S16: =IF(R16="","",R16*$E16) | T16: =IF(R16="","",R16*$F16) | V16: =IF(U16="","",U16*$E16) | W16: =IF(U16="","",U16*$F16) | Y16: =IF(X16="","",X16*$E16) | Z16: =IF(X16="","",X16*$F16) | AB16: =IF(AA16="","",AA16*$E16) | AC16: =IF(AA16="","",AA16*$F16) | AE16: =IF(AD16="","",AD16*$E16) | AF16: =IF(AD16="","",AD16*$F16) | AH16: =IF(AG16="","",AG16*$E16) | AI16: =IF(AG16="","",AG16*$F16) | AK16: =IF(AJ16="","",AJ16*$E16) | AL16: =IF(AJ16="","",AJ16*$F16) | AN16: =IF(AM16="","",AM16*$E16) | AO16: =IF(AM16="","",AM16*$F16) | AQ16: =IF(AP16="","",AP16*$E16) | AR16: =IF(AP16="","",AP16*$F16) | AT16: =IF(AS16="","",AS16*$E16) | AU16: =IF(AS16="","",AS16*$F16) | AW16: =IF(AV16="","",AV16*$E16) | AX16: =IF(AV16="","",AV16*$F16) | AZ16: =IF(AY16="","",AY16*$E16) | BA16: =IF(AY16="","",AY16*$F16) | BC16: =IF(BB16="","",BB16*$E16) | BD16: =IF(BB16="","",BB16*$F16) | BF16: =IF(BE16="","",BE16*$E16) | BG16: =IF(BE16="","",BE16*$F16) | BI16: =IF(BH16="","",BH16*$E16) | BJ16: =IF(BH16="","",BH16*$F16) | BL16: =IF(BK16="","",BK16*$E16) | BM16: =IF(BK16="","",BK16*$F16) | BO16: =IF(BN16="","",BN16*$E16) | BP16: =IF(BN16="","",BN16*$F16) | BR16: =IF(BQ16="","",BQ16*$E16) | BS16: =IF(BQ16="","",BQ16*$F16) | BU16: =IF(BT16="","",BT16*$E16) | BV16: =IF(BT16="","",BT16*$F16) | BX16: =IF(BW16="","",BW16*$E16) | BY16: =IF(BW16="","",BW16*$F16) | CA16: =IF(BZ16="","",BZ16*$E16) | CB16: =IF(BZ16="","",BZ16*$F16) | CD16: =IF(CC16="","",CC16*$E16) | CE16: =IF(CC16="","",CC16*$F16) | CG16: =IF(CF16="","",CF16*$E16) | CH16: =IF(CF16="","",CF16*$F16) | CI16: =IF(R16>0,P16,0) + IF(X16>0,V16,0) + IF(AD16>0,AB16,0) + IF(AJ16>0,AH16,0) + IF(AP16>0,AN16,0) + IF(AV16>0,AT16,0) + IF(BB16>0,AZ16,0) + IF(BH16>0,BF16,0) + IF(BN16>0,BL16,0) + IF(BT16>0,BR16,0) + IF(BZ16>0,BX16,0) + IF(CF16>0,CD16,0) -> 0 | CJ16: =IF(R16>0,Q16,0) + IF(X16>0,W16,0) + IF(AD16>0,AC16,0) + IF(AJ16>0,AI16,0) + IF(AP16>0,AO16,0) + IF(AV16>0,AU16,0) + IF(BB16>0,BA16,0) + IF(BH16>0,BG16,0) + IF(BN16>0,BM16,0) + IF(BT16>0,BS16,0) + IF(BZ16>0,BY16,0) + IF(CF16>0,CE16,0) -> 0
A17: 松原 | B17: =IF(D17="","",IFERROR(VLOOKUP(D17,商品マスタ!$A:$K,2,FALSE),"缶バッジ")) -> 缶バッジ | C17: アニキャン | D17: 下蓋・穴下・ツメ下 | E17: =IF(D17="","",IFERROR(VLOOKUP(D17,商品マスタ!$A:$K,4,FALSE),12.55)) -> 12.55 | F17: =IF(D17="","",IFERROR(VLOOKUP(D17,商品マスタ!$A:$K,8,FALSE),1.14)) -> 1.14 | G17: =SUM(O17,U17,AA17,AG17,AM17,AS17,AY17,BE17,BK17,BQ17,BW17,CC17) -> 0 | H17: =SUM(P17,V17,AB17,AH17,AN17,AT17,AZ17,BF17,BL17,BR17,BX17,CD17) -> 0 | I17: =SUM(Q17,W17,AC17,AI17,AO17,AU17,BA17,BG17,BM17,BS17,BY17,CE17) -> 0 | J17: =SUM(R17,X17,AD17,AJ17,AP17,AV17,BB17,BH17,BN17,BT17,BZ17,CF17) -> 0 | K17: =SUM(S17,Y17,AE17,AK17,AQ17,AW17,BC17,BI17,BO17,BU17,CA17,CG17) -> 0 | L17: =SUM(T17,Z17,AF17,AL17,AR17,AX17,BD17,BJ17,BP17,BV17,CB17,CH17) -> 0 | M17: =IFERROR(K17/CI17,"") | N17: =IFERROR(L17/CJ17,"") | P17: =IF(O17="","",O17*$E17) | Q17: =IF(O17="","",O17*$F17) | S17: =IF(R17="","",R17*$E17) | T17: =IF(R17="","",R17*$F17) | V17: =IF(U17="","",U17*$E17) | W17: =IF(U17="","",U17*$F17) | Y17: =IF(X17="","",X17*$E17) | Z17: =IF(X17="","",X17*$F17) | AB17: =IF(AA17="","",AA17*$E17) | AC17: =IF(AA17="","",AA17*$F17) | AE17: =IF(AD17="","",AD17*$E17) | AF17: =IF(AD17="","",AD17*$F17) | AH17: =IF(AG17="","",AG17*$E17) | AI17: =IF(AG17="","",AG17*$F17) | AK17: =IF(AJ17="","",AJ17*$E17) | AL17: =IF(AJ17="","",AJ17*$F17) | AN17: =IF(AM17="","",AM17*$E17) | AO17: =IF(AM17="","",AM17*$F17) | AQ17: =IF(AP17="","",AP17*$E17) | AR17: =IF(AP17="","",AP17*$F17) | AT17: =IF(AS17="","",AS17*$E17) | AU17: =IF(AS17="","",AS17*$F17) | AW17: =IF(AV17="","",AV17*$E17) | AX17: =IF(AV17="","",AV17*$F17) | AZ17: =IF(AY17="","",AY17*$E17) | BA17: =IF(AY17="","",AY17*$F17) | BC17: =IF(BB17="","",BB17*$E17) | BD17: =IF(BB17="","",BB17*$F17) | BF17: =IF(BE17="","",BE17*$E17) | BG17: =IF(BE17="","",BE17*$F17) | BI17: =IF(BH17="","",BH17*$E17) | BJ17: =IF(BH17="","",BH17*$F17) | BL17: =IF(BK17="","",BK17*$E17) | BM17: =IF(BK17="","",BK17*$F17) | BO17: =IF(BN17="","",BN17*$E17) | BP17: =IF(BN17="","",BN17*$F17) | BR17: =IF(BQ17="","",BQ17*$E17) | BS17: =IF(BQ17="","",BQ17*$F17) | BU17: =IF(BT17="","",BT17*$E17) | BV17: =IF(BT17="","",BT17*$F17) | BX17: =IF(BW17="","",BW17*$E17) | BY17: =IF(BW17="","",BW17*$F17) | CA17: =IF(BZ17="","",BZ17*$E17) | CB17: =IF(BZ17="","",BZ17*$F17) | CD17: =IF(CC17="","",CC17*$E17) | CE17: =IF(CC17="","",CC17*$F17) | CG17: =IF(CF17="","",CF17*$E17) | CH17: =IF(CF17="","",CF17*$F17) | CI17: =IF(R17>0,P17,0) + IF(X17>0,V17,0) + IF(AD17>0,AB17,0) + IF(AJ17>0,AH17,0) + IF(AP17>0,AN17,0) + IF(AV17>0,AT17,0) + IF(BB17>0,AZ17,0) + IF(BH17>0,BF17,0) + IF(BN17>0,BL17,0) + IF(BT17>0,BR17,0) + IF(BZ17>0,BX17,0) + IF(CF17>0,CD17,0) -> 0 | CJ17: =IF(R17>0,Q17,0) + IF(X17>0,W17,0) + IF(AD17>0,AC17,0) + IF(AJ17>0,AI17,0) + IF(AP17>0,AO17,0) + IF(AV17>0,AU17,0) + IF(BB17>0,BA17,0) + IF(BH17>0,BG17,0) + IF(BN17>0,BM17,0) + IF(BT17>0,BS17,0) + IF(BZ17>0,BY17,0) + IF(CF17>0,CE17,0) -> 0
A18: 松原 | B18: =IF(D18="","",IFERROR(VLOOKUP(D18,商品マスタ!$A:$K,2,FALSE),"缶バッジ")) -> 缶バッジ | C18: アンフィニ | D18: 下蓋・穴下・ツメ下 | E18: =IF(D18="","",IFERROR(VLOOKUP(D18,商品マスタ!$A:$K,4,FALSE),12.55)) -> 12.55 | F18: =IF(D18="","",IFERROR(VLOOKUP(D18,商品マスタ!$A:$K,8,FALSE),1.14)) -> 1.14 | G18: =SUM(O18,U18,AA18,AG18,AM18,AS18,AY18,BE18,BK18,BQ18,BW18,CC18) -> 0 | H18: =SUM(P18,V18,AB18,AH18,AN18,AT18,AZ18,BF18,BL18,BR18,BX18,CD18) -> 0 | I18: =SUM(Q18,W18,AC18,AI18,AO18,AU18,BA18,BG18,BM18,BS18,BY18,CE18) -> 0 | J18: =SUM(R18,X18,AD18,AJ18,AP18,AV18,BB18,BH18,BN18,BT18,BZ18,CF18) -> 0 | K18: =SUM(S18,Y18,AE18,AK18,AQ18,AW18,BC18,BI18,BO18,BU18,CA18,CG18) -> 0 | L18: =SUM(T18,Z18,AF18,AL18,AR18,AX18,BD18,BJ18,BP18,BV18,CB18,CH18) -> 0 | M18: =IFERROR(K18/CI18,"") | N18: =IFERROR(L18/CJ18,"") | P18: =IF(O18="","",O18*$E18) | Q18: =IF(O18="","",O18*$F18) | S18: =IF(R18="","",R18*$E18) | T18: =IF(R18="","",R18*$F18) | V18: =IF(U18="","",U18*$E18) | W18: =IF(U18="","",U18*$F18) | Y18: =IF(X18="","",X18*$E18) | Z18: =IF(X18="","",X18*$F18) | AB18: =IF(AA18="","",AA18*$E18) | AC18: =IF(AA18="","",AA18*$F18) | AE18: =IF(AD18="","",AD18*$E18) | AF18: =IF(AD18="","",AD18*$F18) | AH18: =IF(AG18="","",AG18*$E18) | AI18: =IF(AG18="","",AG18*$F18) | AK18: =IF(AJ18="","",AJ18*$E18) | AL18: =IF(AJ18="","",AJ18*$F18) | AN18: =IF(AM18="","",AM18*$E18) | AO18: =IF(AM18="","",AM18*$F18) | AQ18: =IF(AP18="","",AP18*$E18) | AR18: =IF(AP18="","",AP18*$F18) | AT18: =IF(AS18="","",AS18*$E18) | AU18: =IF(AS18="","",AS18*$F18) | AW18: =IF(AV18="","",AV18*$E18) | AX18: =IF(AV18="","",AV18*$F18) | AZ18: =IF(AY18="","",AY18*$E18) | BA18: =IF(AY18="","",AY18*$F18) | BC18: =IF(BB18="","",BB18*$E18) | BD18: =IF(BB18="","",BB18*$F18) | BF18: =IF(BE18="","",BE18*$E18) | BG18: =IF(BE18="","",BE18*$F18) | BI18: =IF(BH18="","",BH18*$E18) | BJ18: =IF(BH18="","",BH18*$F18) | BL18: =IF(BK18="","",BK18*$E18) | BM18: =IF(BK18="","",BK18*$F18) | BO18: =IF(BN18="","",BN18*$E18) | BP18: =IF(BN18="","",BN18*$F18) | BR18: =IF(BQ18="","",BQ18*$E18) | BS18: =IF(BQ18="","",BQ18*$F18) | BU18: =IF(BT18="","",BT18*$E18) | BV18: =IF(BT18="","",BT18*$F18) | BX18: =IF(BW18="","",BW18*$E18) | BY18: =IF(BW18="","",BW18*$F18) | CA18: =IF(BZ18="","",BZ18*$E18) | CB18: =IF(BZ18="","",BZ18*$F18) | CD18: =IF(CC18="","",CC18*$E18) | CE18: =IF(CC18="","",CC18*$F18) | CG18: =IF(CF18="","",CF18*$E18) | CH18: =IF(CF18="","",CF18*$F18) | CI18: =IF(R18>0,P18,0) + IF(X18>0,V18,0) + IF(AD18>0,AB18,0) + IF(AJ18>0,AH18,0) + IF(AP18>0,AN18,0) + IF(AV18>0,AT18,0) + IF(BB18>0,AZ18,0) + IF(BH18>0,BF18,0) + IF(BN18>0,BL18,0) + IF(BT18>0,BR18,0) + IF(BZ18>0,BX18,0) + IF(CF18>0,CD18,0) -> 0 | CJ18: =IF(R18>0,Q18,0) + IF(X18>0,W18,0) + IF(AD18>0,AC18,0) + IF(AJ18>0,AI18,0) + IF(AP18>0,AO18,0) + IF(AV18>0,AU18,0) + IF(BB18>0,BA18,0) + IF(BH18>0,BG18,0) + IF(BN18>0,BM18,0) + IF(BT18>0,BS18,0) + IF(BZ18>0,BY18,0) + IF(CF18>0,CE18,0) -> 0
A19: 松原 | B19: =IF(D19="","",IFERROR(VLOOKUP(D19,商品マスタ!$A:$K,2,FALSE),"缶バッジ")) -> 缶バッジ | C19: イナバ工芸社 | D19: 下蓋・穴下・ツメ下 | E19: =IF(D19="","",IFERROR(VLOOKUP(D19,商品マスタ!$A:$K,4,FALSE),12.55)) -> 12.55 | F19: =IF(D19="","",IFERROR(VLOOKUP(D19,商品マスタ!$A:$K,8,FALSE),1.14)) -> 1.14 | G19: =SUM(O19,U19,AA19,AG19,AM19,AS19,AY19,BE19,BK19,BQ19,BW19,CC19) -> 0 | H19: =SUM(P19,V19,AB19,AH19,AN19,AT19,AZ19,BF19,BL19,BR19,BX19,CD19) -> 0 | I19: =SUM(Q19,W19,AC19,AI19,AO19,AU19,BA19,BG19,BM19,BS19,BY19,CE19) -> 0 | J19: =SUM(R19,X19,AD19,AJ19,AP19,AV19,BB19,BH19,BN19,BT19,BZ19,CF19) -> 0 | K19: =SUM(S19,Y19,AE19,AK19,AQ19,AW19,BC19,BI19,BO19,BU19,CA19,CG19) -> 0 | L19: =SUM(T19,Z19,AF19,AL19,AR19,AX19,BD19,BJ19,BP19,BV19,CB19,CH19) -> 0 | M19: =IFERROR(K19/CI19,"") | N19: =IFERROR(L19/CJ19,"") | P19: =IF(O19="","",O19*$E19) | Q19: =IF(O19="","",O19*$F19) | S19: =IF(R19="","",R19*$E19) | T19: =IF(R19="","",R19*$F19) | V19: =IF(U19="","",U19*$E19) | W19: =IF(U19="","",U19*$F19) | Y19: =IF(X19="","",X19*$E19) | Z19: =IF(X19="","",X19*$F19) | AB19: =IF(AA19="","",AA19*$E19) | AC19: =IF(AA19="","",AA19*$F19) | AE19: =IF(AD19="","",AD19*$E19) | AF19: =IF(AD19="","",AD19*$F19) | AH19: =IF(AG19="","",AG19*$E19) | AI19: =IF(AG19="","",AG19*$F19) | AK19: =IF(AJ19="","",AJ19*$E19) | AL19: =IF(AJ19="","",AJ19*$F19) | AN19: =IF(AM19="","",AM19*$E19) | AO19: =IF(AM19="","",AM19*$F19) | AQ19: =IF(AP19="","",AP19*$E19) | AR19: =IF(AP19="","",AP19*$F19) | AT19: =IF(AS19="","",AS19*$E19) | AU19: =IF(AS19="","",AS19*$F19) | AW19: =IF(AV19="","",AV19*$E19) | AX19: =IF(AV19="","",AV19*$F19) | AZ19: =IF(AY19="","",AY19*$E19) | BA19: =IF(AY19="","",AY19*$F19) | BC19: =IF(BB19="","",BB19*$E19) | BD19: =IF(BB19="","",BB19*$F19) | BF19: =IF(BE19="","",BE19*$E19) | BG19: =IF(BE19="","",BE19*$F19) | BI19: =IF(BH19="","",BH19*$E19) | BJ19: =IF(BH19="","",BH19*$F19) | BL19: =IF(BK19="","",BK19*$E19) | BM19: =IF(BK19="","",BK19*$F19) | BO19: =IF(BN19="","",BN19*$E19) | BP19: =IF(BN19="","",BN19*$F19) | BR19: =IF(BQ19="","",BQ19*$E19) | BS19: =IF(BQ19="","",BQ19*$F19) | BU19: =IF(BT19="","",BT19*$E19) | BV19: =IF(BT19="","",BT19*$F19) | BX19: =IF(BW19="","",BW19*$E19) | BY19: =IF(BW19="","",BW19*$F19) | CA19: =IF(BZ19="","",BZ19*$E19) | CB19: =IF(BZ19="","",BZ19*$F19) | CD19: =IF(CC19="","",CC19*$E19) | CE19: =IF(CC19="","",CC19*$F19) | CG19: =IF(CF19="","",CF19*$E19) | CH19: =IF(CF19="","",CF19*$F19) | CI19: =IF(R19>0,P19,0) + IF(X19>0,V19,0) + IF(AD19>0,AB19,0) + IF(AJ19>0,AH19,0) + IF(AP19>0,AN19,0) + IF(AV19>0,AT19,0) + IF(BB19>0,AZ19,0) + IF(BH19>0,BF19,0) + IF(BN19>0,BL19,0) + IF(BT19>0,BR19,0) + IF(BZ19>0,BX19,0) + IF(CF19>0,CD19,0) -> 0 | CJ19: =IF(R19>0,Q19,0) + IF(X19>0,W19,0) + IF(AD19>0,AC19,0) + IF(AJ19>0,AI19,0) + IF(AP19>0,AO19,0) + IF(AV19>0,AU19,0) + IF(BB19>0,BA19,0) + IF(BH19>0,BG19,0) + IF(BN19>0,BM19,0) + IF(BT19>0,BS19,0) + IF(BZ19>0,BY19,0) + IF(CF19>0,CE19,0) -> 0
A20: 松原 | B20: =IF(D20="","",IFERROR(VLOOKUP(D20,商品マスタ!$A:$K,2,FALSE),"缶バッジ")) -> 缶バッジ | C20: エイチアールシー | D20: 下蓋・穴下・ツメ下 | E20: =IF(D20="","",IFERROR(VLOOKUP(D20,商品マスタ!$A:$K,4,FALSE),12.55)) -> 12.55 | F20: =IF(D20="","",IFERROR(VLOOKUP(D20,商品マスタ!$A:$K,8,FALSE),1.14)) -> 1.14 | G20: =SUM(O20,U20,AA20,AG20,AM20,AS20,AY20,BE20,BK20,BQ20,BW20,CC20) -> 0 | H20: =SUM(P20,V20,AB20,AH20,AN20,AT20,AZ20,BF20,BL20,BR20,BX20,CD20) -> 0 | I20: =SUM(Q20,W20,AC20,AI20,AO20,AU20,BA20,BG20,BM20,BS20,BY20,CE20) -> 0 | J20: =SUM(R20,X20,AD20,AJ20,AP20,AV20,BB20,BH20,BN20,BT20,BZ20,CF20) -> 0 | K20: =SUM(S20,Y20,AE20,AK20,AQ20,AW20,BC20,BI20,BO20,BU20,CA20,CG20) -> 0 | L20: =SUM(T20,Z20,AF20,AL20,AR20,AX20,BD20,BJ20,BP20,BV20,CB20,CH20) -> 0 | M20: =IFERROR(K20/CI20,"") | N20: =IFERROR(L20/CJ20,"") | P20: =IF(O20="","",O20*$E20) | Q20: =IF(O20="","",O20*$F20) | S20: =IF(R20="","",R20*$E20) | T20: =IF(R20="","",R20*$F20) | V20: =IF(U20="","",U20*$E20) | W20: =IF(U20="","",U20*$F20) | Y20: =IF(X20="","",X20*$E20) | Z20: =IF(X20="","",X20*$F20) | AB20: =IF(AA20="","",AA20*$E20) | AC20: =IF(AA20="","",AA20*$F20) | AE20: =IF(AD20="","",AD20*$E20) | AF20: =IF(AD20="","",AD20*$F20) | AH20: =IF(AG20="","",AG20*$E20) | AI20: =IF(AG20="","",AG20*$F20) | AK20: =IF(AJ20="","",AJ20*$E20) | AL20: =IF(AJ20="","",AJ20*$F20) | AN20: =IF(AM20="","",AM20*$E20) | AO20: =IF(AM20="","",AM20*$F20) | AQ20: =IF(AP20="","",AP20*$E20) | AR20: =IF(AP20="","",AP20*$F20) | AT20: =IF(AS20="","",AS20*$E20) | AU20: =IF(AS20="","",AS20*$F20) | AW20: =IF(AV20="","",AV20*$E20) | AX20: =IF(AV20="","",AV20*$F20) | AZ20: =IF(AY20="","",AY20*$E20) | BA20: =IF(AY20="","",AY20*$F20) | BC20: =IF(BB20="","",BB20*$E20) | BD20: =IF(BB20="","",BB20*$F20) | BF20: =IF(BE20="","",BE20*$E20) | BG20: =IF(BE20="","",BE20*$F20) | BI20: =IF(BH20="","",BH20*$E20) | BJ20: =IF(BH20="","",BH20*$F20) | BL20: =IF(BK20="","",BK20*$E20) | BM20: =IF(BK20="","",BK20*$F20) | BO20: =IF(BN20="","",BN20*$E20) | BP20: =IF(BN20="","",BN20*$F20) | BR20: =IF(BQ20="","",BQ20*$E20) | BS20: =IF(BQ20="","",BQ20*$F20) | BU20: =IF(BT20="","",BT20*$E20) | BV20: =IF(BT20="","",BT20*$F20) | BX20: =IF(BW20="","",BW20*$E20) | BY20: =IF(BW20="","",BW20*$F20) | CA20: =IF(BZ20="","",BZ20*$E20) | CB20: =IF(BZ20="","",BZ20*$F20) | CD20: =IF(CC20="","",CC20*$E20) | CE20: =IF(CC20="","",CC20*$F20) | CG20: =IF(CF20="","",CF20*$E20) | CH20: =IF(CF20="","",CF20*$F20) | CI20: =IF(R20>0,P20,0) + IF(X20>0,V20,0) + IF(AD20>0,AB20,0) + IF(AJ20>0,AH20,0) + IF(AP20>0,AN20,0) + IF(AV20>0,AT20,0) + IF(BB20>0,AZ20,0) + IF(BH20>0,BF20,0) + IF(BN20>0,BL20,0) + IF(BT20>0,BR20,0) + IF(BZ20>0,BX20,0) + IF(CF20>0,CD20,0) -> 0 | CJ20: =IF(R20>0,Q20,0) + IF(X20>0,W20,0) + IF(AD20>0,AC20,0) + IF(AJ20>0,AI20,0) + IF(AP20>0,AO20,0) + IF(AV20>0,AU20,0) + IF(BB20>0,BA20,0) + IF(BH20>0,BG20,0) + IF(BN20>0,BM20,0) + IF(BT20>0,BS20,0) + IF(BZ20>0,BY20,0) + IF(CF20>0,CE20,0) -> 0
A21: 松原 | B21: =IF(D21="","",IFERROR(VLOOKUP(D21,商品マスタ!$A:$K,2,FALSE),"缶バッジ")) -> 缶バッジ | C21: エムズカンパニー | D21: 下蓋・穴下・ツメ下 | E21: =IF(D21="","",IFERROR(VLOOKUP(D21,商品マスタ!$A:$K,4,FALSE),12.55)) -> 12.55 | F21: =IF(D21="","",IFERROR(VLOOKUP(D21,商品マスタ!$A:$K,8,FALSE),1.14)) -> 1.14 | G21: =SUM(O21,U21,AA21,AG21,AM21,AS21,AY21,BE21,BK21,BQ21,BW21,CC21) -> 0 | H21: =SUM(P21,V21,AB21,AH21,AN21,AT21,AZ21,BF21,BL21,BR21,BX21,CD21) -> 0 | I21: =SUM(Q21,W21,AC21,AI21,AO21,AU21,BA21,BG21,BM21,BS21,BY21,CE21) -> 0 | J21: =SUM(R21,X21,AD21,AJ21,AP21,AV21,BB21,BH21,BN21,BT21,BZ21,CF21) -> 0 | K21: =SUM(S21,Y21,AE21,AK21,AQ21,AW21,BC21,BI21,BO21,BU21,CA21,CG21) -> 0 | L21: =SUM(T21,Z21,AF21,AL21,AR21,AX21,BD21,BJ21,BP21,BV21,CB21,CH21) -> 0 | M21: =IFERROR(K21/CI21,"") | N21: =IFERROR(L21/CJ21,"") | P21: =IF(O21="","",O21*$E21) | Q21: =IF(O21="","",O21*$F21) | S21: =IF(R21="","",R21*$E21) | T21: =IF(R21="","",R21*$F21) | V21: =IF(U21="","",U21*$E21) | W21: =IF(U21="","",U21*$F21) | Y21: =IF(X21="","",X21*$E21) | Z21: =IF(X21="","",X21*$F21) | AB21: =IF(AA21="","",AA21*$E21) | AC21: =IF(AA21="","",AA21*$F21) | AE21: =IF(AD21="","",AD21*$E21) | AF21: =IF(AD21="","",AD21*$F21) | AH21: =IF(AG21="","",AG21*$E21) | AI21: =IF(AG21="","",AG21*$F21) | AK21: =IF(AJ21="","",AJ21*$E21) | AL21: =IF(AJ21="","",AJ21*$F21) | AN21: =IF(AM21="","",AM21*$E21) | AO21: =IF(AM21="","",AM21*$F21) | AQ21: =IF(AP21="","",AP21*$E21) | AR21: =IF(AP21="","",AP21*$F21) | AT21: =IF(AS21="","",AS21*$E21) | AU21: =IF(AS21="","",AS21*$F21) | AW21: =IF(AV21="","",AV21*$E21) | AX21: =IF(AV21="","",AV21*$F21) | AZ21: =IF(AY21="","",AY21*$E21) | BA21: =IF(AY21="","",AY21*$F21) | BC21: =IF(BB21="","",BB21*$E21) | BD21: =IF(BB21="","",BB21*$F21) | BF21: =IF(BE21="","",BE21*$E21) | BG21: =IF(BE21="","",BE21*$F21) | BI21: =IF(BH21="","",BH21*$E21) | BJ21: =IF(BH21="","",BH21*$F21) | BL21: =IF(BK21="","",BK21*$E21) | BM21: =IF(BK21="","",BK21*$F21) | BO21: =IF(BN21="","",BN21*$E21) | BP21: =IF(BN21="","",BN21*$F21) | BR21: =IF(BQ21="","",BQ21*$E21) | BS21: =IF(BQ21="","",BQ21*$F21) | BU21: =IF(BT21="","",BT21*$E21) | BV21: =IF(BT21="","",BT21*$F21) | BX21: =IF(BW21="","",BW21*$E21) | BY21: =IF(BW21="","",BW21*$F21) | CA21: =IF(BZ21="","",BZ21*$E21) | CB21: =IF(BZ21="","",BZ21*$F21) | CD21: =IF(CC21="","",CC21*$E21) | CE21: =IF(CC21="","",CC21*$F21) | CG21: =IF(CF21="","",CF21*$E21) | CH21: =IF(CF21="","",CF21*$F21) | CI21: =IF(R21>0,P21,0) + IF(X21>0,V21,0) + IF(AD21>0,AB21,0) + IF(AJ21>0,AH21,0) + IF(AP21>0,AN21,0) + IF(AV21>0,AT21,0) + IF(BB21>0,AZ21,0) + IF(BH21>0,BF21,0) + IF(BN21>0,BL21,0) + IF(BT21>0,BR21,0) + IF(BZ21>0,BX21,0) + IF(CF21>0,CD21,0) -> 0 | CJ21: =IF(R21>0,Q21,0) + IF(X21>0,W21,0) + IF(AD21>0,AC21,0) + IF(AJ21>0,AI21,0) + IF(AP21>0,AO21,0) + IF(AV21>0,AU21,0) + IF(BB21>0,BA21,0) + IF(BH21>0,BG21,0) + IF(BN21>0,BM21,0) + IF(BT21>0,BS21,0) + IF(BZ21>0,BY21,0) + IF(CF21>0,CE21,0) -> 0
A22: 松原 | B22: =IF(D22="","",IFERROR(VLOOKUP(D22,商品マスタ!$A:$K,2,FALSE),"缶バッジ")) -> 缶バッジ | C22: オーラルケア | D22: 下蓋・穴下・ツメ下 | E22: =IF(D22="","",IFERROR(VLOOKUP(D22,商品マスタ!$A:$K,4,FALSE),12.55)) -> 12.55 | F22: =IF(D22="","",IFERROR(VLOOKUP(D22,商品マスタ!$A:$K,8,FALSE),1.14)) -> 1.14 | G22: =SUM(O22,U22,AA22,AG22,AM22,AS22,AY22,BE22,BK22,BQ22,BW22,CC22) -> 0 | H22: =SUM(P22,V22,AB22,AH22,AN22,AT22,AZ22,BF22,BL22,BR22,BX22,CD22) -> 0 | I22: =SUM(Q22,W22,AC22,AI22,AO22,AU22,BA22,BG22,BM22,BS22,BY22,CE22) -> 0 | J22: =SUM(R22,X22,AD22,AJ22,AP22,AV22,BB22,BH22,BN22,BT22,BZ22,CF22) -> 0 | K22: =SUM(S22,Y22,AE22,AK22,AQ22,AW22,BC22,BI22,BO22,BU22,CA22,CG22) -> 0 | L22: =SUM(T22,Z22,AF22,AL22,AR22,AX22,BD22,BJ22,BP22,BV22,CB22,CH22) -> 0 | M22: =IFERROR(K22/CI22,"") | N22: =IFERROR(L22/CJ22,"") | P22: =IF(O22="","",O22*$E22) | Q22: =IF(O22="","",O22*$F22) | S22: =IF(R22="","",R22*$E22) | T22: =IF(R22="","",R22*$F22) | V22: =IF(U22="","",U22*$E22) | W22: =IF(U22="","",U22*$F22) | Y22: =IF(X22="","",X22*$E22) | Z22: =IF(X22="","",X22*$F22) | AB22: =IF(AA22="","",AA22*$E22) | AC22: =IF(AA22="","",AA22*$F22) | AE22: =IF(AD22="","",AD22*$E22) | AF22: =IF(AD22="","",AD22*$F22) | AH22: =IF(AG22="","",AG22*$E22) | AI22: =IF(AG22="","",AG22*$F22) | AK22: =IF(AJ22="","",AJ22*$E22) | AL22: =IF(AJ22="","",AJ22*$F22) | AN22: =IF(AM22="","",AM22*$E22) | AO22: =IF(AM22="","",AM22*$F22) | AQ22: =IF(AP22="","",AP22*$E22) | AR22: =IF(AP22="","",AP22*$F22) | AT22: =IF(AS22="","",AS22*$E22) | AU22: =IF(AS22="","",AS22*$F22) | AW22: =IF(AV22="","",AV22*$E22) | AX22: =IF(AV22="","",AV22*$F22) | AZ22: =IF(AY22="","",AY22*$E22) | BA22: =IF(AY22="","",AY22*$F22) | BC22: =IF(BB22="","",BB22*$E22) | BD22: =IF(BB22="","",BB22*$F22) | BF22: =IF(BE22="","",BE22*$E22) | BG22: =IF(BE22="","",BE22*$F22) | BI22: =IF(BH22="","",BH22*$E22) | BJ22: =IF(BH22="","",BH22*$F22) | BL22: =IF(BK22="","",BK22*$E22) | BM22: =IF(BK22="","",BK22*$F22) | BO22: =IF(BN22="","",BN22*$E22) | BP22: =IF(BN22="","",BN22*$F22) | BR22: =IF(BQ22="","",BQ22*$E22) | BS22: =IF(BQ22="","",BQ22*$F22) | BU22: =IF(BT22="","",BT22*$E22) | BV22: =IF(BT22="","",BT22*$F22) | BX22: =IF(BW22="","",BW22*$E22) | BY22: =IF(BW22="","",BW22*$F22) | CA22: =IF(BZ22="","",BZ22*$E22) | CB22: =IF(BZ22="","",BZ22*$F22) | CD22: =IF(CC22="","",CC22*$E22) | CE22: =IF(CC22="","",CC22*$F22) | CG22: =IF(CF22="","",CF22*$E22) | CH22: =IF(CF22="","",CF22*$F22) | CI22: =IF(R22>0,P22,0) + IF(X22>0,V22,0) + IF(AD22>0,AB22,0) + IF(AJ22>0,AH22,0) + IF(AP22>0,AN22,0) + IF(AV22>0,AT22,0) + IF(BB22>0,AZ22,0) + IF(BH22>0,BF22,0) + IF(BN22>0,BL22,0) + IF(BT22>0,BR22,0) + IF(BZ22>0,BX22,0) + IF(CF22>0,CD22,0) -> 0 | CJ22: =IF(R22>0,Q22,0) + IF(X22>0,W22,0) + IF(AD22>0,AC22,0) + IF(AJ22>0,AI22,0) + IF(AP22>0,AO22,0) + IF(AV22>0,AU22,0) + IF(BB22>0,BA22,0) + IF(BH22>0,BG22,0) + IF(BN22>0,BM22,0) + IF(BT22>0,BS22,0) + IF(BZ22>0,BY22,0) + IF(CF22>0,CE22,0) -> 0
