Workbook

Sheet 全社
B1: 名称 | D1: 三幸プロダクツ株式会社 | I1: 46093
B3: 事 業 収 支 実 績 | E3: [ 全社] | J3: ※税込み | L3: 単位：千円
E5: 40期2月 | F5: 構成比 | G5: 41期2月 | H5: 構成比 | I5: 前年比 | J5: 40期累計 | K5: 構成比 | L5: 41期累計 | M5: 構成比 | N5: 前期比 | P5: 41期2月 | Q5: 予算比 | R5: 41期累計 | S5: 予算比
F6: ％ | H6: ％ | I6: ％ | K6: ％ | M6: ％ | N6: ％ | P6: 予算 | Q6: ％ | R6: 予算 | S6: ％ | T6: 実績合計：予算比（千円）
B7: 売上高 | E7: =東大阪工場!E7+松原工場!E7 -> 77847955 | F7: =E7/$E$10 -> 1 | G7: =東大阪工場!G7+松原工場!G7 -> 45531641 | H7: =G7/$G$10 -> 1 | I7: =IF(E7,G7/E7,"-") -> 0.58487909 | J7: =東大阪工場!J7+松原工場!J7 -> 895531534 | K7: =J7/$J$10 -> 0.93882537 | L7: =東大阪工場!L7+松原工場!L7 -> 471462768 | M7: =L7/$L$10 -> 1.0359292 | N7: =IF(J7,L7/J7,"-") -> 0.52646138 | P7: =東大阪工場!P7+松原工場!P7 -> 72895000 | Q7: =P7/$P$10 -> 1 | R7: =東大阪工場!R7+松原工場!R7 -> 634885000 | S7: =R7/$R$10 -> 1 | T7: =L7-R7 -> -163422232 | U7: =IF(L7,L7/R7,"-") -> 0.74259554
B8: 期首製品棚卸高 | E8: =東大阪工場!E8+松原工場!E8 -> 0 | F8: =E8/$E$10 -> 0 | G8: =[1]全社!C7 -> 0 | H8: =G8/$G$10 -> 0 | I8: =IF(E8,G8/E8,"-") -> - | J8: =東大阪工場!J8+松原工場!J8 -> 55532929 | L8: =東大阪工場!L8+松原工場!L8 -> 124406808 | N8: =IF(J8,L8/J8,"-") -> 2.2402349 | Q8: =P8/$P$10 -> 0 | R8: =P8 -> 0 | S8: =R8/$R$10 -> 0
B9: 期末製品棚卸高 | E9: =東大阪工場!E9+松原工場!E9 -> 0 | F9: =E9/$E$10 -> 0 | G9: =[1]全社!C8 -> 0 | H9: =G9/$G$10 -> 0 | I9: =IF(E9,G9/E9,"-") -> - | J9: =東大阪工場!J9+松原工場!J9 -> 113886498 | L9: =東大阪工場!L9+松原工場!L9 -> 108055026 | N9: =IF(J9,L9/J9,"-") -> 0.94879576 | Q9: =P9/$P$10 -> 0 | R9: =P9 -> 0 | S9: =R9/$R$10 -> 0
B10: 生産高 | E10: =E7-E8+E9 -> 77847955 | F10: =E10/$E$10 -> 1 | G10: =G7-G8+G9 -> 45531641 | H10: =G10/$G$10 -> 1 | I10: =IF(E10,G10/E10,"-") -> 0.58487909 | J10: =J7-J8+J9 -> 953885103 | K10: =J10/$J$10 -> 1 | L10: =L7-L8+L9 -> 455110986 | M10: =L10/$L$10 -> 1 | N10: =IF(J10,L10/J10,"-") -> 0.477113 | P10: =P7-P8+P9 -> 72895000 | Q10: =P10/$P$10 -> 1 | R10: =東大阪工場!R10+松原工場!R10 -> 634885000 | S10: =R10/$R$10 -> 1 | T10: =L10-R10 -> -179774014 | U10: =IF(L10,L10/R10,"-") -> 0.71684004
C11: 材料費 | D11: 期首材料棚卸高 | F11: =E11/$E$10 -> 0 | H11: =G11/$G$10 -> 0 | I11: =IF(E11,G11/E11,"-") -> - | J11: =東大阪工場!J11+松原工場!J11 -> 19328505 | L11: =東大阪工場!L11+松原工場!L11 -> 19224796 | N11: =IF(J11,L11/J11,"-") -> 0.9946344 | Q11: =P11/$P$10 -> 0 | R11: =P11 -> 0 | S11: =R11/$R$10 -> 0
D12: 材料仕入高（三幸商事他） | E12: =東大阪工場!E12+松原工場!E12 -> 40042630 | F12: =E12/$E$10 -> 0.51436971 | G12: =東大阪工場!G12+松原工場!G12 -> 19378635 | H12: =G12/$G$10 -> 0.4256081 | I12: =IF(E12,G12/E12,"-") -> 0.48395011 | J12: =東大阪工場!J12+松原工場!J12 -> 395010542 | K12: =J12/$J$10 -> 0.41410705 | L12: =東大阪工場!L12+松原工場!L12 -> 172034483 | M12: =L12/$L$10 -> 0.37800556 | N12: =IF(J12,L12/J12,"-") -> 0.43551871 | P12: =東大阪工場!P12+松原工場!P12 -> 0 | Q12: =P12/$P$10 -> 0 | R12: =東大阪工場!R12+松原工場!R12 -> 0 | S12: =R12/$R$10 -> 0
D13: 材料仕入高（ファイン技研） | E13: =東大阪工場!E13+松原工場!E13 -> 6069360 | F13: =E13/$E$10 -> 0.077964283 | G13: =東大阪工場!G13+松原工場!G13 -> 0 | H13: =G13/$G$10 -> 0 | I13: =IF(E13,G13/E13,"-") -> 0 | J13: =東大阪工場!J13+松原工場!J13 -> 137750845 | K13: =J13/$J$10 -> 0.14441031 | L13: =東大阪工場!L13+松原工場!L13 -> 0 | M13: =L13/$L$10 -> 0 | N13: =IF(J13,L13/J13,"-") -> 0 | P13: =東大阪工場!P13+松原工場!P13 -> 0 | Q13: =P13/$P$10 -> 0 | R13: =東大阪工場!R13+松原工場!R13 -> 0 | S13: =R13/$R$10 -> 0
D14: 材料仕入高計 | E14: =東大阪工場!E14+松原工場!E14 -> 46111990 | F14: =E14/$E$10 -> 0.59233399 | G14: =東大阪工場!G14+松原工場!G14 -> 19378635 | H14: =G14/$G$10 -> 0.4256081 | I14: =IF(E14,G14/E14,"-") -> 0.42025154 | J14: =東大阪工場!J14+松原工場!J14 -> 532761387 | K14: =J14/$J$10 -> 0.55851736 | L14: =東大阪工場!L14+松原工場!L14 -> 172034483 | M14: =L14/$L$10 -> 0.37800556 | N14: =IF(J14,L14/J14,"-") -> 0.32291095 | P14: =東大阪工場!P14+松原工場!P14 -> 35599350 | Q14: =P14/$P$10 -> 0.48836477 | R14: =東大阪工場!R14+松原工場!R14 -> 311774050 | S14: =R14/$R$10 -> 0.49107169 | T14: =L14-R14 -> -139739567 | U14: =IF(L14,L14/R14,"-") -> 0.55179218
D15: 期末材料棚卸高 | F15: =E15/$E$10 -> 0 | H15: =G15/$G$10 -> 0 | I15: =IF(E15,G15/E15,"-") -> - | J15: =東大阪工場!J15+松原工場!J15 -> 27227369 | L15: =東大阪工場!L15+松原工場!L15 -> 11725281 | N15: =IF(J15,L15/J15,"-") -> 0.43064319 | Q15: =P15/$P$10 -> 0 | R15: =P15 -> 0 | S15: =R15/$R$10 -> 0
D16: 材料費計 | E16: =E11+E14-E15 -> 46111990 | F16: =E16/$E$10 -> 0.59233399 | G16: =G11+G14-G15 -> 19378635 | H16: =G16/$G$10 -> 0.4256081 | I16: =IF(E16,G16/E16,"-") -> 0.42025154 | J16: =J11+J14-J15 -> 524862523 | K16: =J16/$J$10 -> 0.55023663 | L16: =L11+L14-L15 -> 179533998 | M16: =L16/$L$10 -> 0.39448399 | N16: =IF(J16,L16/J16,"-") -> 0.34205909 | P16: =P11+P14-P15 -> 35599350 | Q16: =P16/$P$10 -> 0.48836477 | R16: =R11+R14-R15 -> 311774050 | S16: =R16/$R$10 -> 0.49107169 | T16: =L16-R16 -> -132240052 | U16: =IF(L16,L16/R16,"-") -> 0.57584651
C17: 労務費 | D17: 給料手当 | E17: =東大阪工場!E17+松原工場!E17 -> 8414665 | F17: =E17/$E$10 -> 0.10809102 | G17: =東大阪工場!G17+松原工場!G17 -> 6361757 | H17: =G17/$G$10 -> 0.13972167 | I17: =IF(E17,G17/E17,"-") -> 0.75603212 | J17: =東大阪工場!J17+松原工場!J17 -> 73455869 | K17: =J17/$J$10 -> 0.077007041 | L17: =東大阪工場!L17+松原工場!L17 -> 63229017 | M17: =L17/$L$10 -> 0.13893098 | N17: =IF(J17,L17/J17,"-") -> 0.86077556 | P17: =東大阪工場!P17+松原工場!P17 -> 8115000 | Q17: =P17/$P$10 -> 0.11132451 | R17: =東大阪工場!R17+松原工場!R17 -> 73035000 | S17: =R17/$R$10 -> 0.11503658 | T17: =L17-R17 -> -9805983 | U17: =IF(L17,L17/R17,"-") -> 0.86573584
D18: 賞与 | E18: =東大阪工場!E18+松原工場!E18 -> 1230000 | F18: =E18/$E$10 -> 0.01580003 | G18: =東大阪工場!G18+松原工場!G18 -> 1580000 | H18: =G18/$G$10 -> 0.034701143 | I18: =IF(E18,G18/E18,"-") -> 1.2845528 | J18: =東大阪工場!J18+松原工場!J18 -> 11070000 | K18: =J18/$J$10 -> 0.011605171 | L18: =東大阪工場!L18+松原工場!L18 -> 14220000 | M18: =L18/$L$10 -> 0.031245126 | N18: =IF(J18,L18/J18,"-") -> 1.2845528 | P18: =東大阪工場!P18+松原工場!P18 -> 1580000 | Q18: =P18/$P$10 -> 0.021675012 | R18: =東大阪工場!R18+松原工場!R18 -> 14220000 | S18: =R18/$R$10 -> 0.022397757 | T18: =L18-R18 -> 0 | U18: =IF(L18,L18/R18,"-") -> 1
D19: 退職金 | E19: =東大阪工場!E19+松原工場!E19 -> 0 | F19: =E19/$E$10 -> 0 | G19: =東大阪工場!G19+松原工場!G19 -> 0 | H19: =G19/$G$10 -> 0 | I19: =IF(E19,G19/E19,"-") -> - | J19: =東大阪工場!J19+松原工場!J19 -> 0 | K19: =J19/$J$10 -> 0 | L19: =東大阪工場!L19+松原工場!L19 -> 0 | M19: =L19/$L$10 -> 0 | N19: =IF(J19,L19/J19,"-") -> - | P19: =東大阪工場!P19+松原工場!P19 -> 0 | Q19: =P19/$P$10 -> 0 | R19: =東大阪工場!R19+松原工場!R19 -> 0 | S19: =R19/$R$10 -> 0 | T19: =L19-R19 -> 0 | U19: =IF(L19,L19/R19,"-") -> -
D20: 法定福利費 | E20: =東大阪工場!E20+松原工場!E20 -> 1146113 | F20: =E20/$E$10 -> 0.014722455 | G20: =東大阪工場!G20+松原工場!G20 -> 986751 | H20: =G20/$G$10 -> 0.021671764 | I20: =IF(E20,G20/E20,"-") -> 0.86095437 | J20: =東大阪工場!J20+松原工場!J20 -> 12510610 | K20: =J20/$J$10 -> 0.013115427 | L20: =東大阪工場!L20+松原工場!L20 -> 13705601 | M20: =L20/$L$10 -> 0.030114854 | N20: =IF(J20,L20/J20,"-") -> 1.0955182 | P20: =東大阪工場!P20+松原工場!P20 -> 1140000 | Q20: =P20/$P$10 -> 0.015638933 | R20: =東大阪工場!R20+松原工場!R20 -> 13411000 | S20: =R20/$R$10 -> 0.021123511 | T20: =L20-R20 -> 294601 | U20: =IF(L20,L20/R20,"-") -> 1.0219671
D21: 福利厚生費 | E21: =東大阪工場!E21+松原工場!E21 -> 353238 | F21: =E21/$E$10 -> 0.0045375373 | G21: =東大阪工場!G21+松原工場!G21 -> 305103 | H21: =G21/$G$10 -> 0.0067009006 | I21: =IF(E21,G21/E21,"-") -> 0.8637321 | J21: =東大阪工場!J21+松原工場!J21 -> 3216299 | K21: =J21/$J$10 -> 0.0033717887 | L21: =東大阪工場!L21+松原工場!L21 -> 3106753 | M21: =L21/$L$10 -> 0.0068263634 | N21: =IF(J21,L21/J21,"-") -> 0.96594036 | P21: =東大阪工場!P21+松原工場!P21 -> 389500 | Q21: =P21/$P$10 -> 0.005343302 | R21: =東大阪工場!R21+松原工場!R21 -> 3420500 | S21: =R21/$R$10 -> 0.0053875899 | T21: =L21-R21 -> -313747 | U21: =IF(L21,L21/R21,"-") -> 0.90827452
D22: 出向負担金 | E22: =東大阪工場!E22+松原工場!E22 -> 1751633 | F22: =E22/$E$10 -> 0.022500694 | G22: =東大阪工場!G22+松原工場!G22 -> 1668400 | H22: =G22/$G$10 -> 0.03664265 | I22: =IF(E22,G22/E22,"-") -> 0.95248263 | J22: =東大阪工場!J22+松原工場!J22 -> 19912526 | K22: =J22/$J$10 -> 0.020875183 | L22: =東大阪工場!L22+松原工場!L22 -> 14992046 | M22: =L22/$L$10 -> 0.032941516 | N22: =IF(J22,L22/J22,"-") -> 0.75289524 | P22: =東大阪工場!P22+松原工場!P22 -> 1680000 | Q22: =P22/$P$10 -> 0.023046848 | R22: =東大阪工場!R22+松原工場!R22 -> 15120000 | S22: =R22/$R$10 -> 0.023815337 | T22: =L22-R22 -> -127954 | U22: =IF(L22,L22/R22,"-") -> 0.99153743
D23: 実習生管理費 | E23: =東大阪工場!E23+松原工場!E23 -> 21500 | F23: =E23/$E$10 -> 0.00027617938 | G23: =東大阪工場!G23+松原工場!G23 -> 21500 | H23: =G23/$G$10 -> 0.0004721991 | I23: =IF(E23,G23/E23,"-") -> 1 | J23: =東大阪工場!J23+松原工場!J23 -> 209000 | K23: =J23/$J$10 -> 0.00021910396 | L23: =東大阪工場!L23+松原工場!L23 -> 172000 | M23: =L23/$L$10 -> 0.00037792979 | N23: =IF(J23,L23/J23,"-") -> 0.82296651 | P23: =東大阪工場!P23+松原工場!P23 -> 65000 | Q23: =P23/$P$10 -> 0.00089169353 | R23: =東大阪工場!R23+松原工場!R23 -> 433000 | S23: =R23/$R$10 -> 0.00068201328 | T23: =L23-R23 -> -261000 | U23: =IF(L23,L23/R23,"-") -> 0.39722864
D24: 労務費計 | E24: =SUM(E17:E23) -> 12917149 | F24: =E24/$E$10 -> 0.16592792 | G24: =SUM(G17:G23) -> 10923511 | H24: =G24/$G$10 -> 0.23991033 | I24: =IF(E24,G24/E24,"-") -> 0.8456596 | J24: =SUM(J17:J23) -> 120374304 | K24: =J24/$J$10 -> 0.12619371 | L24: =SUM(L17:L23) -> 109425417 | M24: =L24/$L$10 -> 0.24043677 | N24: =IF(J24,L24/J24,"-") -> 0.90904299 | P24: =SUM(P17:P23) -> 12969500 | Q24: =P24/$P$10 -> 0.1779203 | R24: =SUM(R17:R23) -> 119639500 | S24: =R24/$R$10 -> 0.18844279 | T24: =L24-R24 -> -10214083 | U24: =IF(L24,L24/R24,"-") -> 0.91462616
C25: 製造経費 | D25: 人材派遣費 | E25: =東大阪工場!E25+松原工場!E25 -> 255066 | F25: =E25/$E$10 -> 0.0032764637 | G25: =東大阪工場!G25+松原工場!G25 -> 0 | H25: =G25/$G$10 -> 0 | I25: =IF(E25,G25/E25,"-") -> 0 | J25: =東大阪工場!J25+松原工場!J25 -> 2566703 | K25: =J25/$J$10 -> 0.0026907884 | L25: =東大阪工場!L25+松原工場!L25 -> 0 | M25: =L25/$L$10 -> 0 | N25: =IF(J25,L25/J25,"-") -> 0 | P25: =東大阪工場!P25+松原工場!P25 -> 0 | Q25: =P25/$P$10 -> 0 | R25: =東大阪工場!R25+松原工場!R25 -> 0 | S25: =R25/$R$10 -> 0 | T25: =L25-R25 -> 0 | U25: =IF(L25,L25/R25,"-") -> -
D26: 外注加工費 | E26: =東大阪工場!E26+松原工場!E26 -> 6336035 | F26: =E26/$E$10 -> 0.081389871 | G26: =東大阪工場!G26+松原工場!G26 -> 625065 | H26: =G26/$G$10 -> 0.013728146 | I26: =IF(E26,G26/E26,"-") -> 0.098652391 | J26: =東大阪工場!J26+松原工場!J26 -> 45087987 | K26: =J26/$J$10 -> 0.047267734 | L26: =東大阪工場!L26+松原工場!L26 -> 5635236 | M26: =L26/$L$10 -> 0.012382114 | N26: =IF(J26,L26/J26,"-") -> 0.12498309 | P26: =東大阪工場!P26+松原工場!P26 -> 540000 | Q26: =P26/$P$10 -> 0.0074079155 | R26: =東大阪工場!R26+松原工場!R26 -> 4320000 | S26: =R26/$R$10 -> 0.0068043819 | T26: =L26-R26 -> 1315236 | U26: =IF(L26,L26/R26,"-") -> 1.3044528
D27: 動力費 | E27: =東大阪工場!E27+松原工場!E27 -> 795120 | F27: =E27/$E$10 -> 0.010213756 | G27: =東大阪工場!G27+松原工場!G27 -> 520988 | H27: =G27/$G$10 -> 0.011442329 | I27: =IF(E27,G27/E27,"-") -> 0.65523191 | J27: =東大阪工場!J27+松原工場!J27 -> 7104315 | K27: =J27/$J$10 -> 0.0074477681 | L27: =東大阪工場!L27+松原工場!L27 -> 5514458 | M27: =L27/$L$10 -> 0.012116732 | N27: =IF(J27,L27/J27,"-") -> 0.77621248 | P27: =東大阪工場!P27+松原工場!P27 -> 880000 | Q27: =P27/$P$10 -> 0.012072159 | R27: =東大阪工場!R27+松原工場!R27 -> 7920000 | S27: =R27/$R$10 -> 0.0124747 | T27: =L27-R27 -> -2405542 | U27: =IF(L27,L27/R27,"-") -> 0.69626995
D28: 旅費交通費 | E28: =東大阪工場!E28+松原工場!E28 -> 327780 | F28: =E28/$E$10 -> 0.0042105152 | G28: =東大阪工場!G28+松原工場!G28 -> 271390 | H28: =G28/$G$10 -> 0.0059604704 | I28: =IF(E28,G28/E28,"-") -> 0.82796388 | J28: =東大阪工場!J28+松原工場!J28 -> 2755270 | K28: =J28/$J$10 -> 0.0028884716 | L28: =東大阪工場!L28+松原工場!L28 -> 2526920 | M28: =L28/$L$10 -> 0.005552316 | N28: =IF(J28,L28/J28,"-") -> 0.91712246 | P28: =東大阪工場!P28+松原工場!P28 -> 297000 | Q28: =P28/$P$10 -> 0.0040743535 | R28: =東大阪工場!R28+松原工場!R28 -> 2673000 | S28: =R28/$R$10 -> 0.0042102113 | T28: =L28-R28 -> -146080 | U28: =IF(L28,L28/R28,"-") -> 0.94534979
D29: 消耗品費 | E29: =東大阪工場!E29+松原工場!E29 -> 655222 | F29: =E29/$E$10 -> 0.0084166887 | G29: =東大阪工場!G29+松原工場!G29 -> 1441049 | H29: =G29/$G$10 -> 0.031649397 | I29: =IF(E29,G29/E29,"-") -> 2.1993294 | J29: =東大阪工場!J29+松原工場!J29 -> 12851096 | K29: =J29/$J$10 -> 0.013472373 | L29: =東大阪工場!L29+松原工場!L29 -> 10979797 | M29: =L29/$L$10 -> 0.024125537 | N29: =IF(J29,L29/J29,"-") -> 0.85438604 | P29: =東大阪工場!P29+松原工場!P29 -> 1230000 | Q29: =P29/$P$10 -> 0.016873585 | R29: =東大阪工場!R29+松原工場!R29 -> 9840000 | S29: =R29/$R$10 -> 0.01549887 | T29: =L29-R29 -> 1139797 | U29: =IF(L29,L29/R29,"-") -> 1.115833
D30: 修繕費 | E30: =東大阪工場!E30+松原工場!E30 -> 809919 | F30: =E30/$E$10 -> 0.010403857 | G30: =東大阪工場!G30+松原工場!G30 -> 166117 | H30: =G30/$G$10 -> 0.003648386 | I30: =IF(E30,G30/E30,"-") -> 0.20510323 | J30: =東大阪工場!J30+松原工場!J30 -> 11513601 | K30: =J30/$J$10 -> 0.012070218 | L30: =東大阪工場!L30+松原工場!L30 -> 2732857 | M30: =L30/$L$10 -> 0.0060048144 | N30: =IF(J30,L30/J30,"-") -> 0.23735902 | P30: =東大阪工場!P30+松原工場!P30 -> 870000 | Q30: =P30/$P$10 -> 0.011934975 | R30: =東大阪工場!R30+松原工場!R30 -> 6960000 | S30: =R30/$R$10 -> 0.010962615 | T30: =L30-R30 -> -4227143 | U30: =IF(L30,L30/R30,"-") -> 0.39265187
D31: 減価償却費 | E31: =東大阪工場!E31+松原工場!E31 -> 2680000 | F31: =E31/$E$10 -> 0.034426081 | G31: =東大阪工場!G31+松原工場!G31 -> 2470000 | H31: =G31/$G$10 -> 0.05424799 | I31: =IF(E31,G31/E31,"-") -> 0.92164179 | J31: =東大阪工場!J31+松原工場!J31 -> 24120000 | K31: =J31/$J$10 -> 0.025286064 | L31: =東大阪工場!L31+松原工場!L31 -> 22230000 | M31: =L31/$L$10 -> 0.048845228 | N31: =IF(J31,L31/J31,"-") -> 0.92164179 | P31: =東大阪工場!P31+松原工場!P31 -> 2470000 | Q31: =P31/$P$10 -> 0.033884354 | R31: =東大阪工場!R31+松原工場!R31 -> 22230000 | S31: =R31/$R$10 -> 0.035014215 | T31: =L31-R31 -> 0 | U31: =IF(L31,L31/R31,"-") -> 1
D32: 地代家賃 | E32: =東大阪工場!E32+松原工場!E32 -> 2150412 | F32: =E32/$E$10 -> 0.02762323 | G32: =東大阪工場!G32+松原工場!G32 -> 2150412 | H32: =G32/$G$10 -> 0.047228959 | I32: =IF(E32,G32/E32,"-") -> 1 | J32: =東大阪工場!J32+松原工場!J32 -> 19223708 | K32: =J32/$J$10 -> 0.020153064 | L32: =東大阪工場!L32+松原工場!L32 -> 19353708 | M32: =L32/$L$10 -> 0.042525249 | N32: =IF(J32,L32/J32,"-") -> 1.0067625 | P32: =東大阪工場!P32+松原工場!P32 -> 2165000 | Q32: =P32/$P$10 -> 0.029700254 | R32: =東大阪工場!R32+松原工場!R32 -> 19485000 | S32: =R32/$R$10 -> 0.030690598 | T32: =L32-R32 -> -131292 | U32: =IF(L32,L32/R32,"-") -> 0.99326189
D33: 賃借料 | E33: =東大阪工場!E33+松原工場!E33 -> 50325 | F33: =E33/$E$10 -> 0.00064645243 | G33: =東大阪工場!G33+松原工場!G33 -> 50325 | H33: =G33/$G$10 -> 0.0011052753 | I33: =IF(E33,G33/E33,"-") -> 1 | J33: =東大阪工場!J33+松原工場!J33 -> 401775 | K33: =J33/$J$10 -> 0.00042119853 | L33: =東大阪工場!L33+松原工場!L33 -> 401775 | M33: =L33/$L$10 -> 0.00088280664 | N33: =IF(J33,L33/J33,"-") -> 1 | P33: =東大阪工場!P33+松原工場!P33 -> 50000 | Q33: =P33/$P$10 -> 0.0006859181 | R33: =東大阪工場!R33+松原工場!R33 -> 450000 | S33: =R33/$R$10 -> 0.00070878978 | T33: =L33-R33 -> -48225 | U33: =IF(L33,L33/R33,"-") -> 0.89283333
D34: 保険料 | E34: =東大阪工場!E34+松原工場!E34 -> 68119 | F34: =E34/$E$10 -> 0.0008750262 | G34: =東大阪工場!G34+松原工場!G34 -> 34516 | H34: =G34/$G$10 -> 0.00075806624 | I34: =IF(E34,G34/E34,"-") -> 0.50670151 | J34: =東大阪工場!J34+松原工場!J34 -> 613071 | K34: =J34/$J$10 -> 0.00064270948 | L34: =東大阪工場!L34+松原工場!L34 -> 310644 | M34: =L34/$L$10 -> 0.00068256757 | N34: =IF(J34,L34/J34,"-") -> 0.50670151 | P34: =東大阪工場!P34+松原工場!P34 -> 66000 | Q34: =P34/$P$10 -> 0.00090541189 | R34: =東大阪工場!R34+松原工場!R34 -> 594000 | S34: =R34/$R$10 -> 0.00093560251 | T34: =L34-R34 -> -283356 | U34: =IF(L34,L34/R34,"-") -> 0.5229697
D35: 保守料 | E35: =東大阪工場!E35+松原工場!E35 -> 23833 | F35: =E35/$E$10 -> 0.00030614805 | G35: =東大阪工場!G35+松原工場!G35 -> 9933 | H35: =G35/$G$10 -> 0.00021815599 | I35: =IF(E35,G35/E35,"-") -> 0.41677506 | J35: =東大阪工場!J35+松原工場!J35 -> 163186 | K35: =J35/$J$10 -> 0.00017107511 | L35: =東大阪工場!L35+松原工場!L35 -> 572297 | M35: =L35/$L$10 -> 0.0012574889 | N35: =IF(J35,L35/J35,"-") -> 3.5070227 | P35: =東大阪工場!P35+松原工場!P35 -> 27000 | Q35: =P35/$P$10 -> 0.00037039577 | R35: =東大阪工場!R35+松原工場!R35 -> 243000 | S35: =R35/$R$10 -> 0.00038274648 | T35: =L35-R35 -> 329297 | U35: =IF(L35,L35/R35,"-") -> 2.3551317
D36: 少額資産減価償却費 | E36: =東大阪工場!E36+松原工場!E36 -> 440000 | F36: =E36/$E$10 -> 0.0056520431 | G36: =東大阪工場!G36+松原工場!G36 -> 0 | H36: =G36/$G$10 -> 0 | I36: =IF(E36,G36/E36,"-") -> 0 | J36: =東大阪工場!J36+松原工場!J36 -> 3909928 | K36: =J36/$J$10 -> 0.0040989507 | L36: =東大阪工場!L36+松原工場!L36 -> 462000 | M36: =L36/$L$10 -> 0.001015137 | N36: =IF(J36,L36/J36,"-") -> 0.11816074 | P36: =東大阪工場!P36+松原工場!P36 -> 400000 | Q36: =P36/$P$10 -> 0.0054873448 | R36: =東大阪工場!R36+松原工場!R36 -> 3600000 | S36: =R36/$R$10 -> 0.0056703182 | T36: =L36-R36 -> -3138000 | U36: =IF(L36,L36/R36,"-") -> 0.12833333
D37: 業務委託費 | E37: =東大阪工場!E37+松原工場!E37 -> 352000 | F37: =E37/$E$10 -> 0.0045216345 | G37: =東大阪工場!G37+松原工場!G37 -> 167000 | H37: =G37/$G$10 -> 0.0036677791 | I37: =IF(E37,G37/E37,"-") -> 0.47443182 | J37: =東大阪工場!J37+松原工場!J37 -> 2333000 | K37: =J37/$J$10 -> 0.0024457872 | L37: =東大阪工場!L37+松原工場!L37 -> 2428000 | M37: =L37/$L$10 -> 0.0053349624 | N37: =IF(J37,L37/J37,"-") -> 1.0407201 | P37: =東大阪工場!P37+松原工場!P37 -> 167000 | Q37: =P37/$P$10 -> 0.0022909665 | R37: =東大阪工場!R37+松原工場!R37 -> 2428000 | S37: =R37/$R$10 -> 0.0038243146 | T37: =L37-R37 -> 0 | U37: =IF(L37,L37/R37,"-") -> 1
... D39: 棚卸評価損 | E39: =東大阪工場!E39+松原工場!E39 -> 0 | F39: =E39/$E$10 -> 0 | G39: =東大阪工場!G39+松原工場!G39 -> 0 | H39: =G39/$G$10 -> 0 | I39: =IF(E39,G39/E39,"-") -> - | J39: =東大阪工場!J39+松原工場!J39 -> 0 | K39: =J39/$J$10 -> 0 | L39: =東大阪工場!L39+松原工場!L39 -> 0 | M39: =L39/$L$10 -> 0 | N39: =IF(J39,L39/J39,"-") -> - | P39: =東大阪工場!P39+松原工場!P39 -> 0 | Q39: =P39/$P$10 -> 0 | R39: =東大阪工場!R39+松原工場!R39 -> 0 | S39: =R39/$R$10 -> 0 | T39: =L39-R39 -> 0 | U39: =IF(L39,L39/R39,"-") -> -
D40: 製造経費計 | E40: =SUM(E25:E39) -> 14943831 | F40: =E40/$E$10 -> 0.19196177 | G40: =SUM(G25:G39) -> 7956845 | H40: =G40/$G$10 -> 0.17475419 | I40: =IF(E40,G40/E40,"-") -> 0.53245015 | J40: =SUM(J25:J39) -> 132643640 | K40: =J40/$J$10 -> 0.1390562 | L40: =SUM(L25:L39) -> 73598142 | M40: =L40/$L$10 -> 0.16171471 | N40: =IF(J40,L40/J40,"-") -> 0.55485617 | P40: =SUM(P25:P39) -> 9237000 | Q40: =P40/$P$10 -> 0.12671651 | R40: =SUM(R25:R39) -> 81418000 | S40: =R40/$R$10 -> 0.12824055 | T40: =L40-R40 -> -7819858 | U40: =IF(L40,L40/R40,"-") -> 0.90395419
B41: 総製造経費 | D41: 総製造経費計 | E41: =E16+E24+E40 -> 73972970 | F41: =E41/$E$10 -> 0.95022368 | G41: =G16+G24+G40 -> 38258991 | H41: =G41/$G$10 -> 0.84027261 | I41: =IF(E41,G41/E41,"-") -> 0.51720231 | J41: =J40+J24+J16 -> 777880467 | K41: =J41/$J$10 -> 0.81548655 | L41: =L16+L24+L40 -> 362557557 | M41: =L41/$L$10 -> 0.79663548 | N41: =IF(J41,L41/J41,"-") -> 0.46608389 | P41: =P40+P24+P16 -> 57805850 | Q41: =P41/$P$10 -> 0.79300158 | R41: =R40+R24+R16 -> 512831550 | S41: =R41/$R$10 -> 0.80775503 | T41: =L41-R41 -> -150273993 | U41: =IF(L41,L41/R41,"-") -> 0.70697202
B42: 売上総利益（粗利） | E42: =E10-E41 -> 3874985 | F42: =E42/$E$10 -> 0.049776324 | G42: =G10-G41 -> 7272650 | H42: =G42/$G$10 -> 0.15972739 | I42: =IF(E42,G42/E42,"-") -> 1.8768202 | J42: =J10-J41 -> 176004636 | K42: =J42/$J$10 -> 0.18451345 | L42: =L10-L41 -> 92553429 | M42: =L42/$L$10 -> 0.20336452 | N42: =IF(J42,L42/J42,"-") -> 0.5258579 | P42: =P10-P41 -> 15089150 | Q42: =P42/$P$10 -> 0.20699842 | R42: =R10-R41 -> 122053450 | S42: =R42/$R$10 -> 0.19224497 | T42: =L42-R42 -> -29500021 | U42: =IF(L42,L42/R42,"-") -> 0.75830244
B43: 販管費 | D43: 役員報酬 | E43: =東大阪工場!E43+松原工場!E43 -> 1571000 | F43: =E43/$E$10 -> 0.020180363 | G43: =東大阪工場!G43+松原工場!G43 -> 1271000 | H43: =G43/$G$10 -> 0.027914654 | I43: =IF(E43,G43/E43,"-") -> 0.80903883 | J43: =東大阪工場!J43+松原工場!J43 -> 14139000 | K43: =J43/$J$10 -> 0.01482254 | L43: =東大阪工場!L43+松原工場!L43 -> 11439000 | M43: =L43/$L$10 -> 0.025134528 | N43: =IF(J43,L43/J43,"-") -> 0.80903883 | P43: =東大阪工場!P43+松原工場!P43 -> 1271000 | Q43: =P43/$P$10 -> 0.017436038 | R43: =東大阪工場!R43+松原工場!R43 -> 11439000 | S43: =R43/$R$10 -> 0.018017436 | T43: =L43-R43 -> 0 | U43: =IF(L43,L43/R43,"-") -> 1
...

Sheet 東大阪工場
B1: 名称 | D1: 三幸プロダクツ株式会社 | I1: =全社!I1 -> 46093
B3: 事 業 収 支 実 績 | E3: [ 東大阪] | J3: ※税込み | L3: 単位：千円
E5: 40期2月 | F5: 構成比 | G5: 41期2月 | H5: 構成比 | I5: 前年比 | J5: 40期累計 | K5: 構成比 | L5: 41期累計 | M5: 構成比 | N5: 前期比 | P5: 41期2月 | Q5: 予算比 | R5: 41期累計 | S5: 予算比
F6: ％ | H6: ％ | I6: ％ | K6: ％ | M6: ％ | N6: ％ | P6: 予算 | Q6: ％ | R6: 予算 | S6: ％ | T6: 実績合計：予算比（千円）
B7: 売上高 | E7: =[2]東大阪工場!L5 -> 42614877 | F7: =E7/$E$10 -> 1 | G7: =[3]東大阪工場!L5 -> 26245909 | H7: =G7/$G$10 -> 1 | I7: =IF(E7,G7/E7,"-") -> 0.61588607 | J7: =E7+[4]東大阪工場!J7 -> 413806064 | K7: =J7/$J$10 -> 0.9905069 | L7: =G7+[4]東大阪工場!L7 -> 318922952 | M7: =L7/$L$10 -> 1.0009525 | N7: =IF(J7,L7/J7,"-") -> 0.77070633 | P7: =[5]東大阪工場!L5 -> 42545000 | Q7: =P7/$P$10 -> 1 | R7: =P7+[4]東大阪工場!R7 -> 387735000 | S7: =R7/$R$10 -> 1 | T7: =L7-R7 -> -68812048 | U7: =IF(L7,L7/R7,"-") -> 0.82252815
B8: 期首製品棚卸高 | F8: =E8/$E$10 -> 0 | H8: =G8/$G$10 -> 0 | I8: =IF(E8,G8/E8,"-") -> - | J8: 22108193 | L8: 28385258 | N8: =IF(J8,L8/J8,"-") -> 1.2839248 | Q8: =P8/$P$10 -> 0 | R8: =P8 -> 0 | S8: =R8/$R$10 -> 0 | T8: =L8-R8 -> 28385258 | U8: =IF(L8,L8/R8,"-") -> #DIV/0!
B9: 期末製品棚卸高 | F9: =E9/$E$10 -> 0 | H9: =G9/$G$10 -> 0 | I9: =IF(E9,G9/E9,"-") -> - | J9: 26074146 | L9: 28081787 | N9: =IF(J9,L9/J9,"-") -> 1.0769974 | Q9: =P9/$P$10 -> 0 | R9: =P9 -> 0 | S9: =R9/$R$10 -> 0 | T9: =L9-R9 -> 28081787 | U9: =IF(L9,L9/R9,"-") -> #DIV/0!
B10: 生産高 | E10: =E7-E8+E9 -> 42614877 | F10: =E10/$E$10 -> 1 | G10: =G7-G8+G9 -> 26245909 | H10: =G10/$G$10 -> 1 | I10: =IF(E10,G10/E10,"-") -> 0.61588607 | J10: =J7-J8+J9 -> 417772017 | K10: =J10/$J$10 -> 1 | L10: =L7-L8+L9 -> 318619481 | M10: =L10/$L$10 -> 1 | N10: =IF(J10,L10/J10,"-") -> 0.76266353 | P10: =P7-P8+P9 -> 42545000 | Q10: =P10/$P$10 -> 1 | R10: =R7-R8+R9 -> 387735000 | S10: =R10/$R$10 -> 1 | T10: =L10-R10 -> -69115519 | U10: =IF(L10,L10/R10,"-") -> 0.82174547
C11: 材料費 | D11: 期首材料棚卸高 | F11: =E11/$E$10 -> 0 | H11: =G11/$G$10 -> 0 | I11: =IF(E11,G11/E11,"-") -> - | J11: 10684923 | L11: 13953925 | N11: =IF(J11,L11/J11,"-") -> 1.3059453 | Q11: =P11/$P$10 -> 0 | R11: =P11+[4]東大阪工場!R11 -> 0 | S11: =R11/$R$10 -> 0 | T11: =L11-R11 -> 13953925 | U11: =IF(L11,L11/R11,"-") -> #DIV/0!
D12: 材料仕入高（三幸商事他） | E12: =[2]東大阪工場!L11 -> 21559478 | F12: =E12/$E$10 -> 0.50591435 | G12: =[3]東大阪工場!L11 -> 16271693 | H12: =G12/$G$10 -> 0.61997064 | I12: =IF(E12,G12/E12,"-") -> 0.75473502 | J12: =E12+[4]東大阪工場!J12 -> 218590123 | K12: =J12/$J$10 -> 0.52322825 | L12: =G12+[4]東大阪工場!L12 -> 151956202 | M12: =L12/$L$10 -> 0.47692062 | N12: =IF(J12,L12/J12,"-") -> 0.695165 | Q12: =P12/$P$10 -> 0 | R12: =P12+[4]東大阪工場!R12 -> 0 | S12: =R12/$R$10 -> 0
D13: 材料仕入高（ファイン技研） | E13: =[2]東大阪工場!L12 -> 1104400 | F13: =E13/$E$10 -> 0.025915832 | G13: =[3]東大阪工場!L12 -> 0 | H13: =G13/$G$10 -> 0 | I13: =IF(E13,G13/E13,"-") -> 0 | J13: =E13+[4]東大阪工場!J13 -> 9111300 | K13: =J13/$J$10 -> 0.021809263 | L13: =G13+[4]東大阪工場!L13 -> 0 | M13: =L13/$L$10 -> 0 | N13: =IF(J13,L13/J13,"-") -> 0 | Q13: =P13/$P$10 -> 0 | R13: =P13+[4]東大阪工場!R13 -> 0 | S13: =R13/$R$10 -> 0 | T13: =L13-R13 -> 0 | U13: =IF(L13,L13/R13,"-") -> -
D14: 材料仕入高計 | E14: =SUM(E12:E13) -> 22663878 | F14: =E14/$E$10 -> 0.53183019 | G14: =SUM(G12:G13) -> 16271693 | H14: =G14/$G$10 -> 0.61997064 | I14: =IF(E14,G14/E14,"-") -> 0.71795714 | J14: =SUM(J12:J13) -> 227701423 | K14: =J14/$J$10 -> 0.54503752 | L14: =SUM(L12:L13) -> 151956202 | M14: =L14/$L$10 -> 0.47692062 | N14: =IF(J14,L14/J14,"-") -> 0.6673485 | P14: =[5]東大阪工場!L11 -> 22548850 | Q14: =P14/$P$10 -> 0.53 | R14: =P14+[4]東大阪工場!R14 -> 205499550 | S14: =R14/$R$10 -> 0.53 | T14: =L14-R14 -> -53543348 | U14: =IF(L14,L14/R14,"-") -> 0.73944786
D15: 期末材料棚卸高 | F15: =E15/$E$10 -> 0 | H15: =G15/$G$10 -> 0 | I15: =IF(E15,G15/E15,"-") -> - | J15: 11480608 | L15: 7699484 | N15: =IF(J15,L15/J15,"-") -> 0.67065124 | Q15: =P15/$P$10 -> 0 | R15: =P15+[4]東大阪工場!R15 -> 0 | S15: =R15/$R$10 -> 0 | T15: =L15-R15 -> 7699484 | U15: =IF(L15,L15/R15,"-") -> #DIV/0!
D16: 材料費計 | E16: =E11+E14-E15 -> 22663878 | F16: =E16/$E$10 -> 0.53183019 | G16: =G11+G14-G15 -> 16271693 | H16: =G16/$G$10 -> 0.61997064 | I16: =IF(E16,G16/E16,"-") -> 0.71795714 | J16: =J11+J14-J15 -> 226905738 | K16: =J16/$J$10 -> 0.54313293 | L16: =L11+L14-L15 -> 158210643 | M16: =L16/$L$10 -> 0.49655044 | N16: =IF(J16,L16/J16,"-") -> 0.69725272 | P16: =P11+P14-P15 -> 22548850 | Q16: =P16/$P$10 -> 0.53 | R16: =R11+R14-R15 -> 205499550 | S16: =R16/$R$10 -> 0.53 | T16: =L16-R16 -> -47288907 | U16: =IF(L16,L16/R16,"-") -> 0.76988316
C17: 労務費 | D17: 給料手当 | E17: =[2]東大阪工場!L17 -> 3542843 | F17: =E17/$E$10 -> 0.083136295 | G17: =[3]東大阪工場!L17 -> 3411149 | H17: =G17/$G$10 -> 0.12996879 | I17: =IF(E17,G17/E17,"-") -> 0.96282816 | J17: =E17+[4]東大阪工場!J17 -> 34040332 | K17: =J17/$J$10 -> 0.081480642 | L17: =G17+[4]東大阪工場!L17 -> 32144580 | M17: =L17/$L$10 -> 0.10088705 | N17: =IF(J17,L17/J17,"-") -> 0.94430865 | P17: =[5]東大阪工場!L15 -> 3600000 | Q17: =P17/$P$10 -> 0.084616289 | R17: =P17+[4]東大阪工場!R17 -> 32400000 | S17: =R17/$R$10 -> 0.083562227 | T17: =L17-R17 -> -255420 | U17: =IF(L17,L17/R17,"-") -> 0.99211667
D18: 賞与 | E18: =[2]東大阪工場!L18 -> 830000 | F18: =E18/$E$10 -> 0.019476766 | G18: =[3]東大阪工場!L18 -> 950000 | H18: =G18/$G$10 -> 0.036196117 | I18: =IF(E18,G18/E18,"-") -> 1.1445783 | J18: =E18+[4]東大阪工場!J18 -> 7470000 | K18: =J18/$J$10 -> 0.017880566 | L18: =G18+[4]東大阪工場!L18 -> 8550000 | M18: =L18/$L$10 -> 0.026834517 | N18: =IF(J18,L18/J18,"-") -> 1.1445783 | P18: =[5]東大阪工場!L16 -> 950000 | Q18: =P18/$P$10 -> 0.022329298 | R18: =P18+[4]東大阪工場!R18 -> 8550000 | S18: =R18/$R$10 -> 0.022051143 | T18: =L18-R18 -> 0 | U18: =IF(L18,L18/R18,"-") -> 1
D19: 退職金 | E19: =[2]東大阪工場!L19 -> 0 | F19: =E19/$E$10 -> 0 | G19: =[3]東大阪工場!L19 -> 0 | H19: =G19/$G$10 -> 0 | I19: =IF(E19,G19/E19,"-") -> - | J19: =E19+[4]東大阪工場!J19 -> 0 | K19: =J19/$J$10 -> 0 | L19: =G19+[4]東大阪工場!L19 -> 0 | M19: =L19/$L$10 -> 0 | N19: =IF(J19,L19/J19,"-") -> - | P19: =[5]東大阪工場!L17 -> 0 | Q19: =P19/$P$10 -> 0 | R19: =P19+[4]東大阪工場!R19 -> 0 | S19: =R19/$R$10 -> 0 | T19: =L19-R19 -> 0 | U19: =IF(L19,L19/R19,"-") -> -
D20: 法定福利費 | E20: =[2]東大阪工場!L20 -> 540479 | F20: =E20/$E$10 -> 0.012682871 | G20: =[3]東大阪工場!L20 -> 567959 | H20: =G20/$G$10 -> 0.021639906 | I20: =IF(E20,G20/E20,"-") -> 1.0508438 | J20: =E20+[4]東大阪工場!J20 -> 6795470 | K20: =J20/$J$10 -> 0.016265977 | L20: =G20+[4]東大阪工場!L20 -> 7427975 | M20: =L20/$L$10 -> 0.023312997 | N20: =IF(J20,L20/J20,"-") -> 1.0930774 | P20: =[5]東大阪工場!L18 -> 585000 | Q20: =P20/$P$10 -> 0.013750147 | R20: =P20+[4]東大阪工場!R20 -> 6791000 | S20: =R20/$R$10 -> 0.01751454 | T20: =L20-R20 -> 636975 | U20: =IF(L20,L20/R20,"-") -> 1.0937969
D21: 福利厚生費 | E21: =[2]東大阪工場!L21 -> 173064 | F21: =E21/$E$10 -> 0.004061117 | G21: =[3]東大阪工場!L21 -> 185064 | H21: =G21/$G$10 -> 0.007051156 | I21: =IF(E21,G21/E21,"-") -> 1.0693385 | J21: =E21+[4]東大阪工場!J21 -> 1506957 | K21: =J21/$J$10 -> 0.0036071277 | L21: =G21+[4]東大阪工場!L21 -> 1631976 | M21: =L21/$L$10 -> 0.005122022 | N21: =IF(J21,L21/J21,"-") -> 1.0829612 | P21: =[5]東大阪工場!L19 -> 195000 | Q21: =P21/$P$10 -> 0.0045833823 | R21: =P21+[4]東大阪工場!R21 -> 1685000 | S21: =R21/$R$10 -> 0.0043457516 | T21: =L21-R21 -> -53024 | U21: =IF(L21,L21/R21,"-") -> 0.96853175
D22: 出向負担金 | E22: =[2]東大阪工場!L22 -> 1327783 | F22: =E22/$E$10 -> 0.031157734 | G22: =[3]東大阪工場!L22 -> 1331084 | H22: =G22/$G$10 -> 0.050715866 | I22: =IF(E22,G22/E22,"-") -> 1.0024861 | J22: =E22+[4]東大阪工場!J22 -> 13315843 | K22: =J22/$J$10 -> 0.031873468 | L22: =G22+[4]東大阪工場!L22 -> 11972621 | M22: =L22/$L$10 -> 0.03757655 | N22: =IF(J22,L22/J22,"-") -> 0.89912603 | P22: =[5]東大阪工場!L20 -> 1345000 | Q22: =P22/$P$10 -> 0.031613586 | R22: =P22+[4]東大阪工場!R22 -> 12105000 | S22: =R22/$R$10 -> 0.031219776 | T22: =L22-R22 -> -132379 | U22: =IF(L22,L22/R22,"-") -> 0.98906411
D23: 実習生管理費 | E23: =[2]東大阪工場!L23 -> 0 | F23: =E23/$E$10 -> 0 | G23: =[3]東大阪工場!L23 -> 0 | H23: =G23/$G$10 -> 0 | I23: =IF(E23,G23/E23,"-") -> - | J23: =E23+[4]東大阪工場!J23 -> 0 | K23: =J23/$J$10 -> 0 | L23: =G23+[4]東大阪工場!L23 -> 0 | M23: =L23/$L$10 -> 0 | N23: =IF(J23,L23/J23,"-") -> - | P23: =[5]東大阪工場!L21 -> 0 | Q23: =P23/$P$10 -> 0 | R23: =P23+[4]東大阪工場!R23 -> 0 | S23: =R23/$R$10 -> 0 | T23: =L23-R23 -> 0 | U23: =IF(L23,L23/R23,"-") -> -
D24: 労務費計 | E24: =SUM(E17:E23) -> 6414169 | F24: =E24/$E$10 -> 0.15051478 | G24: =SUM(G17:G23) -> 6445256 | H24: =G24/$G$10 -> 0.24557183 | I24: =IF(E24,G24/E24,"-") -> 1.0048466 | J24: =SUM(J17:J23) -> 63128602 | K24: =J24/$J$10 -> 0.15110778 | L24: =SUM(L17:L23) -> 61727152 | M24: =L24/$L$10 -> 0.19373314 | N24: =IF(J24,L24/J24,"-") -> 0.97780008 | P24: =SUM(P17:P23) -> 6675000 | Q24: =P24/$P$10 -> 0.1568927 | R24: =SUM(R17:R23) -> 61531000 | S24: =R24/$R$10 -> 0.15869344 | T24: =L24-R24 -> 196152 | U24: =IF(L24,L24/R24,"-") -> 1.0031879
C25: 製造経費 | D25: 人材派遣費 | E25: =[2]東大阪工場!L25 -> 0 | F25: =E25/$E$10 -> 0 | G25: =[3]東大阪工場!L25 -> 0 | H25: =G25/$G$10 -> 0 | I25: =IF(E25,G25/E25,"-") -> - | J25: =E25+[4]東大阪工場!J25 -> 231518 | K25: =J25/$J$10 -> 0.00055417307 | L25: =G25+[4]東大阪工場!L25 -> 0 | M25: =L25/$L$10 -> 0 | N25: =IF(J25,L25/J25,"-") -> 0 | P25: =[5]東大阪工場!L23 -> 0 | Q25: =P25/$P$10 -> 0 | R25: =P25+[4]東大阪工場!R25 -> 0 | S25: =R25/$R$10 -> 0 | T25: =L25-R25 -> 0 | U25: =IF(L25,L25/R25,"-") -> -
D26: 外注加工費 | E26: =[2]東大阪工場!L26 -> 0 | F26: =E26/$E$10 -> 0 | G26: =[3]東大阪工場!L26 -> 0 | H26: =G26/$G$10 -> 0 | I26: =IF(E26,G26/E26,"-") -> - | J26: =E26+[4]東大阪工場!J26 -> 381106 | K26: =J26/$J$10 -> 0.00091223439 | L26: =G26+[4]東大阪工場!L26 -> 437734 | M26: =L26/$L$10 -> 0.0013738457 | N26: =IF(J26,L26/J26,"-") -> 1.1485886 | P26: =[5]東大阪工場!L24 -> 40000 | Q26: =P26/$P$10 -> 0.00094018098 | R26: =P26+[4]東大阪工場!R26 -> 320000 | S26: =R26/$R$10 -> 0.00082530594 | T26: =L26-R26 -> 117734 | U26: =IF(L26,L26/R26,"-") -> 1.3679188
D27: 動力費 | E27: =[2]東大阪工場!L27 -> 219287 | F27: =E27/$E$10 -> 0.0051457851 | G27: =[3]東大阪工場!L27 -> 149590 | H27: =G27/$G$10 -> 0.0056995549 | I27: =IF(E27,G27/E27,"-") -> 0.68216538 | J27: =E27+[4]東大阪工場!J27 -> 2564982 | K27: =J27/$J$10 -> 0.0061396692 | L27: =G27+[4]東大阪工場!L27 -> 1881385 | M27: =L27/$L$10 -> 0.0059048022 | N27: =IF(J27,L27/J27,"-") -> 0.73348858 | P27: =[5]東大阪工場!L25 -> 280000 | Q27: =P27/$P$10 -> 0.0065812669 | R27: =P27+[4]東大阪工場!R27 -> 2520000 | S27: =R27/$R$10 -> 0.0064992843 | T27: =L27-R27 -> -638615 | U27: =IF(L27,L27/R27,"-") -> 0.74658135
D28: 旅費交通費 | E28: =[2]東大阪工場!L28 -> 192490 | F28: =E28/$E$10 -> 0.0045169672 | G28: =[3]東大阪工場!L28 -> 195490 | H28: =G28/$G$10 -> 0.0074483989 | I28: =IF(E28,G28/E28,"-") -> 1.0155852 | J28: =E28+[4]東大阪工場!J28 -> 1702490 | K28: =J28/$J$10 -> 0.0040751652 | L28: =G28+[4]東大阪工場!L28 -> 1724380 | M28: =L28/$L$10 -> 0.0054120357 | N28: =IF(J28,L28/J28,"-") -> 1.0128576 | P28: =[5]東大阪工場!L26 -> 177000 | Q28: =P28/$P$10 -> 0.0041603009 | R28: =P28+[4]東大阪工場!R28 -> 1593000 | S28: =R28/$R$10 -> 0.0041084761 | T28: =L28-R28 -> 131380 | U28: =IF(L28,L28/R28,"-") -> 1.0824733
D29: 消耗品費 | E29: =[2]東大阪工場!L29 -> 409031 | F29: =E29/$E$10 -> 0.0095983147 | G29: =[3]東大阪工場!L29 -> 288295 | H29: =G29/$G$10 -> 0.010984379 | I29: =IF(E29,G29/E29,"-") -> 0.70482433 | J29: =E29+[4]東大阪工場!J29 -> 3492148 | K29: =J29/$J$10 -> 0.0083589802 | L29: =G29+[4]東大阪工場!L29 -> 2595968 | M29: =L29/$L$10 -> 0.0081475495 | N29: =IF(J29,L29/J29,"-") -> 0.74337285 | P29: =[5]東大阪工場!L27 -> 380000 | Q29: =P29/$P$10 -> 0.0089317194 | R29: =P29+[4]東大阪工場!R29 -> 3040000 | S29: =R29/$R$10 -> 0.0078404065 | T29: =L29-R29 -> -444032 | U29: =IF(L29,L29/R29,"-") -> 0.85393684
D30: 修繕費 | E30: =[2]東大阪工場!L30 -> 38500 | F30: =E30/$E$10 -> 0.00090344036 | G30: =[3]東大阪工場!L30 -> 102317 | H30: =G30/$G$10 -> 0.003898398 | I30: =IF(E30,G30/E30,"-") -> 2.6575844 | J30: =E30+[4]東大阪工場!J30 -> 2281224 | K30: =J30/$J$10 -> 0.0054604519 | L30: =G30+[4]東大阪工場!L30 -> 415817 | M30: =L30/$L$10 -> 0.0013050583 | N30: =IF(J30,L30/J30,"-") -> 0.18227802 | P30: =[5]東大阪工場!L28 -> 270000 | Q30: =P30/$P$10 -> 0.0063462216 | R30: =P30+[4]東大阪工場!R30 -> 2160000 | S30: =R30/$R$10 -> 0.0055708151 | T30: =L30-R30 -> -1744183 | U30: =IF(L30,L30/R30,"-") -> 0.19250787
D31: 減価償却費 | E31: =[2]東大阪工場!L31 -> 530000 | F31: =E31/$E$10 -> 0.012436971 | G31: =[3]東大阪工場!L31 -> 270000 | H31: =G31/$G$10 -> 0.010287318 | I31: =IF(E31,G31/E31,"-") -> 0.50943396 | J31: =E31+[4]東大阪工場!J31 -> 4770000 | K31: =J31/$J$10 -> 0.011417711 | L31: =G31+[4]東大阪工場!L31 -> 2430000 | M31: =L31/$L$10 -> 0.0076266523 | N31: =IF(J31,L31/J31,"-") -> 0.50943396 | P31: =[5]東大阪工場!L29 -> 270000 | Q31: =P31/$P$10 -> 0.0063462216 | R31: =P31+[4]東大阪工場!R31 -> 2430000 | S31: =R31/$R$10 -> 0.006267167 | T31: =L31-R31 -> 0 | U31: =IF(L31,L31/R31,"-") -> 1
D32: 地代家賃 | E32: =[2]東大阪工場!L32 -> 990000 | F32: =E32/$E$10 -> 0.023231324 | G32: =[3]東大阪工場!L32 -> 990000 | H32: =G32/$G$10 -> 0.037720164 | I32: =IF(E32,G32/E32,"-") -> 1 | J32: =E32+[4]東大阪工場!J32 -> 8910000 | K32: =J32/$J$10 -> 0.021327422 | L32: =G32+[4]東大阪工場!L32 -> 8910000 | M32: =L32/$L$10 -> 0.027964392 | N32: =IF(J32,L32/J32,"-") -> 1 | P32: =[5]東大阪工場!L30 -> 990000 | Q32: =P32/$P$10 -> 0.023269479 | R32: =P32+[4]東大阪工場!R32 -> 8910000 | S32: =R32/$R$10 -> 0.022979612 | T32: =L32-R32 -> 0 | U32: =IF(L32,L32/R32,"-") -> 1
D33: 賃借料 | E33: =[2]東大阪工場!L33 -> 0 | F33: =E33/$E$10 -> 0 | G33: =[3]東大阪工場!L33 -> 0 | H33: =G33/$G$10 -> 0 | I33: =IF(E33,G33/E33,"-") -> - | J33: =E33+[4]東大阪工場!J33 -> 0 | K33: =J33/$J$10 -> 0 | L33: =G33+[4]東大阪工場!L33 -> 0 | M33: =L33/$L$10 -> 0 | N33: =IF(J33,L33/J33,"-") -> - | P33: =[5]東大阪工場!L31 -> 0 | Q33: =P33/$P$10 -> 0 | R33: =P33+[4]東大阪工場!R33 -> 0 | S33: =R33/$R$10 -> 0 | T33: =L33-R33 -> 0 | U33: =IF(L33,L33/R33,"-") -> -
D34: 保険料 | E34: =[2]東大阪工場!L34 -> 43044 | F34: =E34/$E$10 -> 0.0010100698 | G34: =[3]東大阪工場!L34 -> 20530 | H34: =G34/$G$10 -> 0.00078221714 | I34: =IF(E34,G34/E34,"-") -> 0.47695381 | J34: =E34+[4]東大阪工場!J34 -> 387396 | K34: =J34/$J$10 -> 0.00092729045 | L34: =G34+[4]東大阪工場!L34 -> 184770 | M34: =L34/$L$10 -> 0.00057990804 | N34: =IF(J34,L34/J34,"-") -> 0.47695381 | P34: =[5]東大阪工場!L32 -> 44000 | Q34: =P34/$P$10 -> 0.0010341991 | R34: =P34+[4]東大阪工場!R34 -> 396000 | S34: =R34/$R$10 -> 0.0010213161 | T34: =L34-R34 -> -211230 | U34: =IF(L34,L34/R34,"-") -> 0.46659091
D35: 保守料 | E35: =[2]東大阪工場!L35 -> 16500 | F35: =E35/$E$10 -> 0.00038718873 | G35: =[3]東大阪工場!L35 -> 0 | H35: =G35/$G$10 -> 0 | I35: =IF(E35,G35/E35,"-") -> 0 | J35: =E35+[4]東大阪工場!J35 -> 148500 | K35: =J35/$J$10 -> 0.00035545703 | L35: =G35+[4]東大阪工場!L35 -> 324500 | M35: =L35/$L$10 -> 0.0010184562 | N35: =IF(J35,L35/J35,"-") -> 2.1851852 | P35: =[5]東大阪工場!L33 -> 17000 | Q35: =P35/$P$10 -> 0.00039957692 | R35: =P35+[4]東大阪工場!R35 -> 153000 | S35: =R35/$R$10 -> 0.0003945994 | T35: =L35-R35 -> 171500 | U35: =IF(L35,L35/R35,"-") -> 2.120915
D36: 少額資産減価償却費 | E36: =[2]東大阪工場!L36 -> 0 | F36: =E36/$E$10 -> 0 | G36: =[3]東大阪工場!L36 -> 0 | H36: =G36/$G$10 -> 0 | I36: =IF(E36,G36/E36,"-") -> - | J36: =E36+[4]東大阪工場!J36 -> 773300 | K36: =J36/$J$10 -> 0.0018510096 | L36: =G36+[4]東大阪工場!L36 -> 198000 | M36: =L36/$L$10 -> 0.00062143093 | N36: =IF(J36,L36/J36,"-") -> 0.25604552 | P36: =[5]東大阪工場!L34 -> 100000 | Q36: =P36/$P$10 -> 0.0023504525 | R36: =P36+[4]東大阪工場!R36 -> 900000 | S36: =R36/$R$10 -> 0.002321173 | T36: =L36-R36 -> -702000 | U36: =IF(L36,L36/R36,"-") -> 0.22
D37: 業務委託費 | E37: =[2]東大阪工場!L37 -> 0 | F37: =E37/$E$10 -> 0 | G37: =[3]東大阪工場!L37 -> 0 | H37: =G37/$G$10 -> 0 | I37: =IF(E37,G37/E37,"-") -> - | J37: =E37+[4]東大阪工場!J37 -> 0 | K37: =J37/$J$10 -> 0 | L37: =G37+[4]東大阪工場!L37 -> 0 | M37: =L37/$L$10 -> 0 | N37: =IF(J37,L37/J37,"-") -> - | P37: =[5]東大阪工場!L35 -> 0 | Q37: =P37/$P$10 -> 0 | R37: =P37+[4]東大阪工場!R37 -> 0 | S37: =R37/$R$10 -> 0 | T37: =L37-R37 -> 0 | U37: =IF(L37,L37/R37,"-") -> -
... D39: 棚卸評価損 | E39: =[2]東大阪工場!L39 -> 0 | F39: =E39/$E$10 -> 0 | G39: =[3]東大阪工場!L39 -> 0 | H39: =G39/$G$10 -> 0 | I39: =IF(E39,G39/E39,"-") -> - | J39: =E39+[4]東大阪工場!J39 -> 0 | K39: =J39/$J$10 -> 0 | L39: =G39+[4]東大阪工場!L39 -> 0 | M39: =L39/$L$10 -> 0 | N39: =IF(J39,L39/J39,"-") -> - | P39: =[5]東大阪工場!L37 -> 0 | Q39: =P39/$P$10 -> 0 | R39: =P39+[4]東大阪工場!R39 -> 0 | S39: =R39/$R$10 -> 0 | T39: =L39-R39 -> 0 | U39: =IF(L39,L39/R39,"-") -> -
D40: 製造経費計 | E40: =SUM(E25:E39) -> 2438852 | F40: =E40/$E$10 -> 0.057230061 | G40: =SUM(G25:G39) -> 2066272 | H40: =G40/$G$10 -> 0.078727393 | I40: =IF(E40,G40/E40,"-") -> 0.8472314 | J40: =SUM(J25:J39) -> 25642664 | K40: =J40/$J$10 -> 0.061379563 | L40: =SUM(L25:L39) -> 19553004 | M40: =L40/$L$10 -> 0.061367886 | N40: =IF(J40,L40/J40,"-") -> 0.76251843 | P40: =SUM(P25:P39) -> 2618000 | Q40: =P40/$P$10 -> 0.061534845 | R40: =SUM(R25:R39) -> 22872000 | S40: =R40/$R$10 -> 0.058988742 | T40: =L40-R40 -> -3318996 | U40: =IF(L40,L40/R40,"-") -> 0.85488825
B41: 総製造経費 | D41: 総製造経費計 | E41: =E16+E24+E40 -> 31516899 | F41: =E41/$E$10 -> 0.73957503 | G41: =G16+G24+G40 -> 24783221 | H41: =G41/$G$10 -> 0.94426987 | I41: =IF(E41,G41/E41,"-") -> 0.78634706 | J41: =J40+J24+J16 -> 315677004 | K41: =J41/$J$10 -> 0.75562027 | L41: =L16+L24+L40 -> 239490799 | M41: =L41/$L$10 -> 0.75165146 | N41: =IF(J41,L41/J41,"-") -> 0.75865773 | P41: =P40+P24+P16 -> 31841850 | Q41: =P41/$P$10 -> 0.74842755 | R41: =R40+R24+R16 -> 289902550 | S41: =R41/$R$10 -> 0.74768218 | T41: =L41-R41 -> -50411751 | U41: =IF(L41,L41/R41,"-") -> 0.82610794
B42: 売上総利益（粗利） | E42: =E10-E41 -> 11097978 | F42: =E42/$E$10 -> 0.26042497 | G42: =G10-G41 -> 1462688 | H42: =G42/$G$10 -> 0.055730133 | I42: =IF(E42,G42/E42,"-") -> 0.1317977 | J42: =J10-J41 -> 102095013 | K42: =J42/$J$10 -> 0.24437973 | L42: =L10-L41 -> 79128682 | M42: =L42/$L$10 -> 0.24834854 | N42: =IF(J42,L42/J42,"-") -> 0.77504943 | P42: =P10-P41 -> 10703150 | Q42: =P42/$P$10 -> 0.25157245 | R42: =R10-R41 -> 97832450 | S42: =R42/$R$10 -> 0.25231782 | T42: =L42-R42 -> -18703768 | U42: =IF(L42,L42/R42,"-") -> 0.80881836
B43: 販管費 | D43: 役員報酬 | E43: =[2]東大阪工場!L45 -> 1421000 | F43: =E43/$E$10 -> 0.033345163 | G43: =[3]東大阪工場!L45 -> 1271000 | H43: =G43/$G$10 -> 0.048426595 | I43: =IF(E43,G43/E43,"-") -> 0.89444053 | J43: =E43+[4]東大阪工場!J43 -> 12789000 | K43: =J43/$J$10 -> 0.03061239 | L43: =G43+[4]東大阪工場!L43 -> 11439000 | M43: =L43/$L$10 -> 0.03590176 | N43: =IF(J43,L43/J43,"-") -> 0.89444053 | P43: =[5]東大阪工場!L43 -> 1271000 | Q43: =P43/$P$10 -> 0.029874251 | R43: =P43+[4]東大阪工場!R43 -> 11439000 | S43: =R43/$R$10 -> 0.029502108 | T43: =L43-R43 -> 0 | U43: =IF(L43,L43/R43,"-") -> 1
...

Sheet 松原工場
B1: 名称 | D1: 三幸プロダクツ株式会社 | I1: =全社!I1 -> 46093
B3: 事 業 収 支 実 績 | E3: [松原] | J3: ※税込み | L3: 単位：千円
E5: 40期2月 | F5: 構成比 | G5: 41期2月 | H5: 構成比 | I5: 前年比 | J5: 40期累計 | K5: 構成比 | L5: 41期累計 | M5: 構成比 | N5: 前期比 | P5: 41期2月 | Q5: 予算比 | R5: 41期累計 | S5: 予算比
F6: ％ | H6: ％ | I6: ％ | K6: ％ | M6: ％ | N6: ％ | P6: 予算 | Q6: ％ | R6: 予算 | S6: ％ | T6: 実績合計：予算比（千円）
B7: 売上高 | E7: =[2]松原工場!L5 -> 35233078 | F7: =E7/$E$10 -> 1 | G7: =[3]松原工場!L5 -> 19285732 | H7: =G7/$G$10 -> 1 | I7: =IF(E7,G7/E7,"-") -> 0.54737574 | J7: =E7+[4]松原工場!J7 -> 481725470 | K7: =J7/$J$10 -> 0.89855197 | L7: =G7+[4]松原工場!L7 -> 152539816 | M7: =L7/$L$10 -> 1.1175774 | N7: =IF(J7,L7/J7,"-") -> 0.316653 | P7: =[5]松原工場!L5 -> 30350000 | Q7: =P7/$P$10 -> 1 | R7: =P7+[4]松原工場!R7 -> 247150000 | S7: =R7/$R$10 -> 1 | T7: =L7-R7 -> -94610184 | U7: =IF(L7,L7/R7,"-") -> 0.61719529
B8: 期首製品棚卸高 | F8: =E8/$E$10 -> 0 | H8: =G8/$G$10 -> 0 | I8: =IF(E8,G8/E8,"-") -> - | J8: 33424736 | L8: 96021550 | N8: =IF(J8,L8/J8,"-") -> 2.8727691 | Q8: =P8/$P$10 -> 0 | R8: =P8 -> 0 | S8: =R8/$R$10 -> 0 | T8: =L8-R8 -> 96021550 | U8: =IF(L8,L8/R8,"-") -> #DIV/0!
B9: 期末製品棚卸高 | F9: =E9/$E$10 -> 0 | H9: =G9/$G$10 -> 0 | I9: =IF(E9,G9/E9,"-") -> - | J9: 87812352 | L9: 79973239 | N9: =IF(J9,L9/J9,"-") -> 0.91072881 | Q9: =P9/$P$10 -> 0 | R9: =P9 -> 0 | S9: =R9/$R$10 -> 0 | T9: =L9-R9 -> 79973239 | U9: =IF(L9,L9/R9,"-") -> #DIV/0!
B10: 生産高 | E10: =E7-E8+E9 -> 35233078 | F10: =E10/$E$10 -> 1 | G10: =G7-G8+G9 -> 19285732 | H10: =G10/$G$10 -> 1 | I10: =IF(E10,G10/E10,"-") -> 0.54737574 | J10: =J7-J8+J9 -> 536113086 | K10: =J10/$J$10 -> 1 | L10: =L7-L8+L9 -> 136491505 | M10: =L10/$L$10 -> 1 | N10: =IF(J10,L10/J10,"-") -> 0.25459462 | P10: =P7-P8+P9 -> 30350000 | Q10: =P10/$P$10 -> 1 | R10: =R7-R8+R9 -> 247150000 | S10: =R10/$R$10 -> 1 | T10: =L10-R10 -> -110658495 | U10: =IF(L10,L10/R10,"-") -> 0.5522618
C11: 材料費 | D11: 期首材料棚卸高 | F11: =E11/$E$10 -> 0 | H11: =G11/$G$10 -> 0 | I11: =IF(E11,G11/E11,"-") -> - | J11: 8643582 | L11: 5270871 | N11: =IF(J11,L11/J11,"-") -> 0.6098017 | Q11: =P11/$P$10 -> 0 | R11: =P11+[4]松原工場!R11 -> 0 | S11: =R11/$R$10 -> 0 | T11: =L11-R11 -> 5270871 | U11: =IF(L11,L11/R11,"-") -> #DIV/0!
D12: 材料仕入高（三幸商事他） | E12: =[2]松原工場!L11 -> 18483152 | G12: =[3]松原工場!L11 -> 3106942 | H12: =G12/$G$10 -> 0.16110055 | J12: =E12+[4]松原工場!J12 -> 176420419 | L12: =G12+[4]松原工場!L12 -> 20078281 | R12: =P12+[4]松原工場!R12 -> 0
D13: 材料仕入高（ファイン技研） | E13: =[2]松原工場!L12 -> 4964960 | G13: =[3]松原工場!L12 -> 0 | H13: =G13/$G$10 -> 0 | J13: =E13+[4]松原工場!J13 -> 128639545 | L13: =G13+[4]松原工場!L13 -> 0 | R13: =P13+[4]松原工場!R13 -> 0 | U13: =IF(L13,L13/R13,"-") -> -
D14: 材料仕入高計 | E14: =SUM(E12:E13) -> 23448112 | F14: =E14/$E$10 -> 0.66551415 | G14: =SUM(G12:G13) -> 3106942 | H14: =G14/$G$10 -> 0.16110055 | I14: =IF(E14,G14/E14,"-") -> 0.13250286 | J14: =SUM(J12:J13) -> 305059964 | K14: =J14/$J$10 -> 0.56902167 | L14: =SUM(L12:L13) -> 20078281 | M14: =L14/$L$10 -> 0.14710279 | N14: =IF(J14,L14/J14,"-") -> 0.06581749 | P14: =[5]松原工場!L11 -> 13050500 | Q14: =P14/$P$10 -> 0.43 | R14: =P14+[4]松原工場!R14 -> 106274500 | S14: =R14/$R$10 -> 0.43 | T14: =L14-R14 -> -86196219 | U14: =IF(L14,L14/R14,"-") -> 0.18892849
D15: 期末材料棚卸高 | F15: =E15/$E$10 -> 0 | H15: =G15/$G$10 -> 0 | I15: =IF(E15,G15/E15,"-") -> - | J15: 15746761 | L15: 4025797 | N15: =IF(J15,L15/J15,"-") -> 0.25565874 | Q15: =P15/$P$10 -> 0 | R15: =P15+[4]松原工場!R15 -> 0 | S15: =R15/$R$10 -> 0 | T15: =L15-R15 -> 4025797 | U15: =IF(L15,L15/R15,"-") -> #DIV/0!
D16: 材料費計 | E16: =E11+E14-E15 -> 23448112 | F16: =E16/$E$10 -> 0.66551415 | G16: =G11+G14-G15 -> 3106942 | H16: =G16/$G$10 -> 0.16110055 | I16: =IF(E16,G16/E16,"-") -> 0.13250286 | J16: =J11+J14-J15 -> 297956785 | K16: =J16/$J$10 -> 0.55577227 | L16: =L11+L14-L15 -> 21323355 | M16: =L16/$L$10 -> 0.15622478 | N16: =IF(J16,L16/J16,"-") -> 0.071565261 | P16: =P11+P14-P15 -> 13050500 | Q16: =P16/$P$10 -> 0.43 | R16: =R11+R14-R15 -> 106274500 | S16: =R16/$R$10 -> 0.43 | T16: =L16-R16 -> -84951145 | U16: =IF(L16,L16/R16,"-") -> 0.20064413
C17: 労務費 | D17: 給料手当 | E17: =[2]松原工場!L17 -> 4871822 | F17: =E17/$E$10 -> 0.1382741 | G17: =[3]松原工場!L17 -> 2950608 | H17: =G17/$G$10 -> 0.15299435 | I17: =IF(E17,G17/E17,"-") -> 0.60564774 | J17: =E17+[4]松原工場!J17 -> 39415537 | K17: =J17/$J$10 -> 0.073520938 | L17: =G17+[4]松原工場!L17 -> 31084437 | M17: =L17/$L$10 -> 0.22773899 | N17: =IF(J17,L17/J17,"-") -> 0.78863411 | P17: =[5]松原工場!L15 -> 4515000 | Q17: =P17/$P$10 -> 0.14876442 | R17: =P17+[4]松原工場!R17 -> 40635000 | S17: =R17/$R$10 -> 0.16441432 | T17: =L17-R17 -> -9550563 | U17: =IF(L17,L17/R17,"-") -> 0.76496707
D18: 賞与 | E18: =[2]松原工場!L18 -> 400000 | F18: =E18/$E$10 -> 0.011352968 | G18: =[3]松原工場!L18 -> 630000 | H18: =G18/$G$10 -> 0.032666637 | I18: =IF(E18,G18/E18,"-") -> 1.575 | J18: =E18+[4]松原工場!J18 -> 3600000 | K18: =J18/$J$10 -> 0.0067150012 | L18: =G18+[4]松原工場!L18 -> 5670000 | M18: =L18/$L$10 -> 0.041541047 | N18: =IF(J18,L18/J18,"-") -> 1.575 | P18: =[5]松原工場!L16 -> 630000 | Q18: =P18/$P$10 -> 0.020757825 | R18: =P18+[4]松原工場!R18 -> 5670000 | S18: =R18/$R$10 -> 0.022941533 | T18: =L18-R18 -> 0 | U18: =IF(L18,L18/R18,"-") -> 1
D19: 退職金 | E19: =[2]松原工場!L19 -> 0 | F19: =E19/$E$10 -> 0 | G19: =[3]松原工場!L19 -> 0 | H19: =G19/$G$10 -> 0 | I19: =IF(E19,G19/E19,"-") -> - | J19: =E19+[4]松原工場!J19 -> 0 | K19: =J19/$J$10 -> 0 | L19: =G19+[4]松原工場!L19 -> 0 | M19: =L19/$L$10 -> 0 | N19: =IF(J19,L19/J19,"-") -> - | P19: =[5]松原工場!L17 -> 0 | Q19: =P19/$P$10 -> 0 | R19: =P19+[4]松原工場!R19 -> 0 | S19: =R19/$R$10 -> 0 | T19: =L19-R19 -> 0 | U19: =IF(L19,L19/R19,"-") -> -
D20: 法定福利費 | E20: =[2]松原工場!L20 -> 605634 | F20: =E20/$E$10 -> 0.017189358 | G20: =[3]松原工場!L20 -> 418792 | H20: =G20/$G$10 -> 0.021715121 | I20: =IF(E20,G20/E20,"-") -> 0.69149354 | J20: =E20+[4]松原工場!J20 -> 5715140 | K20: =J20/$J$10 -> 0.010660325 | L20: =G20+[4]松原工場!L20 -> 6277626 | M20: =L20/$L$10 -> 0.045992796 | N20: =IF(J20,L20/J20,"-") -> 1.0984203 | P20: =[5]松原工場!L18 -> 555000 | Q20: =P20/$P$10 -> 0.018286656 | R20: =P20+[4]松原工場!R20 -> 6620000 | S20: =R20/$R$10 -> 0.026785353 | T20: =L20-R20 -> -342374 | U20: =IF(L20,L20/R20,"-") -> 0.94828187
D21: 福利厚生費 | E21: =[2]松原工場!L21 -> 180174 | F21: =E21/$E$10 -> 0.0051137741 | G21: =[3]松原工場!L21 -> 120039 | H21: =G21/$G$10 -> 0.0062242387 | I21: =IF(E21,G21/E21,"-") -> 0.6662393 | J21: =E21+[4]松原工場!J21 -> 1709342 | K21: =J21/$J$10 -> 0.0031883982 | L21: =G21+[4]松原工場!L21 -> 1474777 | M21: =L21/$L$10 -> 0.0108049 | N21: =IF(J21,L21/J21,"-") -> 0.86277468 | P21: =[5]松原工場!L19 -> 194500 | Q21: =P21/$P$10 -> 0.0064085667 | R21: =P21+[4]松原工場!R21 -> 1735500 | S21: =R21/$R$10 -> 0.0070220514 | T21: =L21-R21 -> -260723 | U21: =IF(L21,L21/R21,"-") -> 0.84977067
D22: 出向負担金 | E22: =[2]松原工場!L22 -> 423850 | F22: =E22/$E$10 -> 0.012029889 | G22: =[3]松原工場!L22 -> 337316 | H22: =G22/$G$10 -> 0.017490443 | I22: =IF(E22,G22/E22,"-") -> 0.79583815 | J22: =E22+[4]松原工場!J22 -> 6596683 | K22: =J22/$J$10 -> 0.012304648 | L22: =G22+[4]松原工場!L22 -> 3019425 | M22: =L22/$L$10 -> 0.022121706 | N22: =IF(J22,L22/J22,"-") -> 0.45771867 | P22: =[5]松原工場!L20 -> 335000 | Q22: =P22/$P$10 -> 0.011037891 | R22: =P22+[4]松原工場!R22 -> 3015000 | S22: =R22/$R$10 -> 0.012199069 | T22: =L22-R22 -> 4425 | U22: =IF(L22,L22/R22,"-") -> 1.0014677
D23: 実習生管理費 | E23: =[2]松原工場!L23 -> 21500 | F23: =E23/$E$10 -> 0.00061022202 | G23: =[3]松原工場!L23 -> 21500 | H23: =G23/$G$10 -> 0.0011148138 | I23: =IF(E23,G23/E23,"-") -> 1 | J23: =E23+[4]松原工場!J23 -> 209000 | K23: =J23/$J$10 -> 0.00038984312 | L23: =G23+[4]松原工場!L23 -> 172000 | M23: =L23/$L$10 -> 0.0012601517 | N23: =IF(J23,L23/J23,"-") -> 0.82296651 | P23: =[5]松原工場!L21 -> 65000 | Q23: =P23/$P$10 -> 0.0021416804 | R23: =P23+[4]松原工場!R23 -> 433000 | S23: =R23/$R$10 -> 0.0017519725 | T23: =L23-R23 -> -261000 | U23: =IF(L23,L23/R23,"-") -> 0.39722864
D24: 労務費計 | E24: =SUM(E17:E23) -> 6502980 | F24: =E24/$E$10 -> 0.18457031 | G24: =SUM(G17:G23) -> 4478255 | H24: =G24/$G$10 -> 0.2322056 | I24: =IF(E24,G24/E24,"-") -> 0.68864659 | J24: =SUM(J17:J23) -> 57245702 | K24: =J24/$J$10 -> 0.10677915 | L24: =SUM(L17:L23) -> 47698265 | M24: =L24/$L$10 -> 0.34945959 | N24: =IF(J24,L24/J24,"-") -> 0.83322002 | P24: =SUM(P17:P23) -> 6294500 | Q24: =P24/$P$10 -> 0.20739703 | R24: =SUM(R17:R23) -> 58108500 | S24: =R24/$R$10 -> 0.2351143 | T24: =L24-R24 -> -10410235 | U24: =IF(L24,L24/R24,"-") -> 0.82084833
C25: 製造経費 | D25: 人材派遣費 | E25: =[2]松原工場!L25 -> 255066 | F25: =E25/$E$10 -> 0.0072393902 | G25: =[3]松原工場!L25 -> 0 | H25: =G25/$G$10 -> 0 | I25: =IF(E25,G25/E25,"-") -> 0 | J25: =E25+[4]松原工場!J25 -> 2335185 | K25: =J25/$J$10 -> 0.0043557694 | L25: =G25+[4]松原工場!L25 -> 0 | M25: =L25/$L$10 -> 0 | N25: =IF(J25,L25/J25,"-") -> 0 | P25: =[5]松原工場!L23 -> 0 | Q25: =P25/$P$10 -> 0 | R25: =P25+[4]松原工場!R25 -> 0 | S25: =R25/$R$10 -> 0 | T25: =L25-R25 -> 0 | U25: =IF(L25,L25/R25,"-") -> -
D26: 外注加工費 | E26: =[2]松原工場!L26 -> 6336035 | F26: =E26/$E$10 -> 0.179832 | G26: =[3]松原工場!L26 -> 625065 | H26: =G26/$G$10 -> 0.032410748 | I26: =IF(E26,G26/E26,"-") -> 0.098652391 | J26: =E26+[4]松原工場!J26 -> 44706881 | K26: =J26/$J$10 -> 0.083390766 | L26: =G26+[4]松原工場!L26 -> 5197502 | M26: =L26/$L$10 -> 0.038079308 | N26: =IF(J26,L26/J26,"-") -> 0.11625732 | P26: =[5]松原工場!L24 -> 500000 | Q26: =P26/$P$10 -> 0.016474465 | R26: =P26+[4]松原工場!R26 -> 4000000 | S26: =R26/$R$10 -> 0.016184503 | T26: =L26-R26 -> 1197502 | U26: =IF(L26,L26/R26,"-") -> 1.2993755
D27: 動力費 | E27: =[2]松原工場!L27 -> 575833 | F27: =E27/$E$10 -> 0.016343534 | G27: =[3]松原工場!L27 -> 371398 | H27: =G27/$G$10 -> 0.019257656 | I27: =IF(E27,G27/E27,"-") -> 0.64497519 | J27: =E27+[4]松原工場!J27 -> 4539333 | K27: =J27/$J$10 -> 0.0084671184 | L27: =G27+[4]松原工場!L27 -> 3633073 | M27: =L27/$L$10 -> 0.026617576 | N27: =IF(J27,L27/J27,"-") -> 0.80035393 | P27: =[5]松原工場!L25 -> 600000 | Q27: =P27/$P$10 -> 0.019769357 | R27: =P27+[4]松原工場!R27 -> 5400000 | S27: =R27/$R$10 -> 0.02184908 | T27: =L27-R27 -> -1766927 | U27: =IF(L27,L27/R27,"-") -> 0.6727913
D28: 旅費交通費 | E28: =[2]松原工場!L28 -> 135290 | F28: =E28/$E$10 -> 0.0038398575 | G28: =[3]松原工場!L28 -> 75900 | H28: =G28/$G$10 -> 0.0039355519 | I28: =IF(E28,G28/E28,"-") -> 0.56101707 | J28: =E28+[4]松原工場!J28 -> 1052780 | K28: =J28/$J$10 -> 0.0019637275 | L28: =G28+[4]松原工場!L28 -> 802540 | M28: =L28/$L$10 -> 0.0058797798 | N28: =IF(J28,L28/J28,"-") -> 0.76230551 | P28: =[5]松原工場!L26 -> 120000 | Q28: =P28/$P$10 -> 0.0039538715 | R28: =P28+[4]松原工場!R28 -> 1080000 | S28: =R28/$R$10 -> 0.0043698159 | T28: =L28-R28 -> -277460 | U28: =IF(L28,L28/R28,"-") -> 0.74309259
D29: 消耗品費 | E29: =[2]松原工場!L29 -> 246191 | F29: =E29/$E$10 -> 0.0069874962 | G29: =[3]松原工場!L29 -> 1152754 | H29: =G29/$G$10 -> 0.059772375 | I29: =IF(E29,G29/E29,"-") -> 4.6823564 | J29: =E29+[4]松原工場!J29 -> 9358948 | K29: =J29/$J$10 -> 0.017457041 | L29: =G29+[4]松原工場!L29 -> 8383829 | M29: =L29/$L$10 -> 0.061423815 | N29: =IF(J29,L29/J29,"-") -> 0.89580891 | P29: =[5]松原工場!L27 -> 850000 | Q29: =P29/$P$10 -> 0.02800659 | R29: =P29+[4]松原工場!R29 -> 6800000 | S29: =R29/$R$10 -> 0.027513656 | T29: =L29-R29 -> 1583829 | U29: =IF(L29,L29/R29,"-") -> 1.232916
D30: 修繕費 | E30: =[2]松原工場!L30 -> 771419 | F30: =E30/$E$10 -> 0.021894738 | G30: =[3]松原工場!L30 -> 63800 | H30: =G30/$G$10 -> 0.0033081451 | I30: =IF(E30,G30/E30,"-") -> 0.08270473 | J30: =E30+[4]松原工場!J30 -> 9232377 | K30: =J30/$J$10 -> 0.017220951 | L30: =G30+[4]松原工場!L30 -> 2317040 | M30: =L30/$L$10 -> 0.016975708 | N30: =IF(J30,L30/J30,"-") -> 0.25096895 | P30: =[5]松原工場!L28 -> 600000 | Q30: =P30/$P$10 -> 0.019769357 | R30: =P30+[4]松原工場!R30 -> 4800000 | S30: =R30/$R$10 -> 0.019421404 | T30: =L30-R30 -> -2482960 | U30: =IF(L30,L30/R30,"-") -> 0.48271667
D31: 減価償却費 | E31: =[2]松原工場!L31 -> 2150000 | F31: =E31/$E$10 -> 0.061022202 | G31: =[3]松原工場!L31 -> 2200000 | H31: =G31/$G$10 -> 0.11407397 | I31: =IF(E31,G31/E31,"-") -> 1.0232558 | J31: =E31+[4]松原工場!J31 -> 19350000 | K31: =J31/$J$10 -> 0.036093131 | L31: =G31+[4]松原工場!L31 -> 19800000 | M31: =L31/$L$10 -> 0.14506397 | N31: =IF(J31,L31/J31,"-") -> 1.0232558 | P31: =[5]松原工場!L29 -> 2200000 | Q31: =P31/$P$10 -> 0.072487644 | R31: =P31+[4]松原工場!R31 -> 19800000 | S31: =R31/$R$10 -> 0.080113292 | T31: =L31-R31 -> 0 | U31: =IF(L31,L31/R31,"-") -> 1
D32: 地代家賃 | E32: =[2]松原工場!L32 -> 1160412 | F32: =E32/$E$10 -> 0.0329353 | G32: =[3]松原工場!L32 -> 1160412 | H32: =G32/$G$10 -> 0.060169456 | I32: =IF(E32,G32/E32,"-") -> 1 | J32: =E32+[4]松原工場!J32 -> 10313708 | K32: =J32/$J$10 -> 0.019237934 | L32: =G32+[4]松原工場!L32 -> 10443708 | M32: =L32/$L$10 -> 0.076515443 | N32: =IF(J32,L32/J32,"-") -> 1.0126046 | P32: =[5]松原工場!L30 -> 1175000 | Q32: =P32/$P$10 -> 0.038714992 | R32: =P32+[4]松原工場!R32 -> 10575000 | S32: =R32/$R$10 -> 0.042787781 | T32: =L32-R32 -> -131292 | U32: =IF(L32,L32/R32,"-") -> 0.98758468
D33: 賃借料 | E33: =[2]松原工場!L33 -> 50325 | F33: =E33/$E$10 -> 0.0014283453 | G33: =[3]松原工場!L33 -> 50325 | H33: =G33/$G$10 -> 0.002609442 | I33: =IF(E33,G33/E33,"-") -> 1 | J33: =E33+[4]松原工場!J33 -> 401775 | K33: =J33/$J$10 -> 0.00074942211 | L33: =G33+[4]松原工場!L33 -> 401775 | M33: =L33/$L$10 -> 0.0029435898 | N33: =IF(J33,L33/J33,"-") -> 1 | P33: =[5]松原工場!L31 -> 50000 | Q33: =P33/$P$10 -> 0.0016474465 | R33: =P33+[4]松原工場!R33 -> 450000 | S33: =R33/$R$10 -> 0.0018207566 | T33: =L33-R33 -> -48225 | U33: =IF(L33,L33/R33,"-") -> 0.89283333
D34: 保険料 | E34: =[2]松原工場!L34 -> 25075 | F34: =E34/$E$10 -> 0.00071168917 | G34: =[3]松原工場!L34 -> 13986 | H34: =G34/$G$10 -> 0.00072519933 | I34: =IF(E34,G34/E34,"-") -> 0.5577667 | J34: =E34+[4]松原工場!J34 -> 225675 | K34: =J34/$J$10 -> 0.00042094664 | L34: =G34+[4]松原工場!L34 -> 125874 | M34: =L34/$L$10 -> 0.00092221124 | N34: =IF(J34,L34/J34,"-") -> 0.5577667 | P34: =[5]松原工場!L32 -> 22000 | Q34: =P34/$P$10 -> 0.00072487644 | R34: =P34+[4]松原工場!R34 -> 198000 | S34: =R34/$R$10 -> 0.00080113292 | T34: =L34-R34 -> -72126 | U34: =IF(L34,L34/R34,"-") -> 0.63572727
D35: 保守料 | E35: =[2]松原工場!L35 -> 7333 | F35: =E35/$E$10 -> 0.00020812828 | G35: =[3]松原工場!L35 -> 9933 | H35: =G35/$G$10 -> 0.00051504397 | I35: =IF(E35,G35/E35,"-") -> 1.3545616 | J35: =E35+[4]松原工場!J35 -> 14686 | K35: =J35/$J$10 -> 2.7393474e-05 | L35: =G35+[4]松原工場!L35 -> 247797 | M35: =L35/$L$10 -> 0.0018154756 | N35: =IF(J35,L35/J35,"-") -> 16.873008 | P35: =[5]松原工場!L33 -> 10000 | Q35: =P35/$P$10 -> 0.00032948929 | R35: =P35+[4]松原工場!R35 -> 90000 | S35: =R35/$R$10 -> 0.00036415133 | T35: =L35-R35 -> 157797 | U35: =IF(L35,L35/R35,"-") -> 2.7533
D36: 少額資産減価償却費 | E36: =[2]松原工場!L36 -> 440000 | F36: =E36/$E$10 -> 0.012488265 | G36: =[3]松原工場!L36 -> 0 | H36: =G36/$G$10 -> 0 | I36: =IF(E36,G36/E36,"-") -> 0 | J36: =E36+[4]松原工場!J36 -> 3136628 | K36: =J36/$J$10 -> 0.0058506835 | L36: =G36+[4]松原工場!L36 -> 264000 | M36: =L36/$L$10 -> 0.0019341863 | N36: =IF(J36,L36/J36,"-") -> 0.084166819 | P36: =[5]松原工場!L34 -> 300000 | Q36: =P36/$P$10 -> 0.0098846787 | R36: =P36+[4]松原工場!R36 -> 2700000 | S36: =R36/$R$10 -> 0.01092454 | T36: =L36-R36 -> -2436000 | U36: =IF(L36,L36/R36,"-") -> 0.097777778
D37: 業務委託費 | E37: =[2]松原工場!L37 -> 352000 | F37: =E37/$E$10 -> 0.0099906117 | G37: =[3]松原工場!L37 -> 167000 | H37: =G37/$G$10 -> 0.0086592513 | I37: =IF(E37,G37/E37,"-") -> 0.47443182 | J37: =E37+[4]松原工場!J37 -> 2333000 | K37: =J37/$J$10 -> 0.0043516938 | L37: =G37+[4]松原工場!L37 -> 2428000 | M37: =L37/$L$10 -> 0.017788653 | N37: =IF(J37,L37/J37,"-") -> 1.0407201 | P37: =[5]松原工場!L35 -> 167000 | Q37: =P37/$P$10 -> 0.0055024712 | R37: =P37+[4]松原工場!R37 -> 2428000 | S37: =R37/$R$10 -> 0.0098239935 | T37: =L37-R37 -> 0 | U37: =IF(L37,L37/R37,"-") -> 1
... D39: 棚卸評価損 | E39: =[2]松原工場!L39 -> 0 | F39: =E39/$E$10 -> 0 | G39: =[3]松原工場!L39 -> 0 | H39: =G39/$G$10 -> 0 | I39: =IF(E39,G39/E39,"-") -> - | J39: =E39+[4]松原工場!J39 -> 0 | K39: =J39/$J$10 -> 0 | L39: =G39+[4]松原工場!L39 -> 0 | M39: =L39/$L$10 -> 0 | N39: =IF(J39,L39/J39,"-") -> - | P39: =[5]松原工場!L37 -> 0 | Q39: =P39/$P$10 -> 0 | R39: =P39+[4]松原工場!R39 -> 0 | S39: =R39/$R$10 -> 0 | T39: =L39-R39 -> 0 | U39: =IF(L39,L39/R39,"-") -> -
D40: 製造経費計 | E40: =SUM(E25:E39) -> 12504979 | F40: =E40/$E$10 -> 0.35492156 | G40: =SUM(G25:G39) -> 5890573 | H40: =G40/$G$10 -> 0.30543684 | I40: =IF(E40,G40/E40,"-") -> 0.47105821 | J40: =SUM(J25:J39) -> 107000976 | K40: =J40/$J$10 -> 0.19958658 | L40: =SUM(L25:L39) -> 54045138 | M40: =L40/$L$10 -> 0.39595972 | N40: =IF(J40,L40/J40,"-") -> 0.50509014 | P40: =SUM(P25:P39) -> 6619000 | Q40: =P40/$P$10 -> 0.21808896 | R40: =SUM(R25:R39) -> 58546000 | S40: =R40/$R$10 -> 0.23688448 | T40: =L40-R40 -> -4500862 | U40: =IF(L40,L40/R40,"-") -> 0.92312264
B41: 総製造経費 | D41: 総製造経費計 | E41: =E16+E24+E40 -> 42456071 | F41: =E41/$E$10 -> 1.205006 | G41: =G16+G24+G40 -> 13475770 | H41: =G41/$G$10 -> 0.69874299 | I41: =IF(E41,G41/E41,"-") -> 0.31740502 | J41: =J40+J24+J16 -> 462203463 | K41: =J41/$J$10 -> 0.862138 | L41: =L16+L24+L40 -> 123066758 | M41: =L41/$L$10 -> 0.90164408 | N41: =IF(J41,L41/J41,"-") -> 0.266261 | P41: =P40+P24+P16 -> 25964000 | Q41: =P41/$P$10 -> 0.855486 | R41: =R40+R24+R16 -> 222929000 | S41: =R41/$R$10 -> 0.90199879 | T41: =L41-R41 -> -99862242 | U41: =IF(L41,L41/R41,"-") -> 0.55204463
B42: 売上総利益（粗利） | E42: =E10-E41 -> -7222993 | F42: =E42/$E$10 -> -0.20500602 | G42: =G10-G41 -> 5809962 | H42: =G42/$G$10 -> 0.30125701 | I42: =IF(E42,G42/E42,"-") -> -0.80437043 | J42: =J10-J41 -> 73909623 | K42: =J42/$J$10 -> 0.137862 | L42: =L10-L41 -> 13424747 | M42: =L42/$L$10 -> 0.098355916 | N42: =IF(J42,L42/J42,"-") -> 0.18163734 | P42: =P10-P41 -> 4386000 | Q42: =P42/$P$10 -> 0.144514 | R42: =R10-R41 -> 24221000 | S42: =R42/$R$10 -> 0.098001214 | T42: =L42-R42 -> -10796253 | U42: =IF(L42,L42/R42,"-") -> 0.55426064
B43: 販管費 | D43: 役員報酬 | E43: =[2]松原工場!L45 -> 150000 | F43: =E43/$E$10 -> 0.0042573629 | G43: =[3]松原工場!L45 -> 0 | H43: =G43/$G$10 -> 0 | I43: =IF(E43,G43/E43,"-") -> 0 | J43: =E43+[4]松原工場!J43 -> 1350000 | K43: =J43/$J$10 -> 0.0025181254 | L43: =G43+[4]松原工場!L43 -> 0 | M43: =L43/$L$10 -> 0 | N43: =IF(J43,L43/J43,"-") -> 0 | P43: =[5]松原工場!L43 -> 0 | Q43: =P43/$P$10 -> 0 | R43: =P43+[4]松原工場!R43 -> 0 | S43: =R43/$R$10 -> 0 | T43: =L43-R43 -> 0 | U43: =IF(L43,L43/R43,"-") -> -
...
